# SRST-3115: AttributeError en unknown

## Error Específico
**Tipo:** `AttributeError`
**Archivo:** `tests/integration/test_story_5_4_complete_flow.py:0`
**Mensaje:** `AttributeError: 'str' object has no attribute 'value'`
**Categoría:** `2_TYPE_ERRORS`
**Prioridad:** `HIGH`

## Contexto Mínimo
- **Test Scope:** `tests/integration/test_story_5_4_complete_flow.py::TestCompleteOpportunityProcessingFlow::test_confidence_threshold_rejection_flow`
- **Archivo a tocar:** `tests/integration/test_story_5_4_complete_flow.py`

## Plan de Fix Sugerido
1. [ ] **Analizar:** Revisar el código en `tests/integration/test_story_5_4_complete_flow.py` en la línea 0.
2. [ ] **Contextualizar:** Entender por qué el test `tests/integration/test_story_5_4_complete_flow.py::TestCompleteOpportunityProcessingFlow::test_confidence_threshold_rejection_flow` causa este error.
3. [ ] **Refactorizar:** Aplicar la corrección necesaria.
4. [ ] **Validar:** Ejecutar `poetry run pytest tests/integration/test_story_5_4_complete_flow.py::TestCompleteOpportunityProcessingFlow::test_confidence_threshold_rejection_flow` para confirmar que el error ha desaparecido.

## Validación Inmediata
```bash
# Validar que el error específico desapareció
poetry run pytest -k "tests/integration/test_story_5_4_complete_flow.py::TestCompleteOpportunityProcessingFlow::test_confidence_threshold_rejection_flow" -v
```

## Criterio de Éxito
- [ ] El error específico ya no aparece en la salida de pytest.
- [ ] La funcionalidad del código modificado sigue siendo la misma.
- [ ] No se han introducido nuevos errores.

**Estado:** `[ ] TODO`
**Tiempo estimado:** `20 minutos`
