# SRST-3737: RuntimeError en unknown

## Error Específico
**Tipo:** `RuntimeError`
**Archivo:** `logs/frontend.log:0`
**Mensaje:** `[MainThread] - market_data_service.py:69 - Fallo en la verificación de conexión con Binance. Revise sus credenciales y permisos.`
**Categoría:** `7_BUSINESS_LOGIC_ERRORS`
**Prioridad:** `MEDIUM`

## Contexto Mínimo
- **Test Scope:** `Runtime Log Error: [MainThread] - market_data_service.py:69 - Fallo e...`
- **Archivo a tocar:** `logs/frontend.log`

## Plan de Fix Sugerido
1. [ ] **Analizar:** Revisar el código en `logs/frontend.log` en la línea 0.
2. [ ] **Contextualizar:** Entender por qué el test `Runtime Log Error: [MainThread] - market_data_service.py:69 - Fallo e...` causa este error.
3. [ ] **Refactorizar:** Aplicar la corrección necesaria.
4. [ ] **Validar:** Ejecutar `poetry run pytest Runtime Log Error: [MainThread] - market_data_service.py:69 - Fallo e...` para confirmar que el error ha desaparecido.

## Validación Inmediata
```bash
# Validar que el error específico desapareció
poetry run pytest -k "Runtime Log Error: [MainThread] - market_data_service.py:69 - Fallo e..." -v
```

## Criterio de Éxito
- [ ] El error específico ya no aparece en la salida de pytest.
- [ ] La funcionalidad del código modificado sigue siendo la misma.
- [ ] No se han introducido nuevos errores.

**Estado:** `[ ] TODO`
**Tiempo estimado:** `30 minutos`
