2025-06-17 15:02:35,988 - ultibot_backend - INFO - [MainThread] - main.py:65 - Logging configurado exitosamente usando dictConfig.
2025-06-17 15:02:35,989 - ultibot_backend - INFO - [MainThread] - main.py:133 - Registrando routers de la API...
2025-06-17 15:02:36,006 - ultibot_backend - INFO - [MainThread] - main.py:145 - Todos los routers han sido registrados.
2025-06-17 15:02:36,106 - qasync - INFO - [MainThread] - __init__.py:57 - Forcing use of PySide6 as Qt Implementation
2025-06-17 15:02:36,250 - matplotlib - DEBUG - [MainThread] - __init__.py:342 - matplotlib data path: C:\Users\zamor\UltiBotInversiones\.venv\Lib\site-packages\matplotlib\mpl-data
2025-06-17 15:02:36,259 - matplotlib - DEBUG - [MainThread] - __init__.py:342 - CONFIGDIR=C:\Users\zamor\.matplotlib
2025-06-17 15:02:36,259 - matplotlib - DEBUG - [MainThread] - __init__.py:1557 - interactive is False
2025-06-17 15:02:36,260 - matplotlib - DEBUG - [MainThread] - __init__.py:1558 - platform is win32
2025-06-17 15:02:36,311 - matplotlib - DEBUG - [MainThread] - __init__.py:342 - CACHEDIR=C:\Users\zamor\.matplotlib
2025-06-17 15:02:36,371 - matplotlib.font_manager - DEBUG - [MainThread] - font_manager.py:1635 - Using fontManager instance from C:\Users\zamor\.matplotlib\fontlist-v390.json
2025-06-17 15:05:39,163 - ultibot_backend - INFO - [MainThread] - main.py:65 - Logging configurado exitosamente usando dictConfig.
2025-06-17 15:05:39,163 - ultibot_backend - INFO - [MainThread] - main.py:133 - Registrando routers de la API...
2025-06-17 15:05:39,179 - ultibot_backend - INFO - [MainThread] - main.py:145 - Todos los routers han sido registrados.
2025-06-17 15:05:39,289 - qasync - INFO - [MainThread] - __init__.py:57 - Forcing use of PySide6 as Qt Implementation
2025-06-17 15:06:29,357 - ultibot_backend - INFO - [MainThread] - main.py:65 - Logging configurado exitosamente usando dictConfig.
2025-06-17 15:06:29,357 - ultibot_backend - INFO - [MainThread] - main.py:133 - Registrando routers de la API...
2025-06-17 15:06:29,389 - ultibot_backend - INFO - [MainThread] - main.py:145 - Todos los routers han sido registrados.
2025-06-17 15:06:29,484 - qasync - INFO - [MainThread] - __init__.py:57 - Forcing use of PySide6 as Qt Implementation
2025-06-17 15:06:29,617 - matplotlib - DEBUG - [MainThread] - __init__.py:342 - matplotlib data path: C:\Users\zamor\UltiBotInversiones\.venv\Lib\site-packages\matplotlib\mpl-data
2025-06-17 15:06:29,624 - matplotlib - DEBUG - [MainThread] - __init__.py:342 - CONFIGDIR=C:\Users\zamor\.matplotlib
2025-06-17 15:06:29,631 - matplotlib - DEBUG - [MainThread] - __init__.py:1557 - interactive is False
2025-06-17 15:06:29,631 - matplotlib - DEBUG - [MainThread] - __init__.py:1558 - platform is win32
2025-06-17 15:06:29,670 - matplotlib - DEBUG - [MainThread] - __init__.py:342 - CACHEDIR=C:\Users\zamor\.matplotlib
2025-06-17 15:06:29,747 - matplotlib.font_manager - DEBUG - [MainThread] - font_manager.py:1635 - Using fontManager instance from C:\Users\zamor\.matplotlib\fontlist-v390.json
2025-06-17 15:07:03,259 - ultibot_backend - INFO - [MainThread] - main.py:65 - Logging configurado exitosamente usando dictConfig.
2025-06-17 15:07:03,259 - ultibot_backend - INFO - [MainThread] - main.py:133 - Registrando routers de la API...
2025-06-17 15:07:03,275 - ultibot_backend - INFO - [MainThread] - main.py:145 - Todos los routers han sido registrados.
2025-06-17 15:07:03,379 - qasync - INFO - [MainThread] - __init__.py:57 - Forcing use of PySide6 as Qt Implementation
2025-06-17 15:07:03,508 - matplotlib - DEBUG - [MainThread] - __init__.py:342 - matplotlib data path: C:\Users\zamor\UltiBotInversiones\.venv\Lib\site-packages\matplotlib\mpl-data
2025-06-17 15:07:03,523 - matplotlib - DEBUG - [MainThread] - __init__.py:342 - CONFIGDIR=C:\Users\zamor\.matplotlib
2025-06-17 15:07:03,523 - matplotlib - DEBUG - [MainThread] - __init__.py:1557 - interactive is False
2025-06-17 15:07:03,523 - matplotlib - DEBUG - [MainThread] - __init__.py:1558 - platform is win32
2025-06-17 15:07:03,571 - matplotlib - DEBUG - [MainThread] - __init__.py:342 - CACHEDIR=C:\Users\zamor\.matplotlib
2025-06-17 15:07:03,618 - matplotlib.font_manager - DEBUG - [MainThread] - font_manager.py:1635 - Using fontManager instance from C:\Users\zamor\.matplotlib\fontlist-v390.json
2025-06-17 15:07:52,238 - ultibot_backend - INFO - [MainThread] - main.py:65 - Logging configurado exitosamente usando dictConfig.
2025-06-17 15:07:52,238 - ultibot_backend - INFO - [MainThread] - main.py:133 - Registrando routers de la API...
2025-06-17 15:07:52,263 - ultibot_backend - INFO - [MainThread] - main.py:145 - Todos los routers han sido registrados.
2025-06-17 15:07:52,348 - qasync - INFO - [MainThread] - __init__.py:57 - Forcing use of PySide6 as Qt Implementation
2025-06-17 15:07:52,493 - matplotlib - DEBUG - [MainThread] - __init__.py:342 - matplotlib data path: C:\Users\zamor\UltiBotInversiones\.venv\Lib\site-packages\matplotlib\mpl-data
2025-06-17 15:07:52,493 - matplotlib - DEBUG - [MainThread] - __init__.py:342 - CONFIGDIR=C:\Users\zamor\.matplotlib
2025-06-17 15:07:52,493 - matplotlib - DEBUG - [MainThread] - __init__.py:1557 - interactive is False
2025-06-17 15:07:52,493 - matplotlib - DEBUG - [MainThread] - __init__.py:1558 - platform is win32
2025-06-17 15:07:52,538 - matplotlib - DEBUG - [MainThread] - __init__.py:342 - CACHEDIR=C:\Users\zamor\.matplotlib
2025-06-17 15:07:52,586 - matplotlib.font_manager - DEBUG - [MainThread] - font_manager.py:1635 - Using fontManager instance from C:\Users\zamor\.matplotlib\fontlist-v390.json
2025-06-17 15:08:30,102 - ultibot_backend - INFO - [MainThread] - main.py:65 - Logging configurado exitosamente usando dictConfig.
2025-06-17 15:08:30,102 - ultibot_backend - INFO - [MainThread] - main.py:133 - Registrando routers de la API...
2025-06-17 15:08:30,116 - ultibot_backend - INFO - [MainThread] - main.py:145 - Todos los routers han sido registrados.
2025-06-17 15:08:30,221 - qasync - INFO - [MainThread] - __init__.py:57 - Forcing use of PySide6 as Qt Implementation
2025-06-17 15:08:30,355 - matplotlib - DEBUG - [MainThread] - __init__.py:342 - matplotlib data path: C:\Users\zamor\UltiBotInversiones\.venv\Lib\site-packages\matplotlib\mpl-data
2025-06-17 15:08:30,364 - matplotlib - DEBUG - [MainThread] - __init__.py:342 - CONFIGDIR=C:\Users\zamor\.matplotlib
2025-06-17 15:08:30,365 - matplotlib - DEBUG - [MainThread] - __init__.py:1557 - interactive is False
2025-06-17 15:08:30,366 - matplotlib - DEBUG - [MainThread] - __init__.py:1558 - platform is win32
2025-06-17 15:08:30,413 - matplotlib - DEBUG - [MainThread] - __init__.py:342 - CACHEDIR=C:\Users\zamor\.matplotlib
2025-06-17 15:08:30,448 - matplotlib.font_manager - DEBUG - [MainThread] - font_manager.py:1635 - Using fontManager instance from C:\Users\zamor\.matplotlib\fontlist-v390.json
2025-06-17 15:09:01,540 - ultibot_backend - INFO - [MainThread] - main.py:65 - Logging configurado exitosamente usando dictConfig.
2025-06-17 15:09:01,540 - ultibot_backend - INFO - [MainThread] - main.py:133 - Registrando routers de la API...
2025-06-17 15:09:01,548 - ultibot_backend - INFO - [MainThread] - main.py:145 - Todos los routers han sido registrados.
2025-06-17 15:09:01,643 - qasync - INFO - [MainThread] - __init__.py:57 - Forcing use of PySide6 as Qt Implementation
2025-06-17 15:09:01,786 - matplotlib - DEBUG - [MainThread] - __init__.py:342 - matplotlib data path: C:\Users\zamor\UltiBotInversiones\.venv\Lib\site-packages\matplotlib\mpl-data
2025-06-17 15:09:01,786 - matplotlib - DEBUG - [MainThread] - __init__.py:342 - CONFIGDIR=C:\Users\zamor\.matplotlib
2025-06-17 15:09:01,786 - matplotlib - DEBUG - [MainThread] - __init__.py:1557 - interactive is False
2025-06-17 15:09:01,786 - matplotlib - DEBUG - [MainThread] - __init__.py:1558 - platform is win32
2025-06-17 15:09:01,850 - matplotlib - DEBUG - [MainThread] - __init__.py:342 - CACHEDIR=C:\Users\zamor\.matplotlib
2025-06-17 15:09:01,899 - matplotlib.font_manager - DEBUG - [MainThread] - font_manager.py:1635 - Using fontManager instance from C:\Users\zamor\.matplotlib\fontlist-v390.json
2025-06-17 15:10:28,265 - ultibot_backend - INFO - [MainThread] - main.py:65 - Logging configurado exitosamente usando dictConfig.
2025-06-17 15:10:28,265 - ultibot_backend - INFO - [MainThread] - main.py:133 - Registrando routers de la API...
2025-06-17 15:10:28,276 - ultibot_backend - INFO - [MainThread] - main.py:145 - Todos los routers han sido registrados.
2025-06-17 15:10:28,374 - qasync - INFO - [MainThread] - __init__.py:57 - Forcing use of PySide6 as Qt Implementation
2025-06-17 15:10:28,508 - matplotlib - DEBUG - [MainThread] - __init__.py:342 - matplotlib data path: C:\Users\zamor\UltiBotInversiones\.venv\Lib\site-packages\matplotlib\mpl-data
2025-06-17 15:10:28,508 - matplotlib - DEBUG - [MainThread] - __init__.py:342 - CONFIGDIR=C:\Users\zamor\.matplotlib
2025-06-17 15:10:28,508 - matplotlib - DEBUG - [MainThread] - __init__.py:1557 - interactive is False
2025-06-17 15:10:28,508 - matplotlib - DEBUG - [MainThread] - __init__.py:1558 - platform is win32
2025-06-17 15:10:28,566 - matplotlib - DEBUG - [MainThread] - __init__.py:342 - CACHEDIR=C:\Users\zamor\.matplotlib
2025-06-17 15:10:28,604 - matplotlib.font_manager - DEBUG - [MainThread] - font_manager.py:1635 - Using fontManager instance from C:\Users\zamor\.matplotlib\fontlist-v390.json
2025-06-17 15:16:07,556 - ultibot_backend - INFO - [MainThread] - main.py:65 - Logging configurado exitosamente usando dictConfig.
2025-06-17 15:16:07,556 - ultibot_backend - INFO - [MainThread] - main.py:133 - Registrando routers de la API...
2025-06-17 15:16:07,560 - ultibot_backend - INFO - [MainThread] - main.py:145 - Todos los routers han sido registrados.
2025-06-17 15:16:07,683 - qasync - INFO - [MainThread] - __init__.py:57 - Forcing use of PySide6 as Qt Implementation
2025-06-17 15:16:07,794 - matplotlib - DEBUG - [MainThread] - __init__.py:342 - matplotlib data path: C:\Users\zamor\UltiBotInversiones\.venv\Lib\site-packages\matplotlib\mpl-data
2025-06-17 15:16:07,809 - matplotlib - DEBUG - [MainThread] - __init__.py:342 - CONFIGDIR=C:\Users\zamor\.matplotlib
2025-06-17 15:16:07,809 - matplotlib - DEBUG - [MainThread] - __init__.py:1557 - interactive is False
2025-06-17 15:16:07,809 - matplotlib - DEBUG - [MainThread] - __init__.py:1558 - platform is win32
2025-06-17 15:16:07,904 - matplotlib - DEBUG - [MainThread] - __init__.py:342 - CACHEDIR=C:\Users\zamor\.matplotlib
2025-06-17 15:16:07,904 - matplotlib.font_manager - DEBUG - [MainThread] - font_manager.py:1635 - Using fontManager instance from C:\Users\zamor\.matplotlib\fontlist-v390.json
2025-06-17 15:16:45,221 - ultibot_backend - INFO - [MainThread] - main.py:65 - Logging configurado exitosamente usando dictConfig.
2025-06-17 15:16:45,221 - ultibot_backend - INFO - [MainThread] - main.py:133 - Registrando routers de la API...
2025-06-17 15:16:45,245 - ultibot_backend - INFO - [MainThread] - main.py:145 - Todos los routers han sido registrados.
2025-06-17 15:16:45,354 - qasync - INFO - [MainThread] - __init__.py:57 - Forcing use of PySide6 as Qt Implementation
2025-06-17 15:16:45,471 - matplotlib - DEBUG - [MainThread] - __init__.py:342 - matplotlib data path: C:\Users\zamor\UltiBotInversiones\.venv\Lib\site-packages\matplotlib\mpl-data
2025-06-17 15:16:45,489 - matplotlib - DEBUG - [MainThread] - __init__.py:342 - CONFIGDIR=C:\Users\zamor\.matplotlib
2025-06-17 15:16:45,489 - matplotlib - DEBUG - [MainThread] - __init__.py:1557 - interactive is False
2025-06-17 15:16:45,489 - matplotlib - DEBUG - [MainThread] - __init__.py:1558 - platform is win32
2025-06-17 15:16:45,537 - matplotlib - DEBUG - [MainThread] - __init__.py:342 - CACHEDIR=C:\Users\zamor\.matplotlib
2025-06-17 15:16:45,602 - matplotlib.font_manager - DEBUG - [MainThread] - font_manager.py:1635 - Using fontManager instance from C:\Users\zamor\.matplotlib\fontlist-v390.json
2025-06-17 15:16:46,425 - ultibot_backend - INFO - [Thread-1 (run_blocking_portal)] - main.py:102 - Middleware: Solicitud entrante: GET /api/v1/performance/strategies
2025-06-17 15:16:46,425 - ultibot_backend - CRITICAL - [Thread-1 (run_blocking_portal)] - main.py:117 - Excepción no controlada en GET /api/v1/performance/strategies: 
  + Exception Group Traceback (most recent call last):
  |   File "C:\Users\zamor\UltiBotInversiones\.venv\Lib\site-packages\starlette\_utils.py", line 87, in collapse_excgroups
  |     yield
  |   File "C:\Users\zamor\UltiBotInversiones\.venv\Lib\site-packages\starlette\middleware\base.py", line 190, in __call__
  |     async with anyio.create_task_group() as task_group:
  |   File "C:\Users\zamor\UltiBotInversiones\.venv\Lib\site-packages\anyio\_backends\_asyncio.py", line 772, in __aexit__
  |     raise BaseExceptionGroup(
  | ExceptionGroup: unhandled errors in a TaskGroup (1 sub-exception)
  +-+---------------- 1 ----------------
    | Traceback (most recent call last):
    |   File "C:\Users\zamor\UltiBotInversiones\.venv\Lib\site-packages\starlette\middleware\errors.py", line 164, in __call__
    |     await self.app(scope, receive, _send)
    |   File "C:\Users\zamor\UltiBotInversiones\.venv\Lib\site-packages\starlette\middleware\cors.py", line 85, in __call__
    |     await self.app(scope, receive, send)
    |   File "C:\Users\zamor\UltiBotInversiones\.venv\Lib\site-packages\starlette\middleware\base.py", line 189, in __call__
    |     with collapse_excgroups():
    |   File "C:\Program Files\Python311\Lib\contextlib.py", line 158, in __exit__
    |     self.gen.throw(typ, value, traceback)
    |   File "C:\Users\zamor\UltiBotInversiones\.venv\Lib\site-packages\starlette\_utils.py", line 93, in collapse_excgroups
    |     raise exc
    |   File "C:\Users\zamor\UltiBotInversiones\.venv\Lib\site-packages\starlette\middleware\base.py", line 191, in __call__
    |     response = await self.dispatch_func(request, call_next)
    |                ^^^^^^^^^^^^^^^^^^^^^^^^^^^^^^^^^^^^^^^^^^^^
    |   File "C:\Users\zamor\UltiBotInversiones\src\ultibot_backend\main.py", line 103, in log_requests
    |     response = await call_next(request)
    |                ^^^^^^^^^^^^^^^^^^^^^^^^
    |   File "C:\Users\zamor\UltiBotInversiones\.venv\Lib\site-packages\starlette\middleware\base.py", line 165, in call_next
    |     raise app_exc
    |   File "C:\Users\zamor\UltiBotInversiones\.venv\Lib\site-packages\starlette\middleware\base.py", line 151, in coro
    |     await self.app(scope, receive_or_disconnect, send_no_error)
    |   File "C:\Users\zamor\UltiBotInversiones\.venv\Lib\site-packages\starlette\middleware\exceptions.py", line 65, in __call__
    |     await wrap_app_handling_exceptions(self.app, conn)(scope, receive, send)
    |   File "C:\Users\zamor\UltiBotInversiones\.venv\Lib\site-packages\starlette\_exception_handler.py", line 64, in wrapped_app
    |     raise exc
    |   File "C:\Users\zamor\UltiBotInversiones\.venv\Lib\site-packages\starlette\_exception_handler.py", line 53, in wrapped_app
    |     await app(scope, receive, sender)
    |   File "C:\Users\zamor\UltiBotInversiones\.venv\Lib\site-packages\starlette\routing.py", line 756, in __call__
    |     await self.middleware_stack(scope, receive, send)
    |   File "C:\Users\zamor\UltiBotInversiones\.venv\Lib\site-packages\starlette\routing.py", line 776, in app
    |     await route.handle(scope, receive, send)
    |   File "C:\Users\zamor\UltiBotInversiones\.venv\Lib\site-packages\starlette\routing.py", line 297, in handle
    |     await self.app(scope, receive, send)
    |   File "C:\Users\zamor\UltiBotInversiones\.venv\Lib\site-packages\starlette\routing.py", line 77, in app
    |     await wrap_app_handling_exceptions(app, request)(scope, receive, send)
    |   File "C:\Users\zamor\UltiBotInversiones\.venv\Lib\site-packages\starlette\_exception_handler.py", line 64, in wrapped_app
    |     raise exc
    |   File "C:\Users\zamor\UltiBotInversiones\.venv\Lib\site-packages\starlette\_exception_handler.py", line 53, in wrapped_app
    |     await app(scope, receive, sender)
    |   File "C:\Users\zamor\UltiBotInversiones\.venv\Lib\site-packages\starlette\routing.py", line 72, in app
    |     response = await func(request)
    |                ^^^^^^^^^^^^^^^^^^^
    |   File "C:\Users\zamor\UltiBotInversiones\.venv\Lib\site-packages\fastapi\routing.py", line 269, in app
    |     solved_result = await solve_dependencies(
    |                     ^^^^^^^^^^^^^^^^^^^^^^^^^
    |   File "C:\Users\zamor\UltiBotInversiones\.venv\Lib\site-packages\fastapi\dependencies\utils.py", line 600, in solve_dependencies
    |     solved = await call(**sub_values)
    |              ^^^^^^^^^^^^^^^^^^^^^^^^
    |   File "C:\Users\zamor\UltiBotInversiones\src\ultibot_backend\dependencies.py", line 212, in get_performance_service
    |     assert container.performance_service is not None
    |            ^^^^^^^^^^^^^^^^^^^^^^^^^^^^^^^^^^^^^^^^^
    | AssertionError
    +------------------------------------

During handling of the above exception, another exception occurred:

Traceback (most recent call last):
  File "C:\Users\zamor\UltiBotInversiones\.venv\Lib\site-packages\starlette\middleware\errors.py", line 164, in __call__
    await self.app(scope, receive, _send)
  File "C:\Users\zamor\UltiBotInversiones\.venv\Lib\site-packages\starlette\middleware\cors.py", line 85, in __call__
    await self.app(scope, receive, send)
  File "C:\Users\zamor\UltiBotInversiones\.venv\Lib\site-packages\starlette\middleware\base.py", line 189, in __call__
    with collapse_excgroups():
  File "C:\Program Files\Python311\Lib\contextlib.py", line 158, in __exit__
    self.gen.throw(typ, value, traceback)
  File "C:\Users\zamor\UltiBotInversiones\.venv\Lib\site-packages\starlette\_utils.py", line 93, in collapse_excgroups
    raise exc
  File "C:\Users\zamor\UltiBotInversiones\.venv\Lib\site-packages\starlette\middleware\base.py", line 191, in __call__
    response = await self.dispatch_func(request, call_next)
               ^^^^^^^^^^^^^^^^^^^^^^^^^^^^^^^^^^^^^^^^^^^^
  File "C:\Users\zamor\UltiBotInversiones\src\ultibot_backend\main.py", line 103, in log_requests
    response = await call_next(request)
               ^^^^^^^^^^^^^^^^^^^^^^^^
  File "C:\Users\zamor\UltiBotInversiones\.venv\Lib\site-packages\starlette\middleware\base.py", line 165, in call_next
    raise app_exc
  File "C:\Users\zamor\UltiBotInversiones\.venv\Lib\site-packages\starlette\middleware\base.py", line 151, in coro
    await self.app(scope, receive_or_disconnect, send_no_error)
  File "C:\Users\zamor\UltiBotInversiones\.venv\Lib\site-packages\starlette\middleware\exceptions.py", line 65, in __call__
    await wrap_app_handling_exceptions(self.app, conn)(scope, receive, send)
  File "C:\Users\zamor\UltiBotInversiones\.venv\Lib\site-packages\starlette\_exception_handler.py", line 64, in wrapped_app
    raise exc
  File "C:\Users\zamor\UltiBotInversiones\.venv\Lib\site-packages\starlette\_exception_handler.py", line 53, in wrapped_app
    await app(scope, receive, sender)
  File "C:\Users\zamor\UltiBotInversiones\.venv\Lib\site-packages\starlette\routing.py", line 756, in __call__
    await self.middleware_stack(scope, receive, send)
  File "C:\Users\zamor\UltiBotInversiones\.venv\Lib\site-packages\starlette\routing.py", line 776, in app
    await route.handle(scope, receive, send)
  File "C:\Users\zamor\UltiBotInversiones\.venv\Lib\site-packages\starlette\routing.py", line 297, in handle
    await self.app(scope, receive, send)
  File "C:\Users\zamor\UltiBotInversiones\.venv\Lib\site-packages\starlette\routing.py", line 77, in app
    await wrap_app_handling_exceptions(app, request)(scope, receive, send)
  File "C:\Users\zamor\UltiBotInversiones\.venv\Lib\site-packages\starlette\_exception_handler.py", line 64, in wrapped_app
    raise exc
  File "C:\Users\zamor\UltiBotInversiones\.venv\Lib\site-packages\starlette\_exception_handler.py", line 53, in wrapped_app
    await app(scope, receive, sender)
  File "C:\Users\zamor\UltiBotInversiones\.venv\Lib\site-packages\starlette\routing.py", line 72, in app
    response = await func(request)
               ^^^^^^^^^^^^^^^^^^^
  File "C:\Users\zamor\UltiBotInversiones\.venv\Lib\site-packages\fastapi\routing.py", line 269, in app
    solved_result = await solve_dependencies(
                    ^^^^^^^^^^^^^^^^^^^^^^^^^
  File "C:\Users\zamor\UltiBotInversiones\.venv\Lib\site-packages\fastapi\dependencies\utils.py", line 600, in solve_dependencies
    solved = await call(**sub_values)
             ^^^^^^^^^^^^^^^^^^^^^^^^
  File "C:\Users\zamor\UltiBotInversiones\src\ultibot_backend\dependencies.py", line 212, in get_performance_service
    assert container.performance_service is not None
           ^^^^^^^^^^^^^^^^^^^^^^^^^^^^^^^^^^^^^^^^^
AssertionError
2025-06-17 15:16:47,059 - ultibot_backend - INFO - [Thread-2 (run_blocking_portal)] - main.py:102 - Middleware: Solicitud entrante: GET /api/v1/performance/strategies
2025-06-17 15:16:47,070 - ultibot_backend - CRITICAL - [Thread-2 (run_blocking_portal)] - main.py:117 - Excepción no controlada en GET /api/v1/performance/strategies: 
  + Exception Group Traceback (most recent call last):
  |   File "C:\Users\zamor\UltiBotInversiones\.venv\Lib\site-packages\starlette\_utils.py", line 87, in collapse_excgroups
  |     yield
  |   File "C:\Users\zamor\UltiBotInversiones\.venv\Lib\site-packages\starlette\middleware\base.py", line 190, in __call__
  |     async with anyio.create_task_group() as task_group:
  |   File "C:\Users\zamor\UltiBotInversiones\.venv\Lib\site-packages\anyio\_backends\_asyncio.py", line 772, in __aexit__
  |     raise BaseExceptionGroup(
  | ExceptionGroup: unhandled errors in a TaskGroup (1 sub-exception)
  +-+---------------- 1 ----------------
    | Traceback (most recent call last):
    |   File "C:\Users\zamor\UltiBotInversiones\.venv\Lib\site-packages\starlette\middleware\errors.py", line 164, in __call__
    |     await self.app(scope, receive, _send)
    |   File "C:\Users\zamor\UltiBotInversiones\.venv\Lib\site-packages\starlette\middleware\cors.py", line 85, in __call__
    |     await self.app(scope, receive, send)
    |   File "C:\Users\zamor\UltiBotInversiones\.venv\Lib\site-packages\starlette\middleware\base.py", line 189, in __call__
    |     with collapse_excgroups():
    |   File "C:\Program Files\Python311\Lib\contextlib.py", line 158, in __exit__
    |     self.gen.throw(typ, value, traceback)
    |   File "C:\Users\zamor\UltiBotInversiones\.venv\Lib\site-packages\starlette\_utils.py", line 93, in collapse_excgroups
    |     raise exc
    |   File "C:\Users\zamor\UltiBotInversiones\.venv\Lib\site-packages\starlette\middleware\base.py", line 191, in __call__
    |     response = await self.dispatch_func(request, call_next)
    |                ^^^^^^^^^^^^^^^^^^^^^^^^^^^^^^^^^^^^^^^^^^^^
    |   File "C:\Users\zamor\UltiBotInversiones\src\ultibot_backend\main.py", line 103, in log_requests
    |     response = await call_next(request)
    |                ^^^^^^^^^^^^^^^^^^^^^^^^
    |   File "C:\Users\zamor\UltiBotInversiones\.venv\Lib\site-packages\starlette\middleware\base.py", line 165, in call_next
    |     raise app_exc
    |   File "C:\Users\zamor\UltiBotInversiones\.venv\Lib\site-packages\starlette\middleware\base.py", line 151, in coro
    |     await self.app(scope, receive_or_disconnect, send_no_error)
    |   File "C:\Users\zamor\UltiBotInversiones\.venv\Lib\site-packages\starlette\middleware\exceptions.py", line 65, in __call__
    |     await wrap_app_handling_exceptions(self.app, conn)(scope, receive, send)
    |   File "C:\Users\zamor\UltiBotInversiones\.venv\Lib\site-packages\starlette\_exception_handler.py", line 64, in wrapped_app
    |     raise exc
    |   File "C:\Users\zamor\UltiBotInversiones\.venv\Lib\site-packages\starlette\_exception_handler.py", line 53, in wrapped_app
    |     await app(scope, receive, sender)
    |   File "C:\Users\zamor\UltiBotInversiones\.venv\Lib\site-packages\starlette\routing.py", line 756, in __call__
    |     await self.middleware_stack(scope, receive, send)
    |   File "C:\Users\zamor\UltiBotInversiones\.venv\Lib\site-packages\starlette\routing.py", line 776, in app
    |     await route.handle(scope, receive, send)
    |   File "C:\Users\zamor\UltiBotInversiones\.venv\Lib\site-packages\starlette\routing.py", line 297, in handle
    |     await self.app(scope, receive, send)
    |   File "C:\Users\zamor\UltiBotInversiones\.venv\Lib\site-packages\starlette\routing.py", line 77, in app
    |     await wrap_app_handling_exceptions(app, request)(scope, receive, send)
    |   File "C:\Users\zamor\UltiBotInversiones\.venv\Lib\site-packages\starlette\_exception_handler.py", line 64, in wrapped_app
    |     raise exc
    |   File "C:\Users\zamor\UltiBotInversiones\.venv\Lib\site-packages\starlette\_exception_handler.py", line 53, in wrapped_app
    |     await app(scope, receive, sender)
    |   File "C:\Users\zamor\UltiBotInversiones\.venv\Lib\site-packages\starlette\routing.py", line 72, in app
    |     response = await func(request)
    |                ^^^^^^^^^^^^^^^^^^^
    |   File "C:\Users\zamor\UltiBotInversiones\.venv\Lib\site-packages\fastapi\routing.py", line 269, in app
    |     solved_result = await solve_dependencies(
    |                     ^^^^^^^^^^^^^^^^^^^^^^^^^
    |   File "C:\Users\zamor\UltiBotInversiones\.venv\Lib\site-packages\fastapi\dependencies\utils.py", line 600, in solve_dependencies
    |     solved = await call(**sub_values)
    |              ^^^^^^^^^^^^^^^^^^^^^^^^
    |   File "C:\Users\zamor\UltiBotInversiones\src\ultibot_backend\dependencies.py", line 212, in get_performance_service
    |     assert container.performance_service is not None
    |            ^^^^^^^^^^^^^^^^^^^^^^^^^^^^^^^^^^^^^^^^^
    | AssertionError
    +------------------------------------

During handling of the above exception, another exception occurred:

Traceback (most recent call last):
  File "C:\Users\zamor\UltiBotInversiones\.venv\Lib\site-packages\starlette\middleware\errors.py", line 164, in __call__
    await self.app(scope, receive, _send)
  File "C:\Users\zamor\UltiBotInversiones\.venv\Lib\site-packages\starlette\middleware\cors.py", line 85, in __call__
    await self.app(scope, receive, send)
  File "C:\Users\zamor\UltiBotInversiones\.venv\Lib\site-packages\starlette\middleware\base.py", line 189, in __call__
    with collapse_excgroups():
  File "C:\Program Files\Python311\Lib\contextlib.py", line 158, in __exit__
    self.gen.throw(typ, value, traceback)
  File "C:\Users\zamor\UltiBotInversiones\.venv\Lib\site-packages\starlette\_utils.py", line 93, in collapse_excgroups
    raise exc
  File "C:\Users\zamor\UltiBotInversiones\.venv\Lib\site-packages\starlette\middleware\base.py", line 191, in __call__
    response = await self.dispatch_func(request, call_next)
               ^^^^^^^^^^^^^^^^^^^^^^^^^^^^^^^^^^^^^^^^^^^^
  File "C:\Users\zamor\UltiBotInversiones\src\ultibot_backend\main.py", line 103, in log_requests
    response = await call_next(request)
               ^^^^^^^^^^^^^^^^^^^^^^^^
  File "C:\Users\zamor\UltiBotInversiones\.venv\Lib\site-packages\starlette\middleware\base.py", line 165, in call_next
    raise app_exc
  File "C:\Users\zamor\UltiBotInversiones\.venv\Lib\site-packages\starlette\middleware\base.py", line 151, in coro
    await self.app(scope, receive_or_disconnect, send_no_error)
  File "C:\Users\zamor\UltiBotInversiones\.venv\Lib\site-packages\starlette\middleware\exceptions.py", line 65, in __call__
    await wrap_app_handling_exceptions(self.app, conn)(scope, receive, send)
  File "C:\Users\zamor\UltiBotInversiones\.venv\Lib\site-packages\starlette\_exception_handler.py", line 64, in wrapped_app
    raise exc
  File "C:\Users\zamor\UltiBotInversiones\.venv\Lib\site-packages\starlette\_exception_handler.py", line 53, in wrapped_app
    await app(scope, receive, sender)
  File "C:\Users\zamor\UltiBotInversiones\.venv\Lib\site-packages\starlette\routing.py", line 756, in __call__
    await self.middleware_stack(scope, receive, send)
  File "C:\Users\zamor\UltiBotInversiones\.venv\Lib\site-packages\starlette\routing.py", line 776, in app
    await route.handle(scope, receive, send)
  File "C:\Users\zamor\UltiBotInversiones\.venv\Lib\site-packages\starlette\routing.py", line 297, in handle
    await self.app(scope, receive, send)
  File "C:\Users\zamor\UltiBotInversiones\.venv\Lib\site-packages\starlette\routing.py", line 77, in app
    await wrap_app_handling_exceptions(app, request)(scope, receive, send)
  File "C:\Users\zamor\UltiBotInversiones\.venv\Lib\site-packages\starlette\_exception_handler.py", line 64, in wrapped_app
    raise exc
  File "C:\Users\zamor\UltiBotInversiones\.venv\Lib\site-packages\starlette\_exception_handler.py", line 53, in wrapped_app
    await app(scope, receive, sender)
  File "C:\Users\zamor\UltiBotInversiones\.venv\Lib\site-packages\starlette\routing.py", line 72, in app
    response = await func(request)
               ^^^^^^^^^^^^^^^^^^^
  File "C:\Users\zamor\UltiBotInversiones\.venv\Lib\site-packages\fastapi\routing.py", line 269, in app
    solved_result = await solve_dependencies(
                    ^^^^^^^^^^^^^^^^^^^^^^^^^
  File "C:\Users\zamor\UltiBotInversiones\.venv\Lib\site-packages\fastapi\dependencies\utils.py", line 600, in solve_dependencies
    solved = await call(**sub_values)
             ^^^^^^^^^^^^^^^^^^^^^^^^
  File "C:\Users\zamor\UltiBotInversiones\src\ultibot_backend\dependencies.py", line 212, in get_performance_service
    assert container.performance_service is not None
           ^^^^^^^^^^^^^^^^^^^^^^^^^^^^^^^^^^^^^^^^^
AssertionError
2025-06-17 15:50:56,483 - ultibot_backend - INFO - [MainThread] - main.py:65 - Logging configurado exitosamente usando dictConfig.
2025-06-17 15:50:56,483 - ultibot_backend - INFO - [MainThread] - main.py:133 - Registrando routers de la API...
2025-06-17 15:50:56,502 - ultibot_backend - INFO - [MainThread] - main.py:145 - Todos los routers han sido registrados.
2025-06-17 15:50:56,502 - uvicorn.error - INFO - [MainThread] - server.py:82 - Started server process [9760]
2025-06-17 15:50:56,503 - uvicorn.error - INFO - [MainThread] - on.py:48 - Waiting for application startup.
2025-06-17 15:50:56,503 - ultibot_backend - INFO - [MainThread] - main.py:74 - Iniciando UltiBot Backend...
2025-06-17 15:50:56,503 - src.ultibot_backend.dependencies - INFO - [MainThread] - dependencies.py:47 - Initializing dependency container...
2025-06-17 15:50:56,503 - httpx - DEBUG - [MainThread] - _config.py:82 - load_ssl_context verify=True cert=None trust_env=True http2=False
2025-06-17 15:50:56,503 - httpx - DEBUG - [MainThread] - _config.py:148 - load_verify_locations cafile='C:\\Users\\zamor\\UltiBotInversiones\\.venv\\Lib\\site-packages\\certifi\\cacert.pem'
2025-06-17 15:50:56,691 - src.ultibot_backend.adapters.persistence_service - INFO - [MainThread] - persistence_service.py:68 - Pool de conexiones a Supabase (psycopg_pool) establecido exitosamente. Min: 2, Max: 10
2025-06-17 15:50:56,691 - httpx - DEBUG - [MainThread] - _config.py:82 - load_ssl_context verify=True cert=None trust_env=True http2=False
2025-06-17 15:50:56,691 - httpx - DEBUG - [MainThread] - _config.py:148 - load_verify_locations cafile='C:\\Users\\zamor\\UltiBotInversiones\\.venv\\Lib\\site-packages\\certifi\\cacert.pem'
2025-06-17 15:50:56,871 - src.ultibot_backend.services.order_execution_service - INFO - [MainThread] - order_execution_service.py:110 - Paper Trading Service inicializado con capital virtual: 10000.0 USDT
2025-06-17 15:50:56,871 - src.ultibot_backend.services.credential_service - INFO - [MainThread] - credential_service.py:28 - CredentialService __init__ intentando obtener encryption_key de ENV: Presente
2025-06-17 15:50:56,871 - src.ultibot_backend.services.credential_service - INFO - [MainThread] - credential_service.py:34 - Pasando la siguiente clave (str) a Fernet: m-28N... (truncada por seguridad)
2025-06-17 15:50:56,871 - src.ultibot_backend.services.unified_order_execution_service - INFO - [MainThread] - unified_order_execution_service.py:27 - UnifiedOrderExecutionService initialized with both real and paper execution services
2025-06-17 15:50:56,994 - src.ultibot_backend.services.ai_orchestrator_service - INFO - [MainThread] - ai_orchestrator_service.py:143 - AIOrchestrator initialized with gemini-1.5-pro-latest and PydanticOutputParser.
2025-06-17 15:50:56,995 - src.ultibot_backend.dependencies - INFO - [MainThread] - dependencies.py:126 - Dependency container initialized successfully.
2025-06-17 15:50:56,995 - ultibot_backend - INFO - [MainThread] - main.py:79 - Contenedor de dependencias inicializado.
2025-06-17 15:50:56,995 - ultibot_backend - INFO - [MainThread] - main.py:86 - Aplicación iniciada correctamente.
2025-06-17 15:50:56,996 - psycopg.pool - WARNING - [MainThread] - pool_async.py:691 - error connecting in 'supabase_pool': invalid connection option "sqlite:///./ultibot_local.db?sslmode"

2025-06-17 15:50:56,996 - psycopg.pool - WARNING - [MainThread] - pool_async.py:691 - error connecting in 'supabase_pool': invalid connection option "sqlite:///./ultibot_local.db?sslmode"

2025-06-17 15:50:56,996 - uvicorn.error - INFO - [MainThread] - on.py:62 - Application startup complete.
2025-06-17 15:50:58,042 - psycopg.pool - WARNING - [MainThread] - pool_async.py:691 - error connecting in 'supabase_pool': invalid connection option "sqlite:///./ultibot_local.db?sslmode"

2025-06-17 15:50:58,074 - psycopg.pool - WARNING - [MainThread] - pool_async.py:691 - error connecting in 'supabase_pool': invalid connection option "sqlite:///./ultibot_local.db?sslmode"

2025-06-17 15:51:00,140 - psycopg.pool - WARNING - [MainThread] - pool_async.py:691 - error connecting in 'supabase_pool': invalid connection option "sqlite:///./ultibot_local.db?sslmode"

2025-06-17 15:51:00,218 - psycopg.pool - WARNING - [MainThread] - pool_async.py:691 - error connecting in 'supabase_pool': invalid connection option "sqlite:///./ultibot_local.db?sslmode"

2025-06-17 15:51:01,115 - ultibot_backend - INFO - [MainThread] - main.py:102 - Middleware: Solicitud entrante: GET /api/v1/config
2025-06-17 15:51:01,115 - psycopg.pool - WARNING - [MainThread] - pool_async.py:691 - error connecting in 'supabase_pool': invalid connection option "sqlite:///./ultibot_local.db?sslmode"

2025-06-17 15:51:02,071 - psycopg.pool - WARNING - [MainThread] - pool_async.py:691 - error connecting in 'supabase_pool': invalid connection option "sqlite:///./ultibot_local.db?sslmode"

2025-06-17 15:51:04,019 - psycopg.pool - WARNING - [MainThread] - pool_async.py:691 - error connecting in 'supabase_pool': invalid connection option "sqlite:///./ultibot_local.db?sslmode"

2025-06-17 15:51:04,309 - psycopg.pool - WARNING - [MainThread] - pool_async.py:691 - error connecting in 'supabase_pool': invalid connection option "sqlite:///./ultibot_local.db?sslmode"

2025-06-17 15:51:04,483 - psycopg.pool - WARNING - [MainThread] - pool_async.py:691 - error connecting in 'supabase_pool': invalid connection option "sqlite:///./ultibot_local.db?sslmode"

2025-06-17 15:51:07,880 - psycopg.pool - WARNING - [MainThread] - pool_async.py:691 - error connecting in 'supabase_pool': invalid connection option "sqlite:///./ultibot_local.db?sslmode"

2025-06-17 15:51:12,641 - psycopg.pool - WARNING - [MainThread] - pool_async.py:691 - error connecting in 'supabase_pool': invalid connection option "sqlite:///./ultibot_local.db?sslmode"

2025-06-17 15:51:13,004 - psycopg.pool - WARNING - [MainThread] - pool_async.py:691 - error connecting in 'supabase_pool': invalid connection option "sqlite:///./ultibot_local.db?sslmode"

2025-06-17 15:51:15,576 - psycopg.pool - WARNING - [MainThread] - pool_async.py:691 - error connecting in 'supabase_pool': invalid connection option "sqlite:///./ultibot_local.db?sslmode"

2025-06-17 15:51:29,293 - psycopg.pool - WARNING - [MainThread] - pool_async.py:691 - error connecting in 'supabase_pool': invalid connection option "sqlite:///./ultibot_local.db?sslmode"

2025-06-17 15:51:30,030 - psycopg.pool - WARNING - [MainThread] - pool_async.py:691 - error connecting in 'supabase_pool': invalid connection option "sqlite:///./ultibot_local.db?sslmode"

2025-06-17 15:51:30,984 - psycopg.pool - WARNING - [MainThread] - pool_async.py:691 - error connecting in 'supabase_pool': invalid connection option "sqlite:///./ultibot_local.db?sslmode"

2025-06-17 15:51:31,111 - src.ultibot_backend.adapters.persistence_service - ERROR - [MainThread] - persistence_service.py:320 - Error al obtener configuración de usuario para 00000000-0000-0000-0000-000000000001 (psycopg_pool): couldn't get a connection after 30.00 sec
Traceback (most recent call last):
  File "c:\Users\zamor\UltiBotInversiones\src\ultibot_backend\adapters\persistence_service.py", line 312, in get_user_configuration
    async with self.pool.connection() as conn:
  File "C:\Program Files\Python311\Lib\contextlib.py", line 210, in __aenter__
    return await anext(self.gen)
           ^^^^^^^^^^^^^^^^^^^^^
  File "C:\Users\zamor\UltiBotInversiones\.venv\Lib\site-packages\psycopg_pool\pool_async.py", line 195, in connection
    conn = await self.getconn(timeout=timeout)
           ^^^^^^^^^^^^^^^^^^^^^^^^^^^^^^^^^^^
  File "C:\Users\zamor\UltiBotInversiones\.venv\Lib\site-packages\psycopg_pool\pool_async.py", line 230, in getconn
    raise PoolTimeout(
psycopg_pool.PoolTimeout: couldn't get a connection after 30.00 sec
2025-06-17 15:51:31,111 - src.ultibot_backend.services.config_service - ERROR - [MainThread] - config_service.py:69 - Error al cargar la configuración: couldn't get a connection after 30.00 sec
Traceback (most recent call last):
  File "c:\Users\zamor\UltiBotInversiones\src\ultibot_backend\services\config_service.py", line 53, in _load_config_from_db
    config_data = await self.persistence_service.get_user_configuration()
                  ^^^^^^^^^^^^^^^^^^^^^^^^^^^^^^^^^^^^^^^^^^^^^^^^^^^^^^^
  File "c:\Users\zamor\UltiBotInversiones\src\ultibot_backend\adapters\persistence_service.py", line 312, in get_user_configuration
    async with self.pool.connection() as conn:
  File "C:\Program Files\Python311\Lib\contextlib.py", line 210, in __aenter__
    return await anext(self.gen)
           ^^^^^^^^^^^^^^^^^^^^^
  File "C:\Users\zamor\UltiBotInversiones\.venv\Lib\site-packages\psycopg_pool\pool_async.py", line 195, in connection
    conn = await self.getconn(timeout=timeout)
           ^^^^^^^^^^^^^^^^^^^^^^^^^^^^^^^^^^^
  File "C:\Users\zamor\UltiBotInversiones\.venv\Lib\site-packages\psycopg_pool\pool_async.py", line 230, in getconn
    raise PoolTimeout(
psycopg_pool.PoolTimeout: couldn't get a connection after 30.00 sec
2025-06-17 15:51:31,116 - ultibot_backend - INFO - [MainThread] - main.py:104 - Middleware: Solicitud procesada: GET /api/v1/config - Status: 200
2025-06-17 15:51:31,116 - uvicorn.access - INFO - [MainThread] - httptools_impl.py:481 - 127.0.0.1:57590 - "GET /api/v1/config HTTP/1.1" 200
2025-06-17 15:58:36,761 - ultibot_backend - INFO - [MainThread] - main.py:65 - Logging configurado exitosamente usando dictConfig.
2025-06-17 15:58:36,761 - ultibot_backend - INFO - [MainThread] - main.py:133 - Registrando routers de la API...
2025-06-17 15:58:36,785 - ultibot_backend - INFO - [MainThread] - main.py:145 - Todos los routers han sido registrados.
2025-06-17 15:58:37,001 - qasync - INFO - [MainThread] - __init__.py:57 - Forcing use of PySide6 as Qt Implementation
2025-06-17 15:58:37,175 - matplotlib - DEBUG - [MainThread] - __init__.py:342 - matplotlib data path: C:\Users\zamor\UltiBotInversiones\.venv\Lib\site-packages\matplotlib\mpl-data
2025-06-17 15:58:37,185 - matplotlib - DEBUG - [MainThread] - __init__.py:342 - CONFIGDIR=C:\Users\zamor\.matplotlib
2025-06-17 15:58:37,185 - matplotlib - DEBUG - [MainThread] - __init__.py:1557 - interactive is False
2025-06-17 15:58:37,185 - matplotlib - DEBUG - [MainThread] - __init__.py:1558 - platform is win32
2025-06-17 15:58:37,241 - matplotlib - DEBUG - [MainThread] - __init__.py:342 - CACHEDIR=C:\Users\zamor\.matplotlib
2025-06-17 15:58:37,241 - matplotlib.font_manager - DEBUG - [MainThread] - font_manager.py:1635 - Using fontManager instance from C:\Users\zamor\.matplotlib\fontlist-v390.json
2025-06-17 15:59:39,441 - ultibot_backend - INFO - [MainThread] - main.py:65 - Logging configurado exitosamente usando dictConfig.
2025-06-17 15:59:39,441 - ultibot_backend - INFO - [MainThread] - main.py:133 - Registrando routers de la API...
2025-06-17 15:59:39,463 - ultibot_backend - INFO - [MainThread] - main.py:145 - Todos los routers han sido registrados.
2025-06-17 15:59:39,571 - qasync - INFO - [MainThread] - __init__.py:57 - Forcing use of PySide6 as Qt Implementation
2025-06-17 15:59:39,711 - matplotlib - DEBUG - [MainThread] - __init__.py:342 - matplotlib data path: C:\Users\zamor\UltiBotInversiones\.venv\Lib\site-packages\matplotlib\mpl-data
2025-06-17 15:59:39,720 - matplotlib - DEBUG - [MainThread] - __init__.py:342 - CONFIGDIR=C:\Users\zamor\.matplotlib
2025-06-17 15:59:39,721 - matplotlib - DEBUG - [MainThread] - __init__.py:1557 - interactive is False
2025-06-17 15:59:39,721 - matplotlib - DEBUG - [MainThread] - __init__.py:1558 - platform is win32
2025-06-17 15:59:39,771 - matplotlib - DEBUG - [MainThread] - __init__.py:342 - CACHEDIR=C:\Users\zamor\.matplotlib
2025-06-17 15:59:39,826 - matplotlib.font_manager - DEBUG - [MainThread] - font_manager.py:1635 - Using fontManager instance from C:\Users\zamor\.matplotlib\fontlist-v390.json
2025-06-17 15:59:40,481 - ultibot_backend - INFO - [Thread-1 (run_blocking_portal)] - main.py:102 - Middleware: Solicitud entrante: GET /api/v1/performance/strategies
2025-06-17 15:59:40,481 - ultibot_backend - CRITICAL - [Thread-1 (run_blocking_portal)] - main.py:117 - Excepción no controlada en GET /api/v1/performance/strategies: 
  + Exception Group Traceback (most recent call last):
  |   File "C:\Users\zamor\UltiBotInversiones\.venv\Lib\site-packages\starlette\_utils.py", line 87, in collapse_excgroups
  |     yield
  |   File "C:\Users\zamor\UltiBotInversiones\.venv\Lib\site-packages\starlette\middleware\base.py", line 190, in __call__
  |     async with anyio.create_task_group() as task_group:
  |   File "C:\Users\zamor\UltiBotInversiones\.venv\Lib\site-packages\anyio\_backends\_asyncio.py", line 772, in __aexit__
  |     raise BaseExceptionGroup(
  | ExceptionGroup: unhandled errors in a TaskGroup (1 sub-exception)
  +-+---------------- 1 ----------------
    | Traceback (most recent call last):
    |   File "C:\Users\zamor\UltiBotInversiones\.venv\Lib\site-packages\starlette\middleware\errors.py", line 164, in __call__
    |     await self.app(scope, receive, _send)
    |   File "C:\Users\zamor\UltiBotInversiones\.venv\Lib\site-packages\starlette\middleware\cors.py", line 85, in __call__
    |     await self.app(scope, receive, send)
    |   File "C:\Users\zamor\UltiBotInversiones\.venv\Lib\site-packages\starlette\middleware\base.py", line 189, in __call__
    |     with collapse_excgroups():
    |   File "C:\Program Files\Python311\Lib\contextlib.py", line 158, in __exit__
    |     self.gen.throw(typ, value, traceback)
    |   File "C:\Users\zamor\UltiBotInversiones\.venv\Lib\site-packages\starlette\_utils.py", line 93, in collapse_excgroups
    |     raise exc
    |   File "C:\Users\zamor\UltiBotInversiones\.venv\Lib\site-packages\starlette\middleware\base.py", line 191, in __call__
    |     response = await self.dispatch_func(request, call_next)
    |                ^^^^^^^^^^^^^^^^^^^^^^^^^^^^^^^^^^^^^^^^^^^^
    |   File "C:\Users\zamor\UltiBotInversiones\src\ultibot_backend\main.py", line 103, in log_requests
    |     response = await call_next(request)
    |                ^^^^^^^^^^^^^^^^^^^^^^^^
    |   File "C:\Users\zamor\UltiBotInversiones\.venv\Lib\site-packages\starlette\middleware\base.py", line 165, in call_next
    |     raise app_exc
    |   File "C:\Users\zamor\UltiBotInversiones\.venv\Lib\site-packages\starlette\middleware\base.py", line 151, in coro
    |     await self.app(scope, receive_or_disconnect, send_no_error)
    |   File "C:\Users\zamor\UltiBotInversiones\.venv\Lib\site-packages\starlette\middleware\exceptions.py", line 65, in __call__
    |     await wrap_app_handling_exceptions(self.app, conn)(scope, receive, send)
    |   File "C:\Users\zamor\UltiBotInversiones\.venv\Lib\site-packages\starlette\_exception_handler.py", line 64, in wrapped_app
    |     raise exc
    |   File "C:\Users\zamor\UltiBotInversiones\.venv\Lib\site-packages\starlette\_exception_handler.py", line 53, in wrapped_app
    |     await app(scope, receive, sender)
    |   File "C:\Users\zamor\UltiBotInversiones\.venv\Lib\site-packages\starlette\routing.py", line 756, in __call__
    |     await self.middleware_stack(scope, receive, send)
    |   File "C:\Users\zamor\UltiBotInversiones\.venv\Lib\site-packages\starlette\routing.py", line 776, in app
    |     await route.handle(scope, receive, send)
    |   File "C:\Users\zamor\UltiBotInversiones\.venv\Lib\site-packages\starlette\routing.py", line 297, in handle
    |     await self.app(scope, receive, send)
    |   File "C:\Users\zamor\UltiBotInversiones\.venv\Lib\site-packages\starlette\routing.py", line 77, in app
    |     await wrap_app_handling_exceptions(app, request)(scope, receive, send)
    |   File "C:\Users\zamor\UltiBotInversiones\.venv\Lib\site-packages\starlette\_exception_handler.py", line 64, in wrapped_app
    |     raise exc
    |   File "C:\Users\zamor\UltiBotInversiones\.venv\Lib\site-packages\starlette\_exception_handler.py", line 53, in wrapped_app
    |     await app(scope, receive, sender)
    |   File "C:\Users\zamor\UltiBotInversiones\.venv\Lib\site-packages\starlette\routing.py", line 72, in app
    |     response = await func(request)
    |                ^^^^^^^^^^^^^^^^^^^
    |   File "C:\Users\zamor\UltiBotInversiones\.venv\Lib\site-packages\fastapi\routing.py", line 269, in app
    |     solved_result = await solve_dependencies(
    |                     ^^^^^^^^^^^^^^^^^^^^^^^^^
    |   File "C:\Users\zamor\UltiBotInversiones\.venv\Lib\site-packages\fastapi\dependencies\utils.py", line 600, in solve_dependencies
    |     solved = await call(**sub_values)
    |              ^^^^^^^^^^^^^^^^^^^^^^^^
    |   File "C:\Users\zamor\UltiBotInversiones\src\ultibot_backend\dependencies.py", line 212, in get_performance_service
    |     assert container.performance_service is not None
    |            ^^^^^^^^^^^^^^^^^^^^^^^^^^^^^^^^^^^^^^^^^
    | AssertionError
    +------------------------------------

During handling of the above exception, another exception occurred:

Traceback (most recent call last):
  File "C:\Users\zamor\UltiBotInversiones\.venv\Lib\site-packages\starlette\middleware\errors.py", line 164, in __call__
    await self.app(scope, receive, _send)
  File "C:\Users\zamor\UltiBotInversiones\.venv\Lib\site-packages\starlette\middleware\cors.py", line 85, in __call__
    await self.app(scope, receive, send)
  File "C:\Users\zamor\UltiBotInversiones\.venv\Lib\site-packages\starlette\middleware\base.py", line 189, in __call__
    with collapse_excgroups():
  File "C:\Program Files\Python311\Lib\contextlib.py", line 158, in __exit__
    self.gen.throw(typ, value, traceback)
  File "C:\Users\zamor\UltiBotInversiones\.venv\Lib\site-packages\starlette\_utils.py", line 93, in collapse_excgroups
    raise exc
  File "C:\Users\zamor\UltiBotInversiones\.venv\Lib\site-packages\starlette\middleware\base.py", line 191, in __call__
    response = await self.dispatch_func(request, call_next)
               ^^^^^^^^^^^^^^^^^^^^^^^^^^^^^^^^^^^^^^^^^^^^
  File "C:\Users\zamor\UltiBotInversiones\src\ultibot_backend\main.py", line 103, in log_requests
    response = await call_next(request)
               ^^^^^^^^^^^^^^^^^^^^^^^^
  File "C:\Users\zamor\UltiBotInversiones\.venv\Lib\site-packages\starlette\middleware\base.py", line 165, in call_next
    raise app_exc
  File "C:\Users\zamor\UltiBotInversiones\.venv\Lib\site-packages\starlette\middleware\base.py", line 151, in coro
    await self.app(scope, receive_or_disconnect, send_no_error)
  File "C:\Users\zamor\UltiBotInversiones\.venv\Lib\site-packages\starlette\middleware\exceptions.py", line 65, in __call__
    await wrap_app_handling_exceptions(self.app, conn)(scope, receive, send)
  File "C:\Users\zamor\UltiBotInversiones\.venv\Lib\site-packages\starlette\_exception_handler.py", line 64, in wrapped_app
    raise exc
  File "C:\Users\zamor\UltiBotInversiones\.venv\Lib\site-packages\starlette\_exception_handler.py", line 53, in wrapped_app
    await app(scope, receive, sender)
  File "C:\Users\zamor\UltiBotInversiones\.venv\Lib\site-packages\starlette\routing.py", line 756, in __call__
    await self.middleware_stack(scope, receive, send)
  File "C:\Users\zamor\UltiBotInversiones\.venv\Lib\site-packages\starlette\routing.py", line 776, in app
    await route.handle(scope, receive, send)
  File "C:\Users\zamor\UltiBotInversiones\.venv\Lib\site-packages\starlette\routing.py", line 297, in handle
    await self.app(scope, receive, send)
  File "C:\Users\zamor\UltiBotInversiones\.venv\Lib\site-packages\starlette\routing.py", line 77, in app
    await wrap_app_handling_exceptions(app, request)(scope, receive, send)
  File "C:\Users\zamor\UltiBotInversiones\.venv\Lib\site-packages\starlette\_exception_handler.py", line 64, in wrapped_app
    raise exc
  File "C:\Users\zamor\UltiBotInversiones\.venv\Lib\site-packages\starlette\_exception_handler.py", line 53, in wrapped_app
    await app(scope, receive, sender)
  File "C:\Users\zamor\UltiBotInversiones\.venv\Lib\site-packages\starlette\routing.py", line 72, in app
    response = await func(request)
               ^^^^^^^^^^^^^^^^^^^
  File "C:\Users\zamor\UltiBotInversiones\.venv\Lib\site-packages\fastapi\routing.py", line 269, in app
    solved_result = await solve_dependencies(
                    ^^^^^^^^^^^^^^^^^^^^^^^^^
  File "C:\Users\zamor\UltiBotInversiones\.venv\Lib\site-packages\fastapi\dependencies\utils.py", line 600, in solve_dependencies
    solved = await call(**sub_values)
             ^^^^^^^^^^^^^^^^^^^^^^^^
  File "C:\Users\zamor\UltiBotInversiones\src\ultibot_backend\dependencies.py", line 212, in get_performance_service
    assert container.performance_service is not None
           ^^^^^^^^^^^^^^^^^^^^^^^^^^^^^^^^^^^^^^^^^
AssertionError
2025-06-17 16:00:38,971 - ultibot_backend - INFO - [MainThread] - main.py:65 - Logging configurado exitosamente usando dictConfig.
2025-06-17 16:00:38,971 - ultibot_backend - INFO - [MainThread] - main.py:133 - Registrando routers de la API...
2025-06-17 16:00:38,991 - ultibot_backend - INFO - [MainThread] - main.py:145 - Todos los routers han sido registrados.
2025-06-17 16:01:40,213 - ultibot_backend - INFO - [MainThread] - main.py:65 - Logging configurado exitosamente usando dictConfig.
2025-06-17 16:01:40,213 - ultibot_backend - INFO - [MainThread] - main.py:133 - Registrando routers de la API...
2025-06-17 16:01:40,231 - ultibot_backend - INFO - [MainThread] - main.py:145 - Todos los routers han sido registrados.
2025-06-17 16:01:40,271 - ultibot_backend - INFO - [MainThread] - main.py:65 - Logging configurado exitosamente usando dictConfig.
2025-06-17 16:01:40,271 - ultibot_backend - INFO - [MainThread] - main.py:133 - Registrando routers de la API...
2025-06-17 16:01:40,291 - ultibot_backend - INFO - [MainThread] - main.py:145 - Todos los routers han sido registrados.
2025-06-17 16:01:40,391 - qasync - INFO - [MainThread] - __init__.py:57 - Forcing use of PySide6 as Qt Implementation
2025-06-17 16:01:40,534 - matplotlib - DEBUG - [MainThread] - __init__.py:342 - matplotlib data path: C:\Users\zamor\UltiBotInversiones\.venv\Lib\site-packages\matplotlib\mpl-data
2025-06-17 16:01:40,543 - matplotlib - DEBUG - [MainThread] - __init__.py:342 - CONFIGDIR=C:\Users\zamor\.matplotlib
2025-06-17 16:01:40,544 - matplotlib - DEBUG - [MainThread] - __init__.py:1557 - interactive is False
2025-06-17 16:01:40,545 - matplotlib - DEBUG - [MainThread] - __init__.py:1558 - platform is win32
2025-06-17 16:01:40,661 - matplotlib - DEBUG - [MainThread] - __init__.py:342 - CACHEDIR=C:\Users\zamor\.matplotlib
2025-06-17 16:01:40,666 - matplotlib.font_manager - DEBUG - [MainThread] - font_manager.py:1635 - Using fontManager instance from C:\Users\zamor\.matplotlib\fontlist-v390.json
2025-06-17 16:01:41,281 - ultibot_backend - INFO - [Thread-1 (run_blocking_portal)] - main.py:102 - Middleware: Solicitud entrante: GET /api/v1/performance/strategies
2025-06-17 16:01:41,281 - ultibot_backend - CRITICAL - [Thread-1 (run_blocking_portal)] - main.py:117 - Excepción no controlada en GET /api/v1/performance/strategies: 
  + Exception Group Traceback (most recent call last):
  |   File "C:\Users\zamor\UltiBotInversiones\.venv\Lib\site-packages\starlette\_utils.py", line 87, in collapse_excgroups
  |     yield
  |   File "C:\Users\zamor\UltiBotInversiones\.venv\Lib\site-packages\starlette\middleware\base.py", line 190, in __call__
  |     async with anyio.create_task_group() as task_group:
  |   File "C:\Users\zamor\UltiBotInversiones\.venv\Lib\site-packages\anyio\_backends\_asyncio.py", line 772, in __aexit__
  |     raise BaseExceptionGroup(
  | ExceptionGroup: unhandled errors in a TaskGroup (1 sub-exception)
  +-+---------------- 1 ----------------
    | Traceback (most recent call last):
    |   File "C:\Users\zamor\UltiBotInversiones\.venv\Lib\site-packages\starlette\middleware\errors.py", line 164, in __call__
    |     await self.app(scope, receive, _send)
    |   File "C:\Users\zamor\UltiBotInversiones\.venv\Lib\site-packages\starlette\middleware\cors.py", line 85, in __call__
    |     await self.app(scope, receive, send)
    |   File "C:\Users\zamor\UltiBotInversiones\.venv\Lib\site-packages\starlette\middleware\base.py", line 189, in __call__
    |     with collapse_excgroups():
    |   File "C:\Program Files\Python311\Lib\contextlib.py", line 158, in __exit__
    |     self.gen.throw(typ, value, traceback)
    |   File "C:\Users\zamor\UltiBotInversiones\.venv\Lib\site-packages\starlette\_utils.py", line 93, in collapse_excgroups
    |     raise exc
    |   File "C:\Users\zamor\UltiBotInversiones\.venv\Lib\site-packages\starlette\middleware\base.py", line 191, in __call__
    |     response = await self.dispatch_func(request, call_next)
    |                ^^^^^^^^^^^^^^^^^^^^^^^^^^^^^^^^^^^^^^^^^^^^
    |   File "C:\Users\zamor\UltiBotInversiones\src\ultibot_backend\main.py", line 103, in log_requests
    |     response = await call_next(request)
    |                ^^^^^^^^^^^^^^^^^^^^^^^^
    |   File "C:\Users\zamor\UltiBotInversiones\.venv\Lib\site-packages\starlette\middleware\base.py", line 165, in call_next
    |     raise app_exc
    |   File "C:\Users\zamor\UltiBotInversiones\.venv\Lib\site-packages\starlette\middleware\base.py", line 151, in coro
    |     await self.app(scope, receive_or_disconnect, send_no_error)
    |   File "C:\Users\zamor\UltiBotInversiones\.venv\Lib\site-packages\starlette\middleware\exceptions.py", line 65, in __call__
    |     await wrap_app_handling_exceptions(self.app, conn)(scope, receive, send)
    |   File "C:\Users\zamor\UltiBotInversiones\.venv\Lib\site-packages\starlette\_exception_handler.py", line 64, in wrapped_app
    |     raise exc
    |   File "C:\Users\zamor\UltiBotInversiones\.venv\Lib\site-packages\starlette\_exception_handler.py", line 53, in wrapped_app
    |     await app(scope, receive, sender)
    |   File "C:\Users\zamor\UltiBotInversiones\.venv\Lib\site-packages\starlette\routing.py", line 756, in __call__
    |     await self.middleware_stack(scope, receive, send)
    |   File "C:\Users\zamor\UltiBotInversiones\.venv\Lib\site-packages\starlette\routing.py", line 776, in app
    |     await route.handle(scope, receive, send)
    |   File "C:\Users\zamor\UltiBotInversiones\.venv\Lib\site-packages\starlette\routing.py", line 297, in handle
    |     await self.app(scope, receive, send)
    |   File "C:\Users\zamor\UltiBotInversiones\.venv\Lib\site-packages\starlette\routing.py", line 77, in app
    |     await wrap_app_handling_exceptions(app, request)(scope, receive, send)
    |   File "C:\Users\zamor\UltiBotInversiones\.venv\Lib\site-packages\starlette\_exception_handler.py", line 64, in wrapped_app
    |     raise exc
    |   File "C:\Users\zamor\UltiBotInversiones\.venv\Lib\site-packages\starlette\_exception_handler.py", line 53, in wrapped_app
    |     await app(scope, receive, sender)
    |   File "C:\Users\zamor\UltiBotInversiones\.venv\Lib\site-packages\starlette\routing.py", line 72, in app
    |     response = await func(request)
    |                ^^^^^^^^^^^^^^^^^^^
    |   File "C:\Users\zamor\UltiBotInversiones\.venv\Lib\site-packages\fastapi\routing.py", line 269, in app
    |     solved_result = await solve_dependencies(
    |                     ^^^^^^^^^^^^^^^^^^^^^^^^^
    |   File "C:\Users\zamor\UltiBotInversiones\.venv\Lib\site-packages\fastapi\dependencies\utils.py", line 600, in solve_dependencies
    |     solved = await call(**sub_values)
    |              ^^^^^^^^^^^^^^^^^^^^^^^^
    |   File "C:\Users\zamor\UltiBotInversiones\src\ultibot_backend\dependencies.py", line 212, in get_performance_service
    |     assert container.performance_service is not None
    |            ^^^^^^^^^^^^^^^^^^^^^^^^^^^^^^^^^^^^^^^^^
    | AssertionError
    +------------------------------------

During handling of the above exception, another exception occurred:

Traceback (most recent call last):
  File "C:\Users\zamor\UltiBotInversiones\.venv\Lib\site-packages\starlette\middleware\errors.py", line 164, in __call__
    await self.app(scope, receive, _send)
  File "C:\Users\zamor\UltiBotInversiones\.venv\Lib\site-packages\starlette\middleware\cors.py", line 85, in __call__
    await self.app(scope, receive, send)
  File "C:\Users\zamor\UltiBotInversiones\.venv\Lib\site-packages\starlette\middleware\base.py", line 189, in __call__
    with collapse_excgroups():
  File "C:\Program Files\Python311\Lib\contextlib.py", line 158, in __exit__
    self.gen.throw(typ, value, traceback)
  File "C:\Users\zamor\UltiBotInversiones\.venv\Lib\site-packages\starlette\_utils.py", line 93, in collapse_excgroups
    raise exc
  File "C:\Users\zamor\UltiBotInversiones\.venv\Lib\site-packages\starlette\middleware\base.py", line 191, in __call__
    response = await self.dispatch_func(request, call_next)
               ^^^^^^^^^^^^^^^^^^^^^^^^^^^^^^^^^^^^^^^^^^^^
  File "C:\Users\zamor\UltiBotInversiones\src\ultibot_backend\main.py", line 103, in log_requests
    response = await call_next(request)
               ^^^^^^^^^^^^^^^^^^^^^^^^
  File "C:\Users\zamor\UltiBotInversiones\.venv\Lib\site-packages\starlette\middleware\base.py", line 165, in call_next
    raise app_exc
  File "C:\Users\zamor\UltiBotInversiones\.venv\Lib\site-packages\starlette\middleware\base.py", line 151, in coro
    await self.app(scope, receive_or_disconnect, send_no_error)
  File "C:\Users\zamor\UltiBotInversiones\.venv\Lib\site-packages\starlette\middleware\exceptions.py", line 65, in __call__
    await wrap_app_handling_exceptions(self.app, conn)(scope, receive, send)
  File "C:\Users\zamor\UltiBotInversiones\.venv\Lib\site-packages\starlette\_exception_handler.py", line 64, in wrapped_app
    raise exc
  File "C:\Users\zamor\UltiBotInversiones\.venv\Lib\site-packages\starlette\_exception_handler.py", line 53, in wrapped_app
    await app(scope, receive, sender)
  File "C:\Users\zamor\UltiBotInversiones\.venv\Lib\site-packages\starlette\routing.py", line 756, in __call__
    await self.middleware_stack(scope, receive, send)
  File "C:\Users\zamor\UltiBotInversiones\.venv\Lib\site-packages\starlette\routing.py", line 776, in app
    await route.handle(scope, receive, send)
  File "C:\Users\zamor\UltiBotInversiones\.venv\Lib\site-packages\starlette\routing.py", line 297, in handle
    await self.app(scope, receive, send)
  File "C:\Users\zamor\UltiBotInversiones\.venv\Lib\site-packages\starlette\routing.py", line 77, in app
    await wrap_app_handling_exceptions(app, request)(scope, receive, send)
  File "C:\Users\zamor\UltiBotInversiones\.venv\Lib\site-packages\starlette\_exception_handler.py", line 64, in wrapped_app
    raise exc
  File "C:\Users\zamor\UltiBotInversiones\.venv\Lib\site-packages\starlette\_exception_handler.py", line 53, in wrapped_app
    await app(scope, receive, sender)
  File "C:\Users\zamor\UltiBotInversiones\.venv\Lib\site-packages\starlette\routing.py", line 72, in app
    response = await func(request)
               ^^^^^^^^^^^^^^^^^^^
  File "C:\Users\zamor\UltiBotInversiones\.venv\Lib\site-packages\fastapi\routing.py", line 269, in app
    solved_result = await solve_dependencies(
                    ^^^^^^^^^^^^^^^^^^^^^^^^^
  File "C:\Users\zamor\UltiBotInversiones\.venv\Lib\site-packages\fastapi\dependencies\utils.py", line 600, in solve_dependencies
    solved = await call(**sub_values)
             ^^^^^^^^^^^^^^^^^^^^^^^^
  File "C:\Users\zamor\UltiBotInversiones\src\ultibot_backend\dependencies.py", line 212, in get_performance_service
    assert container.performance_service is not None
           ^^^^^^^^^^^^^^^^^^^^^^^^^^^^^^^^^^^^^^^^^
AssertionError
2025-06-17 16:02:29,297 - ultibot_backend - INFO - [MainThread] - main.py:65 - Logging configurado exitosamente usando dictConfig.
2025-06-17 16:02:29,301 - ultibot_backend - INFO - [MainThread] - main.py:133 - Registrando routers de la API...
2025-06-17 16:02:29,317 - ultibot_backend - INFO - [MainThread] - main.py:145 - Todos los routers han sido registrados.
2025-06-17 16:02:29,358 - ultibot_backend - INFO - [MainThread] - main.py:65 - Logging configurado exitosamente usando dictConfig.
2025-06-17 16:02:29,358 - ultibot_backend - INFO - [MainThread] - main.py:133 - Registrando routers de la API...
2025-06-17 16:02:29,374 - ultibot_backend - INFO - [MainThread] - main.py:145 - Todos los routers han sido registrados.
2025-06-17 16:02:29,481 - qasync - INFO - [MainThread] - __init__.py:57 - Forcing use of PySide6 as Qt Implementation
2025-06-17 16:02:29,624 - matplotlib - DEBUG - [MainThread] - __init__.py:342 - matplotlib data path: C:\Users\zamor\UltiBotInversiones\.venv\Lib\site-packages\matplotlib\mpl-data
2025-06-17 16:02:29,633 - matplotlib - DEBUG - [MainThread] - __init__.py:342 - CONFIGDIR=C:\Users\zamor\.matplotlib
2025-06-17 16:02:29,635 - matplotlib - DEBUG - [MainThread] - __init__.py:1557 - interactive is False
2025-06-17 16:02:29,635 - matplotlib - DEBUG - [MainThread] - __init__.py:1558 - platform is win32
2025-06-17 16:02:29,741 - matplotlib - DEBUG - [MainThread] - __init__.py:342 - CACHEDIR=C:\Users\zamor\.matplotlib
2025-06-17 16:02:29,741 - matplotlib.font_manager - DEBUG - [MainThread] - font_manager.py:1635 - Using fontManager instance from C:\Users\zamor\.matplotlib\fontlist-v390.json
2025-06-17 16:02:30,363 - ultibot_backend - INFO - [Thread-1 (run_blocking_portal)] - main.py:102 - Middleware: Solicitud entrante: GET /api/v1/performance/strategies
2025-06-17 16:02:30,364 - ultibot_backend - CRITICAL - [Thread-1 (run_blocking_portal)] - main.py:117 - Excepción no controlada en GET /api/v1/performance/strategies: 
  + Exception Group Traceback (most recent call last):
  |   File "C:\Users\zamor\UltiBotInversiones\.venv\Lib\site-packages\starlette\_utils.py", line 87, in collapse_excgroups
  |     yield
  |   File "C:\Users\zamor\UltiBotInversiones\.venv\Lib\site-packages\starlette\middleware\base.py", line 190, in __call__
  |     async with anyio.create_task_group() as task_group:
  |   File "C:\Users\zamor\UltiBotInversiones\.venv\Lib\site-packages\anyio\_backends\_asyncio.py", line 772, in __aexit__
  |     raise BaseExceptionGroup(
  | ExceptionGroup: unhandled errors in a TaskGroup (1 sub-exception)
  +-+---------------- 1 ----------------
    | Traceback (most recent call last):
    |   File "C:\Users\zamor\UltiBotInversiones\.venv\Lib\site-packages\starlette\middleware\errors.py", line 164, in __call__
    |     await self.app(scope, receive, _send)
    |   File "C:\Users\zamor\UltiBotInversiones\.venv\Lib\site-packages\starlette\middleware\cors.py", line 85, in __call__
    |     await self.app(scope, receive, send)
    |   File "C:\Users\zamor\UltiBotInversiones\.venv\Lib\site-packages\starlette\middleware\base.py", line 189, in __call__
    |     with collapse_excgroups():
    |   File "C:\Program Files\Python311\Lib\contextlib.py", line 158, in __exit__
    |     self.gen.throw(typ, value, traceback)
    |   File "C:\Users\zamor\UltiBotInversiones\.venv\Lib\site-packages\starlette\_utils.py", line 93, in collapse_excgroups
    |     raise exc
    |   File "C:\Users\zamor\UltiBotInversiones\.venv\Lib\site-packages\starlette\middleware\base.py", line 191, in __call__
    |     response = await self.dispatch_func(request, call_next)
    |                ^^^^^^^^^^^^^^^^^^^^^^^^^^^^^^^^^^^^^^^^^^^^
    |   File "C:\Users\zamor\UltiBotInversiones\src\ultibot_backend\main.py", line 103, in log_requests
    |     response = await call_next(request)
    |                ^^^^^^^^^^^^^^^^^^^^^^^^
    |   File "C:\Users\zamor\UltiBotInversiones\.venv\Lib\site-packages\starlette\middleware\base.py", line 165, in call_next
    |     raise app_exc
    |   File "C:\Users\zamor\UltiBotInversiones\.venv\Lib\site-packages\starlette\middleware\base.py", line 151, in coro
    |     await self.app(scope, receive_or_disconnect, send_no_error)
    |   File "C:\Users\zamor\UltiBotInversiones\.venv\Lib\site-packages\starlette\middleware\exceptions.py", line 65, in __call__
    |     await wrap_app_handling_exceptions(self.app, conn)(scope, receive, send)
    |   File "C:\Users\zamor\UltiBotInversiones\.venv\Lib\site-packages\starlette\_exception_handler.py", line 64, in wrapped_app
    |     raise exc
    |   File "C:\Users\zamor\UltiBotInversiones\.venv\Lib\site-packages\starlette\_exception_handler.py", line 53, in wrapped_app
    |     await app(scope, receive, sender)
    |   File "C:\Users\zamor\UltiBotInversiones\.venv\Lib\site-packages\starlette\routing.py", line 756, in __call__
    |     await self.middleware_stack(scope, receive, send)
    |   File "C:\Users\zamor\UltiBotInversiones\.venv\Lib\site-packages\starlette\routing.py", line 776, in app
    |     await route.handle(scope, receive, send)
    |   File "C:\Users\zamor\UltiBotInversiones\.venv\Lib\site-packages\starlette\routing.py", line 297, in handle
    |     await self.app(scope, receive, send)
    |   File "C:\Users\zamor\UltiBotInversiones\.venv\Lib\site-packages\starlette\routing.py", line 77, in app
    |     await wrap_app_handling_exceptions(app, request)(scope, receive, send)
    |   File "C:\Users\zamor\UltiBotInversiones\.venv\Lib\site-packages\starlette\_exception_handler.py", line 64, in wrapped_app
    |     raise exc
    |   File "C:\Users\zamor\UltiBotInversiones\.venv\Lib\site-packages\starlette\_exception_handler.py", line 53, in wrapped_app
    |     await app(scope, receive, sender)
    |   File "C:\Users\zamor\UltiBotInversiones\.venv\Lib\site-packages\starlette\routing.py", line 72, in app
    |     response = await func(request)
    |                ^^^^^^^^^^^^^^^^^^^
    |   File "C:\Users\zamor\UltiBotInversiones\.venv\Lib\site-packages\fastapi\routing.py", line 269, in app
    |     solved_result = await solve_dependencies(
    |                     ^^^^^^^^^^^^^^^^^^^^^^^^^
    |   File "C:\Users\zamor\UltiBotInversiones\.venv\Lib\site-packages\fastapi\dependencies\utils.py", line 600, in solve_dependencies
    |     solved = await call(**sub_values)
    |              ^^^^^^^^^^^^^^^^^^^^^^^^
    |   File "C:\Users\zamor\UltiBotInversiones\src\ultibot_backend\dependencies.py", line 212, in get_performance_service
    |     assert container.performance_service is not None
    |            ^^^^^^^^^^^^^^^^^^^^^^^^^^^^^^^^^^^^^^^^^
    | AssertionError
    +------------------------------------

During handling of the above exception, another exception occurred:

Traceback (most recent call last):
  File "C:\Users\zamor\UltiBotInversiones\.venv\Lib\site-packages\starlette\middleware\errors.py", line 164, in __call__
    await self.app(scope, receive, _send)
  File "C:\Users\zamor\UltiBotInversiones\.venv\Lib\site-packages\starlette\middleware\cors.py", line 85, in __call__
    await self.app(scope, receive, send)
  File "C:\Users\zamor\UltiBotInversiones\.venv\Lib\site-packages\starlette\middleware\base.py", line 189, in __call__
    with collapse_excgroups():
  File "C:\Program Files\Python311\Lib\contextlib.py", line 158, in __exit__
    self.gen.throw(typ, value, traceback)
  File "C:\Users\zamor\UltiBotInversiones\.venv\Lib\site-packages\starlette\_utils.py", line 93, in collapse_excgroups
    raise exc
  File "C:\Users\zamor\UltiBotInversiones\.venv\Lib\site-packages\starlette\middleware\base.py", line 191, in __call__
    response = await self.dispatch_func(request, call_next)
               ^^^^^^^^^^^^^^^^^^^^^^^^^^^^^^^^^^^^^^^^^^^^
  File "C:\Users\zamor\UltiBotInversiones\src\ultibot_backend\main.py", line 103, in log_requests
    response = await call_next(request)
               ^^^^^^^^^^^^^^^^^^^^^^^^
  File "C:\Users\zamor\UltiBotInversiones\.venv\Lib\site-packages\starlette\middleware\base.py", line 165, in call_next
    raise app_exc
  File "C:\Users\zamor\UltiBotInversiones\.venv\Lib\site-packages\starlette\middleware\base.py", line 151, in coro
    await self.app(scope, receive_or_disconnect, send_no_error)
  File "C:\Users\zamor\UltiBotInversiones\.venv\Lib\site-packages\starlette\middleware\exceptions.py", line 65, in __call__
    await wrap_app_handling_exceptions(self.app, conn)(scope, receive, send)
  File "C:\Users\zamor\UltiBotInversiones\.venv\Lib\site-packages\starlette\_exception_handler.py", line 64, in wrapped_app
    raise exc
  File "C:\Users\zamor\UltiBotInversiones\.venv\Lib\site-packages\starlette\_exception_handler.py", line 53, in wrapped_app
    await app(scope, receive, sender)
  File "C:\Users\zamor\UltiBotInversiones\.venv\Lib\site-packages\starlette\routing.py", line 756, in __call__
    await self.middleware_stack(scope, receive, send)
  File "C:\Users\zamor\UltiBotInversiones\.venv\Lib\site-packages\starlette\routing.py", line 776, in app
    await route.handle(scope, receive, send)
  File "C:\Users\zamor\UltiBotInversiones\.venv\Lib\site-packages\starlette\routing.py", line 297, in handle
    await self.app(scope, receive, send)
  File "C:\Users\zamor\UltiBotInversiones\.venv\Lib\site-packages\starlette\routing.py", line 77, in app
    await wrap_app_handling_exceptions(app, request)(scope, receive, send)
  File "C:\Users\zamor\UltiBotInversiones\.venv\Lib\site-packages\starlette\_exception_handler.py", line 64, in wrapped_app
    raise exc
  File "C:\Users\zamor\UltiBotInversiones\.venv\Lib\site-packages\starlette\_exception_handler.py", line 53, in wrapped_app
    await app(scope, receive, sender)
  File "C:\Users\zamor\UltiBotInversiones\.venv\Lib\site-packages\starlette\routing.py", line 72, in app
    response = await func(request)
               ^^^^^^^^^^^^^^^^^^^
  File "C:\Users\zamor\UltiBotInversiones\.venv\Lib\site-packages\fastapi\routing.py", line 269, in app
    solved_result = await solve_dependencies(
                    ^^^^^^^^^^^^^^^^^^^^^^^^^
  File "C:\Users\zamor\UltiBotInversiones\.venv\Lib\site-packages\fastapi\dependencies\utils.py", line 600, in solve_dependencies
    solved = await call(**sub_values)
             ^^^^^^^^^^^^^^^^^^^^^^^^
  File "C:\Users\zamor\UltiBotInversiones\src\ultibot_backend\dependencies.py", line 212, in get_performance_service
    assert container.performance_service is not None
           ^^^^^^^^^^^^^^^^^^^^^^^^^^^^^^^^^^^^^^^^^
AssertionError
2025-06-17 16:06:29,781 - ultibot_backend - INFO - [MainThread] - main.py:65 - Logging configurado exitosamente usando dictConfig.
2025-06-17 16:06:29,781 - ultibot_backend - INFO - [MainThread] - main.py:133 - Registrando routers de la API...
2025-06-17 16:06:29,801 - ultibot_backend - INFO - [MainThread] - main.py:145 - Todos los routers han sido registrados.
2025-06-17 16:06:29,851 - ultibot_backend - INFO - [MainThread] - main.py:65 - Logging configurado exitosamente usando dictConfig.
2025-06-17 16:06:29,851 - ultibot_backend - INFO - [MainThread] - main.py:133 - Registrando routers de la API...
2025-06-17 16:06:29,869 - ultibot_backend - INFO - [MainThread] - main.py:145 - Todos los routers han sido registrados.
2025-06-17 16:06:29,981 - qasync - INFO - [MainThread] - __init__.py:57 - Forcing use of PySide6 as Qt Implementation
2025-06-17 16:06:30,118 - matplotlib - DEBUG - [MainThread] - __init__.py:342 - matplotlib data path: C:\Users\zamor\UltiBotInversiones\.venv\Lib\site-packages\matplotlib\mpl-data
2025-06-17 16:06:30,129 - matplotlib - DEBUG - [MainThread] - __init__.py:342 - CONFIGDIR=C:\Users\zamor\.matplotlib
2025-06-17 16:06:30,130 - matplotlib - DEBUG - [MainThread] - __init__.py:1557 - interactive is False
2025-06-17 16:06:30,131 - matplotlib - DEBUG - [MainThread] - __init__.py:1558 - platform is win32
2025-06-17 16:06:30,247 - matplotlib - DEBUG - [MainThread] - __init__.py:342 - CACHEDIR=C:\Users\zamor\.matplotlib
2025-06-17 16:06:30,251 - matplotlib.font_manager - DEBUG - [MainThread] - font_manager.py:1635 - Using fontManager instance from C:\Users\zamor\.matplotlib\fontlist-v390.json
2025-06-17 16:06:30,899 - ultibot_backend - INFO - [Thread-1 (run_blocking_portal)] - main.py:102 - Middleware: Solicitud entrante: GET /api/v1/performance/strategies
2025-06-17 16:06:30,899 - ultibot_backend - CRITICAL - [Thread-1 (run_blocking_portal)] - main.py:117 - Excepción no controlada en GET /api/v1/performance/strategies: 
  + Exception Group Traceback (most recent call last):
  |   File "C:\Users\zamor\UltiBotInversiones\.venv\Lib\site-packages\starlette\_utils.py", line 87, in collapse_excgroups
  |     yield
  |   File "C:\Users\zamor\UltiBotInversiones\.venv\Lib\site-packages\starlette\middleware\base.py", line 190, in __call__
  |     async with anyio.create_task_group() as task_group:
  |   File "C:\Users\zamor\UltiBotInversiones\.venv\Lib\site-packages\anyio\_backends\_asyncio.py", line 772, in __aexit__
  |     raise BaseExceptionGroup(
  | ExceptionGroup: unhandled errors in a TaskGroup (1 sub-exception)
  +-+---------------- 1 ----------------
    | Traceback (most recent call last):
    |   File "C:\Users\zamor\UltiBotInversiones\.venv\Lib\site-packages\starlette\middleware\errors.py", line 164, in __call__
    |     await self.app(scope, receive, _send)
    |   File "C:\Users\zamor\UltiBotInversiones\.venv\Lib\site-packages\starlette\middleware\cors.py", line 85, in __call__
    |     await self.app(scope, receive, send)
    |   File "C:\Users\zamor\UltiBotInversiones\.venv\Lib\site-packages\starlette\middleware\base.py", line 189, in __call__
    |     with collapse_excgroups():
    |   File "C:\Program Files\Python311\Lib\contextlib.py", line 158, in __exit__
    |     self.gen.throw(typ, value, traceback)
    |   File "C:\Users\zamor\UltiBotInversiones\.venv\Lib\site-packages\starlette\_utils.py", line 93, in collapse_excgroups
    |     raise exc
    |   File "C:\Users\zamor\UltiBotInversiones\.venv\Lib\site-packages\starlette\middleware\base.py", line 191, in __call__
    |     response = await self.dispatch_func(request, call_next)
    |                ^^^^^^^^^^^^^^^^^^^^^^^^^^^^^^^^^^^^^^^^^^^^
    |   File "C:\Users\zamor\UltiBotInversiones\src\ultibot_backend\main.py", line 103, in log_requests
    |     response = await call_next(request)
    |                ^^^^^^^^^^^^^^^^^^^^^^^^
    |   File "C:\Users\zamor\UltiBotInversiones\.venv\Lib\site-packages\starlette\middleware\base.py", line 165, in call_next
    |     raise app_exc
    |   File "C:\Users\zamor\UltiBotInversiones\.venv\Lib\site-packages\starlette\middleware\base.py", line 151, in coro
    |     await self.app(scope, receive_or_disconnect, send_no_error)
    |   File "C:\Users\zamor\UltiBotInversiones\.venv\Lib\site-packages\starlette\middleware\exceptions.py", line 65, in __call__
    |     await wrap_app_handling_exceptions(self.app, conn)(scope, receive, send)
    |   File "C:\Users\zamor\UltiBotInversiones\.venv\Lib\site-packages\starlette\_exception_handler.py", line 64, in wrapped_app
    |     raise exc
    |   File "C:\Users\zamor\UltiBotInversiones\.venv\Lib\site-packages\starlette\_exception_handler.py", line 53, in wrapped_app
    |     await app(scope, receive, sender)
    |   File "C:\Users\zamor\UltiBotInversiones\.venv\Lib\site-packages\starlette\routing.py", line 756, in __call__
    |     await self.middleware_stack(scope, receive, send)
    |   File "C:\Users\zamor\UltiBotInversiones\.venv\Lib\site-packages\starlette\routing.py", line 776, in app
    |     await route.handle(scope, receive, send)
    |   File "C:\Users\zamor\UltiBotInversiones\.venv\Lib\site-packages\starlette\routing.py", line 297, in handle
    |     await self.app(scope, receive, send)
    |   File "C:\Users\zamor\UltiBotInversiones\.venv\Lib\site-packages\starlette\routing.py", line 77, in app
    |     await wrap_app_handling_exceptions(app, request)(scope, receive, send)
    |   File "C:\Users\zamor\UltiBotInversiones\.venv\Lib\site-packages\starlette\_exception_handler.py", line 64, in wrapped_app
    |     raise exc
    |   File "C:\Users\zamor\UltiBotInversiones\.venv\Lib\site-packages\starlette\_exception_handler.py", line 53, in wrapped_app
    |     await app(scope, receive, sender)
    |   File "C:\Users\zamor\UltiBotInversiones\.venv\Lib\site-packages\starlette\routing.py", line 72, in app
    |     response = await func(request)
    |                ^^^^^^^^^^^^^^^^^^^
    |   File "C:\Users\zamor\UltiBotInversiones\.venv\Lib\site-packages\fastapi\routing.py", line 269, in app
    |     solved_result = await solve_dependencies(
    |                     ^^^^^^^^^^^^^^^^^^^^^^^^^
    |   File "C:\Users\zamor\UltiBotInversiones\.venv\Lib\site-packages\fastapi\dependencies\utils.py", line 600, in solve_dependencies
    |     solved = await call(**sub_values)
    |              ^^^^^^^^^^^^^^^^^^^^^^^^
    |   File "C:\Users\zamor\UltiBotInversiones\src\ultibot_backend\dependencies.py", line 212, in get_performance_service
    |     assert container.performance_service is not None
    |            ^^^^^^^^^^^^^^^^^^^^^^^^^^^^^^^^^^^^^^^^^
    | AssertionError
    +------------------------------------

During handling of the above exception, another exception occurred:

Traceback (most recent call last):
  File "C:\Users\zamor\UltiBotInversiones\.venv\Lib\site-packages\starlette\middleware\errors.py", line 164, in __call__
    await self.app(scope, receive, _send)
  File "C:\Users\zamor\UltiBotInversiones\.venv\Lib\site-packages\starlette\middleware\cors.py", line 85, in __call__
    await self.app(scope, receive, send)
  File "C:\Users\zamor\UltiBotInversiones\.venv\Lib\site-packages\starlette\middleware\base.py", line 189, in __call__
    with collapse_excgroups():
  File "C:\Program Files\Python311\Lib\contextlib.py", line 158, in __exit__
    self.gen.throw(typ, value, traceback)
  File "C:\Users\zamor\UltiBotInversiones\.venv\Lib\site-packages\starlette\_utils.py", line 93, in collapse_excgroups
    raise exc
  File "C:\Users\zamor\UltiBotInversiones\.venv\Lib\site-packages\starlette\middleware\base.py", line 191, in __call__
    response = await self.dispatch_func(request, call_next)
               ^^^^^^^^^^^^^^^^^^^^^^^^^^^^^^^^^^^^^^^^^^^^
  File "C:\Users\zamor\UltiBotInversiones\src\ultibot_backend\main.py", line 103, in log_requests
    response = await call_next(request)
               ^^^^^^^^^^^^^^^^^^^^^^^^
  File "C:\Users\zamor\UltiBotInversiones\.venv\Lib\site-packages\starlette\middleware\base.py", line 165, in call_next
    raise app_exc
  File "C:\Users\zamor\UltiBotInversiones\.venv\Lib\site-packages\starlette\middleware\base.py", line 151, in coro
    await self.app(scope, receive_or_disconnect, send_no_error)
  File "C:\Users\zamor\UltiBotInversiones\.venv\Lib\site-packages\starlette\middleware\exceptions.py", line 65, in __call__
    await wrap_app_handling_exceptions(self.app, conn)(scope, receive, send)
  File "C:\Users\zamor\UltiBotInversiones\.venv\Lib\site-packages\starlette\_exception_handler.py", line 64, in wrapped_app
    raise exc
  File "C:\Users\zamor\UltiBotInversiones\.venv\Lib\site-packages\starlette\_exception_handler.py", line 53, in wrapped_app
    await app(scope, receive, sender)
  File "C:\Users\zamor\UltiBotInversiones\.venv\Lib\site-packages\starlette\routing.py", line 756, in __call__
    await self.middleware_stack(scope, receive, send)
  File "C:\Users\zamor\UltiBotInversiones\.venv\Lib\site-packages\starlette\routing.py", line 776, in app
    await route.handle(scope, receive, send)
  File "C:\Users\zamor\UltiBotInversiones\.venv\Lib\site-packages\starlette\routing.py", line 297, in handle
    await self.app(scope, receive, send)
  File "C:\Users\zamor\UltiBotInversiones\.venv\Lib\site-packages\starlette\routing.py", line 77, in app
    await wrap_app_handling_exceptions(app, request)(scope, receive, send)
  File "C:\Users\zamor\UltiBotInversiones\.venv\Lib\site-packages\starlette\_exception_handler.py", line 64, in wrapped_app
    raise exc
  File "C:\Users\zamor\UltiBotInversiones\.venv\Lib\site-packages\starlette\_exception_handler.py", line 53, in wrapped_app
    await app(scope, receive, sender)
  File "C:\Users\zamor\UltiBotInversiones\.venv\Lib\site-packages\starlette\routing.py", line 72, in app
    response = await func(request)
               ^^^^^^^^^^^^^^^^^^^
  File "C:\Users\zamor\UltiBotInversiones\.venv\Lib\site-packages\fastapi\routing.py", line 269, in app
    solved_result = await solve_dependencies(
                    ^^^^^^^^^^^^^^^^^^^^^^^^^
  File "C:\Users\zamor\UltiBotInversiones\.venv\Lib\site-packages\fastapi\dependencies\utils.py", line 600, in solve_dependencies
    solved = await call(**sub_values)
             ^^^^^^^^^^^^^^^^^^^^^^^^
  File "C:\Users\zamor\UltiBotInversiones\src\ultibot_backend\dependencies.py", line 212, in get_performance_service
    assert container.performance_service is not None
           ^^^^^^^^^^^^^^^^^^^^^^^^^^^^^^^^^^^^^^^^^
AssertionError
2025-06-17 16:08:19,047 - ultibot_backend - INFO - [MainThread] - main.py:65 - Logging configurado exitosamente usando dictConfig.
2025-06-17 16:08:19,047 - ultibot_backend - INFO - [MainThread] - main.py:136 - Registrando routers de la API...
2025-06-17 16:08:19,062 - ultibot_backend - INFO - [MainThread] - main.py:148 - Todos los routers han sido registrados.
2025-06-17 16:08:19,101 - ultibot_backend - INFO - [MainThread] - main.py:65 - Logging configurado exitosamente usando dictConfig.
2025-06-17 16:08:19,101 - ultibot_backend - INFO - [MainThread] - main.py:136 - Registrando routers de la API...
2025-06-17 16:08:19,121 - ultibot_backend - INFO - [MainThread] - main.py:148 - Todos los routers han sido registrados.
2025-06-17 16:08:19,231 - qasync - INFO - [MainThread] - __init__.py:57 - Forcing use of PySide6 as Qt Implementation
2025-06-17 16:08:19,367 - matplotlib - DEBUG - [MainThread] - __init__.py:342 - matplotlib data path: C:\Users\zamor\UltiBotInversiones\.venv\Lib\site-packages\matplotlib\mpl-data
2025-06-17 16:08:19,377 - matplotlib - DEBUG - [MainThread] - __init__.py:342 - CONFIGDIR=C:\Users\zamor\.matplotlib
2025-06-17 16:08:19,378 - matplotlib - DEBUG - [MainThread] - __init__.py:1557 - interactive is False
2025-06-17 16:08:19,379 - matplotlib - DEBUG - [MainThread] - __init__.py:1558 - platform is win32
2025-06-17 16:08:19,505 - matplotlib - DEBUG - [MainThread] - __init__.py:342 - CACHEDIR=C:\Users\zamor\.matplotlib
2025-06-17 16:08:19,512 - matplotlib.font_manager - DEBUG - [MainThread] - font_manager.py:1635 - Using fontManager instance from C:\Users\zamor\.matplotlib\fontlist-v390.json
2025-06-17 16:08:20,135 - ultibot_backend - INFO - [Thread-1 (run_blocking_portal)] - main.py:105 - Middleware: Solicitud entrante: GET /api/v1/performance/strategies
2025-06-17 16:08:20,135 - ultibot_backend - CRITICAL - [Thread-1 (run_blocking_portal)] - main.py:120 - Excepción no controlada en GET /api/v1/performance/strategies: 
  + Exception Group Traceback (most recent call last):
  |   File "C:\Users\zamor\UltiBotInversiones\.venv\Lib\site-packages\starlette\_utils.py", line 87, in collapse_excgroups
  |     yield
  |   File "C:\Users\zamor\UltiBotInversiones\.venv\Lib\site-packages\starlette\middleware\base.py", line 190, in __call__
  |     async with anyio.create_task_group() as task_group:
  |   File "C:\Users\zamor\UltiBotInversiones\.venv\Lib\site-packages\anyio\_backends\_asyncio.py", line 772, in __aexit__
  |     raise BaseExceptionGroup(
  | ExceptionGroup: unhandled errors in a TaskGroup (1 sub-exception)
  +-+---------------- 1 ----------------
    | Traceback (most recent call last):
    |   File "C:\Users\zamor\UltiBotInversiones\.venv\Lib\site-packages\starlette\middleware\errors.py", line 164, in __call__
    |     await self.app(scope, receive, _send)
    |   File "C:\Users\zamor\UltiBotInversiones\.venv\Lib\site-packages\starlette\middleware\cors.py", line 85, in __call__
    |     await self.app(scope, receive, send)
    |   File "C:\Users\zamor\UltiBotInversiones\.venv\Lib\site-packages\starlette\middleware\base.py", line 189, in __call__
    |     with collapse_excgroups():
    |   File "C:\Program Files\Python311\Lib\contextlib.py", line 158, in __exit__
    |     self.gen.throw(typ, value, traceback)
    |   File "C:\Users\zamor\UltiBotInversiones\.venv\Lib\site-packages\starlette\_utils.py", line 93, in collapse_excgroups
    |     raise exc
    |   File "C:\Users\zamor\UltiBotInversiones\.venv\Lib\site-packages\starlette\middleware\base.py", line 191, in __call__
    |     response = await self.dispatch_func(request, call_next)
    |                ^^^^^^^^^^^^^^^^^^^^^^^^^^^^^^^^^^^^^^^^^^^^
    |   File "C:\Users\zamor\UltiBotInversiones\src\ultibot_backend\main.py", line 106, in log_requests
    |     response = await call_next(request)
    |                ^^^^^^^^^^^^^^^^^^^^^^^^
    |   File "C:\Users\zamor\UltiBotInversiones\.venv\Lib\site-packages\starlette\middleware\base.py", line 165, in call_next
    |     raise app_exc
    |   File "C:\Users\zamor\UltiBotInversiones\.venv\Lib\site-packages\starlette\middleware\base.py", line 151, in coro
    |     await self.app(scope, receive_or_disconnect, send_no_error)
    |   File "C:\Users\zamor\UltiBotInversiones\.venv\Lib\site-packages\starlette\middleware\exceptions.py", line 65, in __call__
    |     await wrap_app_handling_exceptions(self.app, conn)(scope, receive, send)
    |   File "C:\Users\zamor\UltiBotInversiones\.venv\Lib\site-packages\starlette\_exception_handler.py", line 64, in wrapped_app
    |     raise exc
    |   File "C:\Users\zamor\UltiBotInversiones\.venv\Lib\site-packages\starlette\_exception_handler.py", line 53, in wrapped_app
    |     await app(scope, receive, sender)
    |   File "C:\Users\zamor\UltiBotInversiones\.venv\Lib\site-packages\starlette\routing.py", line 756, in __call__
    |     await self.middleware_stack(scope, receive, send)
    |   File "C:\Users\zamor\UltiBotInversiones\.venv\Lib\site-packages\starlette\routing.py", line 776, in app
    |     await route.handle(scope, receive, send)
    |   File "C:\Users\zamor\UltiBotInversiones\.venv\Lib\site-packages\starlette\routing.py", line 297, in handle
    |     await self.app(scope, receive, send)
    |   File "C:\Users\zamor\UltiBotInversiones\.venv\Lib\site-packages\starlette\routing.py", line 77, in app
    |     await wrap_app_handling_exceptions(app, request)(scope, receive, send)
    |   File "C:\Users\zamor\UltiBotInversiones\.venv\Lib\site-packages\starlette\_exception_handler.py", line 64, in wrapped_app
    |     raise exc
    |   File "C:\Users\zamor\UltiBotInversiones\.venv\Lib\site-packages\starlette\_exception_handler.py", line 53, in wrapped_app
    |     await app(scope, receive, sender)
    |   File "C:\Users\zamor\UltiBotInversiones\.venv\Lib\site-packages\starlette\routing.py", line 72, in app
    |     response = await func(request)
    |                ^^^^^^^^^^^^^^^^^^^
    |   File "C:\Users\zamor\UltiBotInversiones\.venv\Lib\site-packages\fastapi\routing.py", line 269, in app
    |     solved_result = await solve_dependencies(
    |                     ^^^^^^^^^^^^^^^^^^^^^^^^^
    |   File "C:\Users\zamor\UltiBotInversiones\.venv\Lib\site-packages\fastapi\dependencies\utils.py", line 600, in solve_dependencies
    |     solved = await call(**sub_values)
    |              ^^^^^^^^^^^^^^^^^^^^^^^^
    |   File "C:\Users\zamor\UltiBotInversiones\src\ultibot_backend\dependencies.py", line 212, in get_performance_service
    |     assert container.performance_service is not None
    |            ^^^^^^^^^^^^^^^^^^^^^^^^^^^^^^^^^^^^^^^^^
    | AssertionError
    +------------------------------------

During handling of the above exception, another exception occurred:

Traceback (most recent call last):
  File "C:\Users\zamor\UltiBotInversiones\.venv\Lib\site-packages\starlette\middleware\errors.py", line 164, in __call__
    await self.app(scope, receive, _send)
  File "C:\Users\zamor\UltiBotInversiones\.venv\Lib\site-packages\starlette\middleware\cors.py", line 85, in __call__
    await self.app(scope, receive, send)
  File "C:\Users\zamor\UltiBotInversiones\.venv\Lib\site-packages\starlette\middleware\base.py", line 189, in __call__
    with collapse_excgroups():
  File "C:\Program Files\Python311\Lib\contextlib.py", line 158, in __exit__
    self.gen.throw(typ, value, traceback)
  File "C:\Users\zamor\UltiBotInversiones\.venv\Lib\site-packages\starlette\_utils.py", line 93, in collapse_excgroups
    raise exc
  File "C:\Users\zamor\UltiBotInversiones\.venv\Lib\site-packages\starlette\middleware\base.py", line 191, in __call__
    response = await self.dispatch_func(request, call_next)
               ^^^^^^^^^^^^^^^^^^^^^^^^^^^^^^^^^^^^^^^^^^^^
  File "C:\Users\zamor\UltiBotInversiones\src\ultibot_backend\main.py", line 106, in log_requests
    response = await call_next(request)
               ^^^^^^^^^^^^^^^^^^^^^^^^
  File "C:\Users\zamor\UltiBotInversiones\.venv\Lib\site-packages\starlette\middleware\base.py", line 165, in call_next
    raise app_exc
  File "C:\Users\zamor\UltiBotInversiones\.venv\Lib\site-packages\starlette\middleware\base.py", line 151, in coro
    await self.app(scope, receive_or_disconnect, send_no_error)
  File "C:\Users\zamor\UltiBotInversiones\.venv\Lib\site-packages\starlette\middleware\exceptions.py", line 65, in __call__
    await wrap_app_handling_exceptions(self.app, conn)(scope, receive, send)
  File "C:\Users\zamor\UltiBotInversiones\.venv\Lib\site-packages\starlette\_exception_handler.py", line 64, in wrapped_app
    raise exc
  File "C:\Users\zamor\UltiBotInversiones\.venv\Lib\site-packages\starlette\_exception_handler.py", line 53, in wrapped_app
    await app(scope, receive, sender)
  File "C:\Users\zamor\UltiBotInversiones\.venv\Lib\site-packages\starlette\routing.py", line 756, in __call__
    await self.middleware_stack(scope, receive, send)
  File "C:\Users\zamor\UltiBotInversiones\.venv\Lib\site-packages\starlette\routing.py", line 776, in app
    await route.handle(scope, receive, send)
  File "C:\Users\zamor\UltiBotInversiones\.venv\Lib\site-packages\starlette\routing.py", line 297, in handle
    await self.app(scope, receive, send)
  File "C:\Users\zamor\UltiBotInversiones\.venv\Lib\site-packages\starlette\routing.py", line 77, in app
    await wrap_app_handling_exceptions(app, request)(scope, receive, send)
  File "C:\Users\zamor\UltiBotInversiones\.venv\Lib\site-packages\starlette\_exception_handler.py", line 64, in wrapped_app
    raise exc
  File "C:\Users\zamor\UltiBotInversiones\.venv\Lib\site-packages\starlette\_exception_handler.py", line 53, in wrapped_app
    await app(scope, receive, sender)
  File "C:\Users\zamor\UltiBotInversiones\.venv\Lib\site-packages\starlette\routing.py", line 72, in app
    response = await func(request)
               ^^^^^^^^^^^^^^^^^^^
  File "C:\Users\zamor\UltiBotInversiones\.venv\Lib\site-packages\fastapi\routing.py", line 269, in app
    solved_result = await solve_dependencies(
                    ^^^^^^^^^^^^^^^^^^^^^^^^^
  File "C:\Users\zamor\UltiBotInversiones\.venv\Lib\site-packages\fastapi\dependencies\utils.py", line 600, in solve_dependencies
    solved = await call(**sub_values)
             ^^^^^^^^^^^^^^^^^^^^^^^^
  File "C:\Users\zamor\UltiBotInversiones\src\ultibot_backend\dependencies.py", line 212, in get_performance_service
    assert container.performance_service is not None
           ^^^^^^^^^^^^^^^^^^^^^^^^^^^^^^^^^^^^^^^^^
AssertionError
2025-06-17 16:28:49,654 - ultibot_backend - INFO - [MainThread] - main.py:65 - Logging configurado exitosamente usando dictConfig.
2025-06-17 16:28:49,654 - ultibot_backend - INFO - [MainThread] - main.py:136 - Registrando routers de la API...
2025-06-17 16:28:49,675 - ultibot_backend - INFO - [MainThread] - main.py:148 - Todos los routers han sido registrados.
2025-06-17 16:28:49,727 - ultibot_backend - INFO - [MainThread] - main.py:65 - Logging configurado exitosamente usando dictConfig.
2025-06-17 16:28:49,727 - ultibot_backend - INFO - [MainThread] - main.py:136 - Registrando routers de la API...
2025-06-17 16:28:49,746 - ultibot_backend - INFO - [MainThread] - main.py:148 - Todos los routers han sido registrados.
2025-06-17 16:28:49,866 - qasync - INFO - [MainThread] - __init__.py:57 - Forcing use of PySide6 as Qt Implementation
2025-06-17 16:28:50,025 - matplotlib - DEBUG - [MainThread] - __init__.py:342 - matplotlib data path: C:\Users\zamor\UltiBotInversiones\.venv\Lib\site-packages\matplotlib\mpl-data
2025-06-17 16:28:50,035 - matplotlib - DEBUG - [MainThread] - __init__.py:342 - CONFIGDIR=C:\Users\zamor\.matplotlib
2025-06-17 16:28:50,038 - matplotlib - DEBUG - [MainThread] - __init__.py:1557 - interactive is False
2025-06-17 16:28:50,039 - matplotlib - DEBUG - [MainThread] - __init__.py:1558 - platform is win32
2025-06-17 16:28:50,172 - matplotlib - DEBUG - [MainThread] - __init__.py:342 - CACHEDIR=C:\Users\zamor\.matplotlib
2025-06-17 16:28:50,175 - matplotlib.font_manager - DEBUG - [MainThread] - font_manager.py:1635 - Using fontManager instance from C:\Users\zamor\.matplotlib\fontlist-v390.json
2025-06-17 16:28:50,876 - ultibot_backend - INFO - [Thread-1 (run_blocking_portal)] - main.py:105 - Middleware: Solicitud entrante: GET /api/v1/performance/strategies
2025-06-17 16:28:50,876 - ultibot_backend - CRITICAL - [Thread-1 (run_blocking_portal)] - main.py:120 - Excepción no controlada en GET /api/v1/performance/strategies: 'State' object has no attribute 'container'
  + Exception Group Traceback (most recent call last):
  |   File "C:\Users\zamor\UltiBotInversiones\.venv\Lib\site-packages\starlette\_utils.py", line 87, in collapse_excgroups
  |     yield
  |   File "C:\Users\zamor\UltiBotInversiones\.venv\Lib\site-packages\starlette\middleware\base.py", line 190, in __call__
  |     async with anyio.create_task_group() as task_group:
  |   File "C:\Users\zamor\UltiBotInversiones\.venv\Lib\site-packages\anyio\_backends\_asyncio.py", line 772, in __aexit__
  |     raise BaseExceptionGroup(
  | ExceptionGroup: unhandled errors in a TaskGroup (1 sub-exception)
  +-+---------------- 1 ----------------
    | Traceback (most recent call last):
    |   File "C:\Users\zamor\UltiBotInversiones\.venv\Lib\site-packages\starlette\middleware\errors.py", line 164, in __call__
    |     await self.app(scope, receive, _send)
    |   File "C:\Users\zamor\UltiBotInversiones\.venv\Lib\site-packages\starlette\middleware\cors.py", line 85, in __call__
    |     await self.app(scope, receive, send)
    |   File "C:\Users\zamor\UltiBotInversiones\.venv\Lib\site-packages\starlette\middleware\base.py", line 189, in __call__
    |     with collapse_excgroups():
    |   File "C:\Program Files\Python311\Lib\contextlib.py", line 158, in __exit__
    |     self.gen.throw(typ, value, traceback)
    |   File "C:\Users\zamor\UltiBotInversiones\.venv\Lib\site-packages\starlette\_utils.py", line 93, in collapse_excgroups
    |     raise exc
    |   File "C:\Users\zamor\UltiBotInversiones\.venv\Lib\site-packages\starlette\middleware\base.py", line 191, in __call__
    |     response = await self.dispatch_func(request, call_next)
    |                ^^^^^^^^^^^^^^^^^^^^^^^^^^^^^^^^^^^^^^^^^^^^
    |   File "C:\Users\zamor\UltiBotInversiones\src\ultibot_backend\main.py", line 106, in log_requests
    |     response = await call_next(request)
    |                ^^^^^^^^^^^^^^^^^^^^^^^^
    |   File "C:\Users\zamor\UltiBotInversiones\.venv\Lib\site-packages\starlette\middleware\base.py", line 165, in call_next
    |     raise app_exc
    |   File "C:\Users\zamor\UltiBotInversiones\.venv\Lib\site-packages\starlette\middleware\base.py", line 151, in coro
    |     await self.app(scope, receive_or_disconnect, send_no_error)
    |   File "C:\Users\zamor\UltiBotInversiones\.venv\Lib\site-packages\starlette\middleware\exceptions.py", line 65, in __call__
    |     await wrap_app_handling_exceptions(self.app, conn)(scope, receive, send)
    |   File "C:\Users\zamor\UltiBotInversiones\.venv\Lib\site-packages\starlette\_exception_handler.py", line 64, in wrapped_app
    |     raise exc
    |   File "C:\Users\zamor\UltiBotInversiones\.venv\Lib\site-packages\starlette\_exception_handler.py", line 53, in wrapped_app
    |     await app(scope, receive, sender)
    |   File "C:\Users\zamor\UltiBotInversiones\.venv\Lib\site-packages\starlette\routing.py", line 756, in __call__
    |     await self.middleware_stack(scope, receive, send)
    |   File "C:\Users\zamor\UltiBotInversiones\.venv\Lib\site-packages\starlette\routing.py", line 776, in app
    |     await route.handle(scope, receive, send)
    |   File "C:\Users\zamor\UltiBotInversiones\.venv\Lib\site-packages\starlette\routing.py", line 297, in handle
    |     await self.app(scope, receive, send)
    |   File "C:\Users\zamor\UltiBotInversiones\.venv\Lib\site-packages\starlette\routing.py", line 77, in app
    |     await wrap_app_handling_exceptions(app, request)(scope, receive, send)
    |   File "C:\Users\zamor\UltiBotInversiones\.venv\Lib\site-packages\starlette\_exception_handler.py", line 64, in wrapped_app
    |     raise exc
    |   File "C:\Users\zamor\UltiBotInversiones\.venv\Lib\site-packages\starlette\_exception_handler.py", line 53, in wrapped_app
    |     await app(scope, receive, sender)
    |   File "C:\Users\zamor\UltiBotInversiones\.venv\Lib\site-packages\starlette\routing.py", line 72, in app
    |     response = await func(request)
    |                ^^^^^^^^^^^^^^^^^^^
    |   File "C:\Users\zamor\UltiBotInversiones\.venv\Lib\site-packages\fastapi\routing.py", line 269, in app
    |     solved_result = await solve_dependencies(
    |                     ^^^^^^^^^^^^^^^^^^^^^^^^^
    |   File "C:\Users\zamor\UltiBotInversiones\.venv\Lib\site-packages\fastapi\dependencies\utils.py", line 600, in solve_dependencies
    |     solved = await call(**sub_values)
    |              ^^^^^^^^^^^^^^^^^^^^^^^^
    |   File "C:\Users\zamor\UltiBotInversiones\src\ultibot_backend\dependencies.py", line 211, in get_performance_service
    |     container = get_container(request)
    |                 ^^^^^^^^^^^^^^^^^^^^^^
    |   File "C:\Users\zamor\UltiBotInversiones\src\ultibot_backend\dependencies.py", line 141, in get_container
    |     return request.app.state.container
    |            ^^^^^^^^^^^^^^^^^^^^^^^^^^^
    |   File "C:\Users\zamor\UltiBotInversiones\.venv\Lib\site-packages\starlette\datastructures.py", line 702, in __getattr__
    |     raise AttributeError(message.format(self.__class__.__name__, key))
    | AttributeError: 'State' object has no attribute 'container'
    +------------------------------------

During handling of the above exception, another exception occurred:

Traceback (most recent call last):
  File "C:\Users\zamor\UltiBotInversiones\.venv\Lib\site-packages\starlette\middleware\errors.py", line 164, in __call__
    await self.app(scope, receive, _send)
  File "C:\Users\zamor\UltiBotInversiones\.venv\Lib\site-packages\starlette\middleware\cors.py", line 85, in __call__
    await self.app(scope, receive, send)
  File "C:\Users\zamor\UltiBotInversiones\.venv\Lib\site-packages\starlette\middleware\base.py", line 189, in __call__
    with collapse_excgroups():
  File "C:\Program Files\Python311\Lib\contextlib.py", line 158, in __exit__
    self.gen.throw(typ, value, traceback)
  File "C:\Users\zamor\UltiBotInversiones\.venv\Lib\site-packages\starlette\_utils.py", line 93, in collapse_excgroups
    raise exc
  File "C:\Users\zamor\UltiBotInversiones\.venv\Lib\site-packages\starlette\middleware\base.py", line 191, in __call__
    response = await self.dispatch_func(request, call_next)
               ^^^^^^^^^^^^^^^^^^^^^^^^^^^^^^^^^^^^^^^^^^^^
  File "C:\Users\zamor\UltiBotInversiones\src\ultibot_backend\main.py", line 106, in log_requests
    response = await call_next(request)
               ^^^^^^^^^^^^^^^^^^^^^^^^
  File "C:\Users\zamor\UltiBotInversiones\.venv\Lib\site-packages\starlette\middleware\base.py", line 165, in call_next
    raise app_exc
  File "C:\Users\zamor\UltiBotInversiones\.venv\Lib\site-packages\starlette\middleware\base.py", line 151, in coro
    await self.app(scope, receive_or_disconnect, send_no_error)
  File "C:\Users\zamor\UltiBotInversiones\.venv\Lib\site-packages\starlette\middleware\exceptions.py", line 65, in __call__
    await wrap_app_handling_exceptions(self.app, conn)(scope, receive, send)
  File "C:\Users\zamor\UltiBotInversiones\.venv\Lib\site-packages\starlette\_exception_handler.py", line 64, in wrapped_app
    raise exc
  File "C:\Users\zamor\UltiBotInversiones\.venv\Lib\site-packages\starlette\_exception_handler.py", line 53, in wrapped_app
    await app(scope, receive, sender)
  File "C:\Users\zamor\UltiBotInversiones\.venv\Lib\site-packages\starlette\routing.py", line 756, in __call__
    await self.middleware_stack(scope, receive, send)
  File "C:\Users\zamor\UltiBotInversiones\.venv\Lib\site-packages\starlette\routing.py", line 776, in app
    await route.handle(scope, receive, send)
  File "C:\Users\zamor\UltiBotInversiones\.venv\Lib\site-packages\starlette\routing.py", line 297, in handle
    await self.app(scope, receive, send)
  File "C:\Users\zamor\UltiBotInversiones\.venv\Lib\site-packages\starlette\routing.py", line 77, in app
    await wrap_app_handling_exceptions(app, request)(scope, receive, send)
  File "C:\Users\zamor\UltiBotInversiones\.venv\Lib\site-packages\starlette\_exception_handler.py", line 64, in wrapped_app
    raise exc
  File "C:\Users\zamor\UltiBotInversiones\.venv\Lib\site-packages\starlette\_exception_handler.py", line 53, in wrapped_app
    await app(scope, receive, sender)
  File "C:\Users\zamor\UltiBotInversiones\.venv\Lib\site-packages\starlette\routing.py", line 72, in app
    response = await func(request)
               ^^^^^^^^^^^^^^^^^^^
  File "C:\Users\zamor\UltiBotInversiones\.venv\Lib\site-packages\fastapi\routing.py", line 269, in app
    solved_result = await solve_dependencies(
                    ^^^^^^^^^^^^^^^^^^^^^^^^^
  File "C:\Users\zamor\UltiBotInversiones\.venv\Lib\site-packages\fastapi\dependencies\utils.py", line 600, in solve_dependencies
    solved = await call(**sub_values)
             ^^^^^^^^^^^^^^^^^^^^^^^^
  File "C:\Users\zamor\UltiBotInversiones\src\ultibot_backend\dependencies.py", line 211, in get_performance_service
    container = get_container(request)
                ^^^^^^^^^^^^^^^^^^^^^^
  File "C:\Users\zamor\UltiBotInversiones\src\ultibot_backend\dependencies.py", line 141, in get_container
    return request.app.state.container
           ^^^^^^^^^^^^^^^^^^^^^^^^^^^
  File "C:\Users\zamor\UltiBotInversiones\.venv\Lib\site-packages\starlette\datastructures.py", line 702, in __getattr__
    raise AttributeError(message.format(self.__class__.__name__, key))
AttributeError: 'State' object has no attribute 'container'
2025-06-17 16:33:39,304 - ultibot_backend - INFO - [MainThread] - main.py:65 - Logging configurado exitosamente usando dictConfig.
2025-06-17 16:33:39,304 - ultibot_backend - INFO - [MainThread] - main.py:136 - Registrando routers de la API...
2025-06-17 16:33:39,322 - ultibot_backend - INFO - [MainThread] - main.py:148 - Todos los routers han sido registrados.
2025-06-17 16:39:33,994 - ultibot_backend - INFO - [MainThread] - main.py:65 - Logging configurado exitosamente usando dictConfig.
2025-06-17 16:39:33,994 - ultibot_backend - INFO - [MainThread] - main.py:136 - Registrando routers de la API...
2025-06-17 16:39:34,012 - ultibot_backend - INFO - [MainThread] - main.py:148 - Todos los routers han sido registrados.
2025-06-17 16:39:34,334 - qasync - INFO - [MainThread] - __init__.py:57 - Forcing use of PySide6 as Qt Implementation
2025-06-17 16:39:34,476 - matplotlib - DEBUG - [MainThread] - __init__.py:342 - matplotlib data path: C:\Users\zamor\UltiBotInversiones\.venv\Lib\site-packages\matplotlib\mpl-data
2025-06-17 16:39:34,484 - matplotlib - DEBUG - [MainThread] - __init__.py:342 - CONFIGDIR=C:\Users\zamor\.matplotlib
2025-06-17 16:39:34,487 - matplotlib - DEBUG - [MainThread] - __init__.py:1557 - interactive is False
2025-06-17 16:39:34,488 - matplotlib - DEBUG - [MainThread] - __init__.py:1558 - platform is win32
2025-06-17 16:39:34,549 - matplotlib - DEBUG - [MainThread] - __init__.py:342 - CACHEDIR=C:\Users\zamor\.matplotlib
2025-06-17 16:39:34,552 - matplotlib.font_manager - DEBUG - [MainThread] - font_manager.py:1635 - Using fontManager instance from C:\Users\zamor\.matplotlib\fontlist-v390.json
2025-06-17 16:39:35,422 - ultibot_backend - INFO - [Thread-1 (run_blocking_portal)] - main.py:105 - Middleware: Solicitud entrante: GET /api/v1/performance/strategies
2025-06-17 16:39:35,422 - ultibot_backend - CRITICAL - [Thread-1 (run_blocking_portal)] - main.py:120 - Excepción no controlada en GET /api/v1/performance/strategies: 'State' object has no attribute 'container'
  + Exception Group Traceback (most recent call last):
  |   File "C:\Users\zamor\UltiBotInversiones\.venv\Lib\site-packages\starlette\_utils.py", line 87, in collapse_excgroups
  |     yield
  |   File "C:\Users\zamor\UltiBotInversiones\.venv\Lib\site-packages\starlette\middleware\base.py", line 190, in __call__
  |     async with anyio.create_task_group() as task_group:
  |   File "C:\Users\zamor\UltiBotInversiones\.venv\Lib\site-packages\anyio\_backends\_asyncio.py", line 772, in __aexit__
  |     raise BaseExceptionGroup(
  | ExceptionGroup: unhandled errors in a TaskGroup (1 sub-exception)
  +-+---------------- 1 ----------------
    | Traceback (most recent call last):
    |   File "C:\Users\zamor\UltiBotInversiones\.venv\Lib\site-packages\starlette\middleware\errors.py", line 164, in __call__
    |     await self.app(scope, receive, _send)
    |   File "C:\Users\zamor\UltiBotInversiones\.venv\Lib\site-packages\starlette\middleware\cors.py", line 85, in __call__
    |     await self.app(scope, receive, send)
    |   File "C:\Users\zamor\UltiBotInversiones\.venv\Lib\site-packages\starlette\middleware\base.py", line 189, in __call__
    |     with collapse_excgroups():
    |   File "C:\Program Files\Python311\Lib\contextlib.py", line 158, in __exit__
    |     self.gen.throw(typ, value, traceback)
    |   File "C:\Users\zamor\UltiBotInversiones\.venv\Lib\site-packages\starlette\_utils.py", line 93, in collapse_excgroups
    |     raise exc
    |   File "C:\Users\zamor\UltiBotInversiones\.venv\Lib\site-packages\starlette\middleware\base.py", line 191, in __call__
    |     response = await self.dispatch_func(request, call_next)
    |                ^^^^^^^^^^^^^^^^^^^^^^^^^^^^^^^^^^^^^^^^^^^^
    |   File "C:\Users\zamor\UltiBotInversiones\src\ultibot_backend\main.py", line 106, in log_requests
    |     response = await call_next(request)
    |                ^^^^^^^^^^^^^^^^^^^^^^^^
    |   File "C:\Users\zamor\UltiBotInversiones\.venv\Lib\site-packages\starlette\middleware\base.py", line 165, in call_next
    |     raise app_exc
    |   File "C:\Users\zamor\UltiBotInversiones\.venv\Lib\site-packages\starlette\middleware\base.py", line 151, in coro
    |     await self.app(scope, receive_or_disconnect, send_no_error)
    |   File "C:\Users\zamor\UltiBotInversiones\.venv\Lib\site-packages\starlette\middleware\exceptions.py", line 65, in __call__
    |     await wrap_app_handling_exceptions(self.app, conn)(scope, receive, send)
    |   File "C:\Users\zamor\UltiBotInversiones\.venv\Lib\site-packages\starlette\_exception_handler.py", line 64, in wrapped_app
    |     raise exc
    |   File "C:\Users\zamor\UltiBotInversiones\.venv\Lib\site-packages\starlette\_exception_handler.py", line 53, in wrapped_app
    |     await app(scope, receive, sender)
    |   File "C:\Users\zamor\UltiBotInversiones\.venv\Lib\site-packages\starlette\routing.py", line 756, in __call__
    |     await self.middleware_stack(scope, receive, send)
    |   File "C:\Users\zamor\UltiBotInversiones\.venv\Lib\site-packages\starlette\routing.py", line 776, in app
    |     await route.handle(scope, receive, send)
    |   File "C:\Users\zamor\UltiBotInversiones\.venv\Lib\site-packages\starlette\routing.py", line 297, in handle
    |     await self.app(scope, receive, send)
    |   File "C:\Users\zamor\UltiBotInversiones\.venv\Lib\site-packages\starlette\routing.py", line 77, in app
    |     await wrap_app_handling_exceptions(app, request)(scope, receive, send)
    |   File "C:\Users\zamor\UltiBotInversiones\.venv\Lib\site-packages\starlette\_exception_handler.py", line 64, in wrapped_app
    |     raise exc
    |   File "C:\Users\zamor\UltiBotInversiones\.venv\Lib\site-packages\starlette\_exception_handler.py", line 53, in wrapped_app
    |     await app(scope, receive, sender)
    |   File "C:\Users\zamor\UltiBotInversiones\.venv\Lib\site-packages\starlette\routing.py", line 72, in app
    |     response = await func(request)
    |                ^^^^^^^^^^^^^^^^^^^
    |   File "C:\Users\zamor\UltiBotInversiones\.venv\Lib\site-packages\fastapi\routing.py", line 269, in app
    |     solved_result = await solve_dependencies(
    |                     ^^^^^^^^^^^^^^^^^^^^^^^^^
    |   File "C:\Users\zamor\UltiBotInversiones\.venv\Lib\site-packages\fastapi\dependencies\utils.py", line 600, in solve_dependencies
    |     solved = await call(**sub_values)
    |              ^^^^^^^^^^^^^^^^^^^^^^^^
    |   File "C:\Users\zamor\UltiBotInversiones\src\ultibot_backend\dependencies.py", line 211, in get_performance_service
    |     container = get_container(request)
    |                 ^^^^^^^^^^^^^^^^^^^^^^
    |   File "C:\Users\zamor\UltiBotInversiones\src\ultibot_backend\dependencies.py", line 141, in get_container
    |     return request.app.state.container
    |            ^^^^^^^^^^^^^^^^^^^^^^^^^^^
    |   File "C:\Users\zamor\UltiBotInversiones\.venv\Lib\site-packages\starlette\datastructures.py", line 702, in __getattr__
    |     raise AttributeError(message.format(self.__class__.__name__, key))
    | AttributeError: 'State' object has no attribute 'container'
    +------------------------------------

During handling of the above exception, another exception occurred:

Traceback (most recent call last):
  File "C:\Users\zamor\UltiBotInversiones\.venv\Lib\site-packages\starlette\middleware\errors.py", line 164, in __call__
    await self.app(scope, receive, _send)
  File "C:\Users\zamor\UltiBotInversiones\.venv\Lib\site-packages\starlette\middleware\cors.py", line 85, in __call__
    await self.app(scope, receive, send)
  File "C:\Users\zamor\UltiBotInversiones\.venv\Lib\site-packages\starlette\middleware\base.py", line 189, in __call__
    with collapse_excgroups():
  File "C:\Program Files\Python311\Lib\contextlib.py", line 158, in __exit__
    self.gen.throw(typ, value, traceback)
  File "C:\Users\zamor\UltiBotInversiones\.venv\Lib\site-packages\starlette\_utils.py", line 93, in collapse_excgroups
    raise exc
  File "C:\Users\zamor\UltiBotInversiones\.venv\Lib\site-packages\starlette\middleware\base.py", line 191, in __call__
    response = await self.dispatch_func(request, call_next)
               ^^^^^^^^^^^^^^^^^^^^^^^^^^^^^^^^^^^^^^^^^^^^
  File "C:\Users\zamor\UltiBotInversiones\src\ultibot_backend\main.py", line 106, in log_requests
    response = await call_next(request)
               ^^^^^^^^^^^^^^^^^^^^^^^^
  File "C:\Users\zamor\UltiBotInversiones\.venv\Lib\site-packages\starlette\middleware\base.py", line 165, in call_next
    raise app_exc
  File "C:\Users\zamor\UltiBotInversiones\.venv\Lib\site-packages\starlette\middleware\base.py", line 151, in coro
    await self.app(scope, receive_or_disconnect, send_no_error)
  File "C:\Users\zamor\UltiBotInversiones\.venv\Lib\site-packages\starlette\middleware\exceptions.py", line 65, in __call__
    await wrap_app_handling_exceptions(self.app, conn)(scope, receive, send)
  File "C:\Users\zamor\UltiBotInversiones\.venv\Lib\site-packages\starlette\_exception_handler.py", line 64, in wrapped_app
    raise exc
  File "C:\Users\zamor\UltiBotInversiones\.venv\Lib\site-packages\starlette\_exception_handler.py", line 53, in wrapped_app
    await app(scope, receive, sender)
  File "C:\Users\zamor\UltiBotInversiones\.venv\Lib\site-packages\starlette\routing.py", line 756, in __call__
    await self.middleware_stack(scope, receive, send)
  File "C:\Users\zamor\UltiBotInversiones\.venv\Lib\site-packages\starlette\routing.py", line 776, in app
    await route.handle(scope, receive, send)
  File "C:\Users\zamor\UltiBotInversiones\.venv\Lib\site-packages\starlette\routing.py", line 297, in handle
    await self.app(scope, receive, send)
  File "C:\Users\zamor\UltiBotInversiones\.venv\Lib\site-packages\starlette\routing.py", line 77, in app
    await wrap_app_handling_exceptions(app, request)(scope, receive, send)
  File "C:\Users\zamor\UltiBotInversiones\.venv\Lib\site-packages\starlette\_exception_handler.py", line 64, in wrapped_app
    raise exc
  File "C:\Users\zamor\UltiBotInversiones\.venv\Lib\site-packages\starlette\_exception_handler.py", line 53, in wrapped_app
    await app(scope, receive, sender)
  File "C:\Users\zamor\UltiBotInversiones\.venv\Lib\site-packages\starlette\routing.py", line 72, in app
    response = await func(request)
               ^^^^^^^^^^^^^^^^^^^
  File "C:\Users\zamor\UltiBotInversiones\.venv\Lib\site-packages\fastapi\routing.py", line 269, in app
    solved_result = await solve_dependencies(
                    ^^^^^^^^^^^^^^^^^^^^^^^^^
  File "C:\Users\zamor\UltiBotInversiones\.venv\Lib\site-packages\fastapi\dependencies\utils.py", line 600, in solve_dependencies
    solved = await call(**sub_values)
             ^^^^^^^^^^^^^^^^^^^^^^^^
  File "C:\Users\zamor\UltiBotInversiones\src\ultibot_backend\dependencies.py", line 211, in get_performance_service
    container = get_container(request)
                ^^^^^^^^^^^^^^^^^^^^^^
  File "C:\Users\zamor\UltiBotInversiones\src\ultibot_backend\dependencies.py", line 141, in get_container
    return request.app.state.container
           ^^^^^^^^^^^^^^^^^^^^^^^^^^^
  File "C:\Users\zamor\UltiBotInversiones\.venv\Lib\site-packages\starlette\datastructures.py", line 702, in __getattr__
    raise AttributeError(message.format(self.__class__.__name__, key))
AttributeError: 'State' object has no attribute 'container'
2025-06-17 16:49:08,791 - ultibot_backend - INFO - [MainThread] - main.py:65 - Logging configurado exitosamente usando dictConfig.
2025-06-17 16:49:08,791 - ultibot_backend - INFO - [MainThread] - main.py:136 - Registrando routers de la API...
2025-06-17 16:49:08,810 - ultibot_backend - INFO - [MainThread] - main.py:148 - Todos los routers han sido registrados.
2025-06-17 16:49:08,963 - qasync - INFO - [MainThread] - __init__.py:57 - Forcing use of PySide6 as Qt Implementation
2025-06-17 16:49:09,112 - matplotlib - DEBUG - [MainThread] - __init__.py:342 - matplotlib data path: C:\Users\zamor\UltiBotInversiones\.venv\Lib\site-packages\matplotlib\mpl-data
2025-06-17 16:49:09,127 - matplotlib - DEBUG - [MainThread] - __init__.py:342 - CONFIGDIR=C:\Users\zamor\.matplotlib
2025-06-17 16:49:09,128 - matplotlib - DEBUG - [MainThread] - __init__.py:1557 - interactive is False
2025-06-17 16:49:09,128 - matplotlib - DEBUG - [MainThread] - __init__.py:1558 - platform is win32
2025-06-17 16:49:09,242 - matplotlib - DEBUG - [MainThread] - __init__.py:342 - CACHEDIR=C:\Users\zamor\.matplotlib
2025-06-17 16:49:09,246 - matplotlib.font_manager - DEBUG - [MainThread] - font_manager.py:1635 - Using fontManager instance from C:\Users\zamor\.matplotlib\fontlist-v390.json
2025-06-17 16:49:09,884 - ultibot_backend - INFO - [Thread-1 (run_blocking_portal)] - main.py:105 - Middleware: Solicitud entrante: GET /api/v1/performance/strategies
2025-06-17 16:49:09,884 - ultibot_backend - CRITICAL - [Thread-1 (run_blocking_portal)] - main.py:120 - Excepción no controlada en GET /api/v1/performance/strategies: 'State' object has no attribute 'container'
  + Exception Group Traceback (most recent call last):
  |   File "C:\Users\zamor\UltiBotInversiones\.venv\Lib\site-packages\starlette\_utils.py", line 87, in collapse_excgroups
  |     yield
  |   File "C:\Users\zamor\UltiBotInversiones\.venv\Lib\site-packages\starlette\middleware\base.py", line 190, in __call__
  |     async with anyio.create_task_group() as task_group:
  |   File "C:\Users\zamor\UltiBotInversiones\.venv\Lib\site-packages\anyio\_backends\_asyncio.py", line 772, in __aexit__
  |     raise BaseExceptionGroup(
  | ExceptionGroup: unhandled errors in a TaskGroup (1 sub-exception)
  +-+---------------- 1 ----------------
    | Traceback (most recent call last):
    |   File "C:\Users\zamor\UltiBotInversiones\.venv\Lib\site-packages\starlette\middleware\errors.py", line 164, in __call__
    |     await self.app(scope, receive, _send)
    |   File "C:\Users\zamor\UltiBotInversiones\.venv\Lib\site-packages\starlette\middleware\cors.py", line 85, in __call__
    |     await self.app(scope, receive, send)
    |   File "C:\Users\zamor\UltiBotInversiones\.venv\Lib\site-packages\starlette\middleware\base.py", line 189, in __call__
    |     with collapse_excgroups():
    |   File "C:\Program Files\Python311\Lib\contextlib.py", line 158, in __exit__
    |     self.gen.throw(typ, value, traceback)
    |   File "C:\Users\zamor\UltiBotInversiones\.venv\Lib\site-packages\starlette\_utils.py", line 93, in collapse_excgroups
    |     raise exc
    |   File "C:\Users\zamor\UltiBotInversiones\.venv\Lib\site-packages\starlette\middleware\base.py", line 191, in __call__
    |     response = await self.dispatch_func(request, call_next)
    |                ^^^^^^^^^^^^^^^^^^^^^^^^^^^^^^^^^^^^^^^^^^^^
    |   File "C:\Users\zamor\UltiBotInversiones\src\ultibot_backend\main.py", line 106, in log_requests
    |     response = await call_next(request)
    |                ^^^^^^^^^^^^^^^^^^^^^^^^
    |   File "C:\Users\zamor\UltiBotInversiones\.venv\Lib\site-packages\starlette\middleware\base.py", line 165, in call_next
    |     raise app_exc
    |   File "C:\Users\zamor\UltiBotInversiones\.venv\Lib\site-packages\starlette\middleware\base.py", line 151, in coro
    |     await self.app(scope, receive_or_disconnect, send_no_error)
    |   File "C:\Users\zamor\UltiBotInversiones\.venv\Lib\site-packages\starlette\middleware\exceptions.py", line 65, in __call__
    |     await wrap_app_handling_exceptions(self.app, conn)(scope, receive, send)
    |   File "C:\Users\zamor\UltiBotInversiones\.venv\Lib\site-packages\starlette\_exception_handler.py", line 64, in wrapped_app
    |     raise exc
    |   File "C:\Users\zamor\UltiBotInversiones\.venv\Lib\site-packages\starlette\_exception_handler.py", line 53, in wrapped_app
    |     await app(scope, receive, sender)
    |   File "C:\Users\zamor\UltiBotInversiones\.venv\Lib\site-packages\starlette\routing.py", line 756, in __call__
    |     await self.middleware_stack(scope, receive, send)
    |   File "C:\Users\zamor\UltiBotInversiones\.venv\Lib\site-packages\starlette\routing.py", line 776, in app
    |     await route.handle(scope, receive, send)
    |   File "C:\Users\zamor\UltiBotInversiones\.venv\Lib\site-packages\starlette\routing.py", line 297, in handle
    |     await self.app(scope, receive, send)
    |   File "C:\Users\zamor\UltiBotInversiones\.venv\Lib\site-packages\starlette\routing.py", line 77, in app
    |     await wrap_app_handling_exceptions(app, request)(scope, receive, send)
    |   File "C:\Users\zamor\UltiBotInversiones\.venv\Lib\site-packages\starlette\_exception_handler.py", line 64, in wrapped_app
    |     raise exc
    |   File "C:\Users\zamor\UltiBotInversiones\.venv\Lib\site-packages\starlette\_exception_handler.py", line 53, in wrapped_app
    |     await app(scope, receive, sender)
    |   File "C:\Users\zamor\UltiBotInversiones\.venv\Lib\site-packages\starlette\routing.py", line 72, in app
    |     response = await func(request)
    |                ^^^^^^^^^^^^^^^^^^^
    |   File "C:\Users\zamor\UltiBotInversiones\.venv\Lib\site-packages\fastapi\routing.py", line 269, in app
    |     solved_result = await solve_dependencies(
    |                     ^^^^^^^^^^^^^^^^^^^^^^^^^
    |   File "C:\Users\zamor\UltiBotInversiones\.venv\Lib\site-packages\fastapi\dependencies\utils.py", line 600, in solve_dependencies
    |     solved = await call(**sub_values)
    |              ^^^^^^^^^^^^^^^^^^^^^^^^
    |   File "C:\Users\zamor\UltiBotInversiones\src\ultibot_backend\dependencies.py", line 211, in get_performance_service
    |     container = get_container(request)
    |                 ^^^^^^^^^^^^^^^^^^^^^^
    |   File "C:\Users\zamor\UltiBotInversiones\src\ultibot_backend\dependencies.py", line 141, in get_container
    |     return request.app.state.container
    |            ^^^^^^^^^^^^^^^^^^^^^^^^^^^
    |   File "C:\Users\zamor\UltiBotInversiones\.venv\Lib\site-packages\starlette\datastructures.py", line 702, in __getattr__
    |     raise AttributeError(message.format(self.__class__.__name__, key))
    | AttributeError: 'State' object has no attribute 'container'
    +------------------------------------

During handling of the above exception, another exception occurred:

Traceback (most recent call last):
  File "C:\Users\zamor\UltiBotInversiones\.venv\Lib\site-packages\starlette\middleware\errors.py", line 164, in __call__
    await self.app(scope, receive, _send)
  File "C:\Users\zamor\UltiBotInversiones\.venv\Lib\site-packages\starlette\middleware\cors.py", line 85, in __call__
    await self.app(scope, receive, send)
  File "C:\Users\zamor\UltiBotInversiones\.venv\Lib\site-packages\starlette\middleware\base.py", line 189, in __call__
    with collapse_excgroups():
  File "C:\Program Files\Python311\Lib\contextlib.py", line 158, in __exit__
    self.gen.throw(typ, value, traceback)
  File "C:\Users\zamor\UltiBotInversiones\.venv\Lib\site-packages\starlette\_utils.py", line 93, in collapse_excgroups
    raise exc
  File "C:\Users\zamor\UltiBotInversiones\.venv\Lib\site-packages\starlette\middleware\base.py", line 191, in __call__
    response = await self.dispatch_func(request, call_next)
               ^^^^^^^^^^^^^^^^^^^^^^^^^^^^^^^^^^^^^^^^^^^^
  File "C:\Users\zamor\UltiBotInversiones\src\ultibot_backend\main.py", line 106, in log_requests
    response = await call_next(request)
               ^^^^^^^^^^^^^^^^^^^^^^^^
  File "C:\Users\zamor\UltiBotInversiones\.venv\Lib\site-packages\starlette\middleware\base.py", line 165, in call_next
    raise app_exc
  File "C:\Users\zamor\UltiBotInversiones\.venv\Lib\site-packages\starlette\middleware\base.py", line 151, in coro
    await self.app(scope, receive_or_disconnect, send_no_error)
  File "C:\Users\zamor\UltiBotInversiones\.venv\Lib\site-packages\starlette\middleware\exceptions.py", line 65, in __call__
    await wrap_app_handling_exceptions(self.app, conn)(scope, receive, send)
  File "C:\Users\zamor\UltiBotInversiones\.venv\Lib\site-packages\starlette\_exception_handler.py", line 64, in wrapped_app
    raise exc
  File "C:\Users\zamor\UltiBotInversiones\.venv\Lib\site-packages\starlette\_exception_handler.py", line 53, in wrapped_app
    await app(scope, receive, sender)
  File "C:\Users\zamor\UltiBotInversiones\.venv\Lib\site-packages\starlette\routing.py", line 756, in __call__
    await self.middleware_stack(scope, receive, send)
  File "C:\Users\zamor\UltiBotInversiones\.venv\Lib\site-packages\starlette\routing.py", line 776, in app
    await route.handle(scope, receive, send)
  File "C:\Users\zamor\UltiBotInversiones\.venv\Lib\site-packages\starlette\routing.py", line 297, in handle
    await self.app(scope, receive, send)
  File "C:\Users\zamor\UltiBotInversiones\.venv\Lib\site-packages\starlette\routing.py", line 77, in app
    await wrap_app_handling_exceptions(app, request)(scope, receive, send)
  File "C:\Users\zamor\UltiBotInversiones\.venv\Lib\site-packages\starlette\_exception_handler.py", line 64, in wrapped_app
    raise exc
  File "C:\Users\zamor\UltiBotInversiones\.venv\Lib\site-packages\starlette\_exception_handler.py", line 53, in wrapped_app
    await app(scope, receive, sender)
  File "C:\Users\zamor\UltiBotInversiones\.venv\Lib\site-packages\starlette\routing.py", line 72, in app
    response = await func(request)
               ^^^^^^^^^^^^^^^^^^^
  File "C:\Users\zamor\UltiBotInversiones\.venv\Lib\site-packages\fastapi\routing.py", line 269, in app
    solved_result = await solve_dependencies(
                    ^^^^^^^^^^^^^^^^^^^^^^^^^
  File "C:\Users\zamor\UltiBotInversiones\.venv\Lib\site-packages\fastapi\dependencies\utils.py", line 600, in solve_dependencies
    solved = await call(**sub_values)
             ^^^^^^^^^^^^^^^^^^^^^^^^
  File "C:\Users\zamor\UltiBotInversiones\src\ultibot_backend\dependencies.py", line 211, in get_performance_service
    container = get_container(request)
                ^^^^^^^^^^^^^^^^^^^^^^
  File "C:\Users\zamor\UltiBotInversiones\src\ultibot_backend\dependencies.py", line 141, in get_container
    return request.app.state.container
           ^^^^^^^^^^^^^^^^^^^^^^^^^^^
  File "C:\Users\zamor\UltiBotInversiones\.venv\Lib\site-packages\starlette\datastructures.py", line 702, in __getattr__
    raise AttributeError(message.format(self.__class__.__name__, key))
AttributeError: 'State' object has no attribute 'container'
2025-06-17 16:50:31,142 - ultibot_backend - INFO - [MainThread] - main.py:65 - Logging configurado exitosamente usando dictConfig.
2025-06-17 16:50:31,142 - ultibot_backend - INFO - [MainThread] - main.py:136 - Registrando routers de la API...
2025-06-17 16:50:31,163 - ultibot_backend - INFO - [MainThread] - main.py:148 - Todos los routers han sido registrados.
2025-06-17 16:50:31,307 - qasync - INFO - [MainThread] - __init__.py:57 - Forcing use of PySide6 as Qt Implementation
2025-06-17 16:50:31,451 - matplotlib - DEBUG - [MainThread] - __init__.py:342 - matplotlib data path: C:\Users\zamor\UltiBotInversiones\.venv\Lib\site-packages\matplotlib\mpl-data
2025-06-17 16:50:31,462 - matplotlib - DEBUG - [MainThread] - __init__.py:342 - CONFIGDIR=C:\Users\zamor\.matplotlib
2025-06-17 16:50:31,462 - matplotlib - DEBUG - [MainThread] - __init__.py:1557 - interactive is False
2025-06-17 16:50:31,464 - matplotlib - DEBUG - [MainThread] - __init__.py:1558 - platform is win32
2025-06-17 16:50:31,513 - matplotlib - DEBUG - [MainThread] - __init__.py:342 - CACHEDIR=C:\Users\zamor\.matplotlib
2025-06-17 16:50:31,577 - matplotlib.font_manager - DEBUG - [MainThread] - font_manager.py:1635 - Using fontManager instance from C:\Users\zamor\.matplotlib\fontlist-v390.json
2025-06-17 16:50:32,211 - ultibot_backend - INFO - [Thread-1 (run_blocking_portal)] - main.py:105 - Middleware: Solicitud entrante: GET /api/v1/performance/strategies
2025-06-17 16:50:32,213 - ultibot_backend - CRITICAL - [Thread-1 (run_blocking_portal)] - main.py:120 - Excepción no controlada en GET /api/v1/performance/strategies: 'State' object has no attribute 'container'
  + Exception Group Traceback (most recent call last):
  |   File "C:\Users\zamor\UltiBotInversiones\.venv\Lib\site-packages\starlette\_utils.py", line 87, in collapse_excgroups
  |     yield
  |   File "C:\Users\zamor\UltiBotInversiones\.venv\Lib\site-packages\starlette\middleware\base.py", line 190, in __call__
  |     async with anyio.create_task_group() as task_group:
  |   File "C:\Users\zamor\UltiBotInversiones\.venv\Lib\site-packages\anyio\_backends\_asyncio.py", line 772, in __aexit__
  |     raise BaseExceptionGroup(
  | ExceptionGroup: unhandled errors in a TaskGroup (1 sub-exception)
  +-+---------------- 1 ----------------
    | Traceback (most recent call last):
    |   File "C:\Users\zamor\UltiBotInversiones\.venv\Lib\site-packages\starlette\middleware\errors.py", line 164, in __call__
    |     await self.app(scope, receive, _send)
    |   File "C:\Users\zamor\UltiBotInversiones\.venv\Lib\site-packages\starlette\middleware\cors.py", line 85, in __call__
    |     await self.app(scope, receive, send)
    |   File "C:\Users\zamor\UltiBotInversiones\.venv\Lib\site-packages\starlette\middleware\base.py", line 189, in __call__
    |     with collapse_excgroups():
    |   File "C:\Program Files\Python311\Lib\contextlib.py", line 158, in __exit__
    |     self.gen.throw(typ, value, traceback)
    |   File "C:\Users\zamor\UltiBotInversiones\.venv\Lib\site-packages\starlette\_utils.py", line 93, in collapse_excgroups
    |     raise exc
    |   File "C:\Users\zamor\UltiBotInversiones\.venv\Lib\site-packages\starlette\middleware\base.py", line 191, in __call__
    |     response = await self.dispatch_func(request, call_next)
    |                ^^^^^^^^^^^^^^^^^^^^^^^^^^^^^^^^^^^^^^^^^^^^
    |   File "C:\Users\zamor\UltiBotInversiones\src\ultibot_backend\main.py", line 106, in log_requests
    |     response = await call_next(request)
    |                ^^^^^^^^^^^^^^^^^^^^^^^^
    |   File "C:\Users\zamor\UltiBotInversiones\.venv\Lib\site-packages\starlette\middleware\base.py", line 165, in call_next
    |     raise app_exc
    |   File "C:\Users\zamor\UltiBotInversiones\.venv\Lib\site-packages\starlette\middleware\base.py", line 151, in coro
    |     await self.app(scope, receive_or_disconnect, send_no_error)
    |   File "C:\Users\zamor\UltiBotInversiones\.venv\Lib\site-packages\starlette\middleware\exceptions.py", line 65, in __call__
    |     await wrap_app_handling_exceptions(self.app, conn)(scope, receive, send)
    |   File "C:\Users\zamor\UltiBotInversiones\.venv\Lib\site-packages\starlette\_exception_handler.py", line 64, in wrapped_app
    |     raise exc
    |   File "C:\Users\zamor\UltiBotInversiones\.venv\Lib\site-packages\starlette\_exception_handler.py", line 53, in wrapped_app
    |     await app(scope, receive, sender)
    |   File "C:\Users\zamor\UltiBotInversiones\.venv\Lib\site-packages\starlette\routing.py", line 756, in __call__
    |     await self.middleware_stack(scope, receive, send)
    |   File "C:\Users\zamor\UltiBotInversiones\.venv\Lib\site-packages\starlette\routing.py", line 776, in app
    |     await route.handle(scope, receive, send)
    |   File "C:\Users\zamor\UltiBotInversiones\.venv\Lib\site-packages\starlette\routing.py", line 297, in handle
    |     await self.app(scope, receive, send)
    |   File "C:\Users\zamor\UltiBotInversiones\.venv\Lib\site-packages\starlette\routing.py", line 77, in app
    |     await wrap_app_handling_exceptions(app, request)(scope, receive, send)
    |   File "C:\Users\zamor\UltiBotInversiones\.venv\Lib\site-packages\starlette\_exception_handler.py", line 64, in wrapped_app
    |     raise exc
    |   File "C:\Users\zamor\UltiBotInversiones\.venv\Lib\site-packages\starlette\_exception_handler.py", line 53, in wrapped_app
    |     await app(scope, receive, sender)
    |   File "C:\Users\zamor\UltiBotInversiones\.venv\Lib\site-packages\starlette\routing.py", line 72, in app
    |     response = await func(request)
    |                ^^^^^^^^^^^^^^^^^^^
    |   File "C:\Users\zamor\UltiBotInversiones\.venv\Lib\site-packages\fastapi\routing.py", line 269, in app
    |     solved_result = await solve_dependencies(
    |                     ^^^^^^^^^^^^^^^^^^^^^^^^^
    |   File "C:\Users\zamor\UltiBotInversiones\.venv\Lib\site-packages\fastapi\dependencies\utils.py", line 600, in solve_dependencies
    |     solved = await call(**sub_values)
    |              ^^^^^^^^^^^^^^^^^^^^^^^^
    |   File "C:\Users\zamor\UltiBotInversiones\src\ultibot_backend\dependencies.py", line 211, in get_performance_service
    |     container = get_container(request)
    |                 ^^^^^^^^^^^^^^^^^^^^^^
    |   File "C:\Users\zamor\UltiBotInversiones\src\ultibot_backend\dependencies.py", line 141, in get_container
    |     return request.app.state.container
    |            ^^^^^^^^^^^^^^^^^^^^^^^^^^^
    |   File "C:\Users\zamor\UltiBotInversiones\.venv\Lib\site-packages\starlette\datastructures.py", line 702, in __getattr__
    |     raise AttributeError(message.format(self.__class__.__name__, key))
    | AttributeError: 'State' object has no attribute 'container'
    +------------------------------------

During handling of the above exception, another exception occurred:

Traceback (most recent call last):
  File "C:\Users\zamor\UltiBotInversiones\.venv\Lib\site-packages\starlette\middleware\errors.py", line 164, in __call__
    await self.app(scope, receive, _send)
  File "C:\Users\zamor\UltiBotInversiones\.venv\Lib\site-packages\starlette\middleware\cors.py", line 85, in __call__
    await self.app(scope, receive, send)
  File "C:\Users\zamor\UltiBotInversiones\.venv\Lib\site-packages\starlette\middleware\base.py", line 189, in __call__
    with collapse_excgroups():
  File "C:\Program Files\Python311\Lib\contextlib.py", line 158, in __exit__
    self.gen.throw(typ, value, traceback)
  File "C:\Users\zamor\UltiBotInversiones\.venv\Lib\site-packages\starlette\_utils.py", line 93, in collapse_excgroups
    raise exc
  File "C:\Users\zamor\UltiBotInversiones\.venv\Lib\site-packages\starlette\middleware\base.py", line 191, in __call__
    response = await self.dispatch_func(request, call_next)
               ^^^^^^^^^^^^^^^^^^^^^^^^^^^^^^^^^^^^^^^^^^^^
  File "C:\Users\zamor\UltiBotInversiones\src\ultibot_backend\main.py", line 106, in log_requests
    response = await call_next(request)
               ^^^^^^^^^^^^^^^^^^^^^^^^
  File "C:\Users\zamor\UltiBotInversiones\.venv\Lib\site-packages\starlette\middleware\base.py", line 165, in call_next
    raise app_exc
  File "C:\Users\zamor\UltiBotInversiones\.venv\Lib\site-packages\starlette\middleware\base.py", line 151, in coro
    await self.app(scope, receive_or_disconnect, send_no_error)
  File "C:\Users\zamor\UltiBotInversiones\.venv\Lib\site-packages\starlette\middleware\exceptions.py", line 65, in __call__
    await wrap_app_handling_exceptions(self.app, conn)(scope, receive, send)
  File "C:\Users\zamor\UltiBotInversiones\.venv\Lib\site-packages\starlette\_exception_handler.py", line 64, in wrapped_app
    raise exc
  File "C:\Users\zamor\UltiBotInversiones\.venv\Lib\site-packages\starlette\_exception_handler.py", line 53, in wrapped_app
    await app(scope, receive, sender)
  File "C:\Users\zamor\UltiBotInversiones\.venv\Lib\site-packages\starlette\routing.py", line 756, in __call__
    await self.middleware_stack(scope, receive, send)
  File "C:\Users\zamor\UltiBotInversiones\.venv\Lib\site-packages\starlette\routing.py", line 776, in app
    await route.handle(scope, receive, send)
  File "C:\Users\zamor\UltiBotInversiones\.venv\Lib\site-packages\starlette\routing.py", line 297, in handle
    await self.app(scope, receive, send)
  File "C:\Users\zamor\UltiBotInversiones\.venv\Lib\site-packages\starlette\routing.py", line 77, in app
    await wrap_app_handling_exceptions(app, request)(scope, receive, send)
  File "C:\Users\zamor\UltiBotInversiones\.venv\Lib\site-packages\starlette\_exception_handler.py", line 64, in wrapped_app
    raise exc
  File "C:\Users\zamor\UltiBotInversiones\.venv\Lib\site-packages\starlette\_exception_handler.py", line 53, in wrapped_app
    await app(scope, receive, sender)
  File "C:\Users\zamor\UltiBotInversiones\.venv\Lib\site-packages\starlette\routing.py", line 72, in app
    response = await func(request)
               ^^^^^^^^^^^^^^^^^^^
  File "C:\Users\zamor\UltiBotInversiones\.venv\Lib\site-packages\fastapi\routing.py", line 269, in app
    solved_result = await solve_dependencies(
                    ^^^^^^^^^^^^^^^^^^^^^^^^^
  File "C:\Users\zamor\UltiBotInversiones\.venv\Lib\site-packages\fastapi\dependencies\utils.py", line 600, in solve_dependencies
    solved = await call(**sub_values)
             ^^^^^^^^^^^^^^^^^^^^^^^^
  File "C:\Users\zamor\UltiBotInversiones\src\ultibot_backend\dependencies.py", line 211, in get_performance_service
    container = get_container(request)
                ^^^^^^^^^^^^^^^^^^^^^^
  File "C:\Users\zamor\UltiBotInversiones\src\ultibot_backend\dependencies.py", line 141, in get_container
    return request.app.state.container
           ^^^^^^^^^^^^^^^^^^^^^^^^^^^
  File "C:\Users\zamor\UltiBotInversiones\.venv\Lib\site-packages\starlette\datastructures.py", line 702, in __getattr__
    raise AttributeError(message.format(self.__class__.__name__, key))
AttributeError: 'State' object has no attribute 'container'
2025-06-17 16:51:35,130 - ultibot_backend - INFO - [MainThread] - main.py:65 - Logging configurado exitosamente usando dictConfig.
2025-06-17 16:51:35,130 - ultibot_backend - INFO - [MainThread] - main.py:136 - Registrando routers de la API...
2025-06-17 16:51:35,145 - ultibot_backend - INFO - [MainThread] - main.py:148 - Todos los routers han sido registrados.
2025-06-17 16:51:35,327 - qasync - INFO - [MainThread] - __init__.py:57 - Forcing use of PySide6 as Qt Implementation
2025-06-17 16:51:35,490 - matplotlib - DEBUG - [MainThread] - __init__.py:342 - matplotlib data path: C:\Users\zamor\UltiBotInversiones\.venv\Lib\site-packages\matplotlib\mpl-data
2025-06-17 16:51:35,496 - matplotlib - DEBUG - [MainThread] - __init__.py:342 - CONFIGDIR=C:\Users\zamor\.matplotlib
2025-06-17 16:51:35,496 - matplotlib - DEBUG - [MainThread] - __init__.py:1557 - interactive is False
2025-06-17 16:51:35,496 - matplotlib - DEBUG - [MainThread] - __init__.py:1558 - platform is win32
2025-06-17 16:51:35,617 - matplotlib - DEBUG - [MainThread] - __init__.py:342 - CACHEDIR=C:\Users\zamor\.matplotlib
2025-06-17 16:51:35,622 - matplotlib.font_manager - DEBUG - [MainThread] - font_manager.py:1635 - Using fontManager instance from C:\Users\zamor\.matplotlib\fontlist-v390.json
2025-06-17 16:51:36,263 - ultibot_backend - INFO - [MainThread] - main.py:105 - Middleware: Solicitud entrante: GET /api/v1/performance/strategies
2025-06-17 16:51:36,265 - ultibot_backend.services.performance_service - INFO - [MainThread] - performance_service.py:109 - Fetching performance data for user 00000000-0000-0000-0000-000000000001, mode_filter: None
2025-06-17 16:51:36,265 - ultibot_backend.services.performance_service - INFO - [MainThread] - performance_service.py:120 - No closed trades found for user 00000000-0000-0000-0000-000000000001 with mode_filter: None
2025-06-17 16:51:36,265 - ultibot_backend - INFO - [MainThread] - main.py:107 - Middleware: Solicitud procesada: GET /api/v1/performance/strategies - Status: 200
2025-06-17 16:52:27,337 - ultibot_backend - INFO - [MainThread] - main.py:65 - Logging configurado exitosamente usando dictConfig.
2025-06-17 16:52:27,337 - ultibot_backend - INFO - [MainThread] - main.py:136 - Registrando routers de la API...
2025-06-17 16:52:27,357 - ultibot_backend - INFO - [MainThread] - main.py:148 - Todos los routers han sido registrados.
2025-06-17 16:52:27,527 - qasync - INFO - [MainThread] - __init__.py:57 - Forcing use of PySide6 as Qt Implementation
2025-06-17 16:52:27,658 - matplotlib - DEBUG - [MainThread] - __init__.py:342 - matplotlib data path: C:\Users\zamor\UltiBotInversiones\.venv\Lib\site-packages\matplotlib\mpl-data
2025-06-17 16:52:27,667 - matplotlib - DEBUG - [MainThread] - __init__.py:342 - CONFIGDIR=C:\Users\zamor\.matplotlib
2025-06-17 16:52:27,667 - matplotlib - DEBUG - [MainThread] - __init__.py:1557 - interactive is False
2025-06-17 16:52:27,667 - matplotlib - DEBUG - [MainThread] - __init__.py:1558 - platform is win32
2025-06-17 16:52:27,773 - matplotlib - DEBUG - [MainThread] - __init__.py:342 - CACHEDIR=C:\Users\zamor\.matplotlib
2025-06-17 16:52:27,782 - matplotlib.font_manager - DEBUG - [MainThread] - font_manager.py:1635 - Using fontManager instance from C:\Users\zamor\.matplotlib\fontlist-v390.json
2025-06-17 16:52:28,392 - ultibot_backend - INFO - [MainThread] - main.py:105 - Middleware: Solicitud entrante: GET /api/v1/performance/strategies
2025-06-17 16:52:28,392 - ultibot_backend.services.performance_service - INFO - [MainThread] - performance_service.py:109 - Fetching performance data for user 00000000-0000-0000-0000-000000000001, mode_filter: None
2025-06-17 16:52:28,392 - ultibot_backend.services.performance_service - INFO - [MainThread] - performance_service.py:120 - No closed trades found for user 00000000-0000-0000-0000-000000000001 with mode_filter: None
2025-06-17 16:52:28,392 - ultibot_backend - INFO - [MainThread] - main.py:107 - Middleware: Solicitud procesada: GET /api/v1/performance/strategies - Status: 200
2025-06-17 17:00:35,953 - ultibot_backend - INFO - [MainThread] - main.py:65 - Logging configurado exitosamente usando dictConfig.
2025-06-17 17:00:35,953 - ultibot_backend - INFO - [MainThread] - main.py:136 - Registrando routers de la API...
2025-06-17 17:00:35,973 - ultibot_backend - INFO - [MainThread] - main.py:148 - Todos los routers han sido registrados.
2025-06-17 17:00:36,151 - qasync - INFO - [MainThread] - __init__.py:57 - Forcing use of PySide6 as Qt Implementation
2025-06-17 17:00:36,301 - matplotlib - DEBUG - [MainThread] - __init__.py:342 - matplotlib data path: C:\Users\zamor\UltiBotInversiones\.venv\Lib\site-packages\matplotlib\mpl-data
2025-06-17 17:00:36,313 - matplotlib - DEBUG - [MainThread] - __init__.py:342 - CONFIGDIR=C:\Users\zamor\.matplotlib
2025-06-17 17:00:36,313 - matplotlib - DEBUG - [MainThread] - __init__.py:1557 - interactive is False
2025-06-17 17:00:36,313 - matplotlib - DEBUG - [MainThread] - __init__.py:1558 - platform is win32
2025-06-17 17:00:36,423 - matplotlib - DEBUG - [MainThread] - __init__.py:342 - CACHEDIR=C:\Users\zamor\.matplotlib
2025-06-17 17:00:36,433 - matplotlib.font_manager - DEBUG - [MainThread] - font_manager.py:1635 - Using fontManager instance from C:\Users\zamor\.matplotlib\fontlist-v390.json
2025-06-17 17:00:37,060 - ultibot_backend - INFO - [MainThread] - main.py:105 - Middleware: Solicitud entrante: GET /api/v1/performance/strategies
2025-06-17 17:00:37,062 - ultibot_backend.services.performance_service - INFO - [MainThread] - performance_service.py:109 - Fetching performance data for user 00000000-0000-0000-0000-000000000001, mode_filter: None
2025-06-17 17:00:37,063 - ultibot_backend.services.performance_service - INFO - [MainThread] - performance_service.py:120 - No closed trades found for user 00000000-0000-0000-0000-000000000001 with mode_filter: None
2025-06-17 17:00:37,063 - ultibot_backend - INFO - [MainThread] - main.py:107 - Middleware: Solicitud procesada: GET /api/v1/performance/strategies - Status: 200
2025-06-17 17:00:37,367 - ultibot_backend - INFO - [MainThread] - main.py:105 - Middleware: Solicitud entrante: GET /api/v1/performance/strategies
2025-06-17 17:00:37,369 - ultibot_backend - INFO - [MainThread] - main.py:107 - Middleware: Solicitud procesada: GET /api/v1/performance/strategies - Status: 422
2025-06-17 17:00:38,973 - ultibot_backend.services.trading_report_service - ERROR - [MainThread] - trading_report_service.py:71 - Error al obtener trades cerrados para usuario 123e4567-e89b-12d3-a456-426614174000: 9 validation errors for Trade
id
  Input should be a valid UUID, invalid character: expected an optional prefix of `urn:uuid:` followed by [0-9a-fA-F-], found `t` at 1 [type=uuid_parsing, input_value='trade-win-1', input_type=str]
    For further information visit https://errors.pydantic.dev/2.11/v/uuid_parsing
user_id
  Input should be a valid UUID, invalid character: expected an optional prefix of `urn:uuid:` followed by [0-9a-fA-F-], found `u` at 1 [type=uuid_parsing, input_value='user-123', input_type=str]
    For further information visit https://errors.pydantic.dev/2.11/v/uuid_parsing
mode
  Field required [type=missing, input_value={'id': 'trade-win-1', 'us...xecutedPrice': 50000.0}}, input_type=dict]
    For further information visit https://errors.pydantic.dev/2.11/v/missing
side
  Field required [type=missing, input_value={'id': 'trade-win-1', 'us...xecutedPrice': 50000.0}}, input_type=dict]
    For further information visit https://errors.pydantic.dev/2.11/v/missing
entryOrder.orderCategory
  Field required [type=missing, input_value={'executedQuantity': 0.00...executedPrice': 50000.0}, input_type=dict]
    For further information visit https://errors.pydantic.dev/2.11/v/missing
entryOrder.type
  Field required [type=missing, input_value={'executedQuantity': 0.00...executedPrice': 50000.0}, input_type=dict]
    For further information visit https://errors.pydantic.dev/2.11/v/missing
entryOrder.status
  Field required [type=missing, input_value={'executedQuantity': 0.00...executedPrice': 50000.0}, input_type=dict]
    For further information visit https://errors.pydantic.dev/2.11/v/missing
entryOrder.requestedQuantity
  Field required [type=missing, input_value={'executedQuantity': 0.00...executedPrice': 50000.0}, input_type=dict]
    For further information visit https://errors.pydantic.dev/2.11/v/missing
positionStatus
  Field required [type=missing, input_value={'id': 'trade-win-1', 'us...xecutedPrice': 50000.0}}, input_type=dict]
    For further information visit https://errors.pydantic.dev/2.11/v/missing
Traceback (most recent call last):
  File "C:\Users\zamor\UltiBotInversiones\src\ultibot_backend\services\trading_report_service.py", line 65, in get_closed_trades
    trades = [Trade(**record) for record in trade_records]
             ^^^^^^^^^^^^^^^^^^^^^^^^^^^^^^^^^^^^^^^^^^^^^
  File "C:\Users\zamor\UltiBotInversiones\src\ultibot_backend\services\trading_report_service.py", line 65, in <listcomp>
    trades = [Trade(**record) for record in trade_records]
              ^^^^^^^^^^^^^^^
  File "C:\Users\zamor\UltiBotInversiones\.venv\Lib\site-packages\pydantic\main.py", line 253, in __init__
    validated_self = self.__pydantic_validator__.validate_python(data, self_instance=self)
                     ^^^^^^^^^^^^^^^^^^^^^^^^^^^^^^^^^^^^^^^^^^^^^^^^^^^^^^^^^^^^^^^^^^^^^
pydantic_core._pydantic_core.ValidationError: 9 validation errors for Trade
id
  Input should be a valid UUID, invalid character: expected an optional prefix of `urn:uuid:` followed by [0-9a-fA-F-], found `t` at 1 [type=uuid_parsing, input_value='trade-win-1', input_type=str]
    For further information visit https://errors.pydantic.dev/2.11/v/uuid_parsing
user_id
  Input should be a valid UUID, invalid character: expected an optional prefix of `urn:uuid:` followed by [0-9a-fA-F-], found `u` at 1 [type=uuid_parsing, input_value='user-123', input_type=str]
    For further information visit https://errors.pydantic.dev/2.11/v/uuid_parsing
mode
  Field required [type=missing, input_value={'id': 'trade-win-1', 'us...xecutedPrice': 50000.0}}, input_type=dict]
    For further information visit https://errors.pydantic.dev/2.11/v/missing
side
  Field required [type=missing, input_value={'id': 'trade-win-1', 'us...xecutedPrice': 50000.0}}, input_type=dict]
    For further information visit https://errors.pydantic.dev/2.11/v/missing
entryOrder.orderCategory
  Field required [type=missing, input_value={'executedQuantity': 0.00...executedPrice': 50000.0}, input_type=dict]
    For further information visit https://errors.pydantic.dev/2.11/v/missing
entryOrder.type
  Field required [type=missing, input_value={'executedQuantity': 0.00...executedPrice': 50000.0}, input_type=dict]
    For further information visit https://errors.pydantic.dev/2.11/v/missing
entryOrder.status
  Field required [type=missing, input_value={'executedQuantity': 0.00...executedPrice': 50000.0}, input_type=dict]
    For further information visit https://errors.pydantic.dev/2.11/v/missing
entryOrder.requestedQuantity
  Field required [type=missing, input_value={'executedQuantity': 0.00...executedPrice': 50000.0}, input_type=dict]
    For further information visit https://errors.pydantic.dev/2.11/v/missing
positionStatus
  Field required [type=missing, input_value={'id': 'trade-win-1', 'us...xecutedPrice': 50000.0}}, input_type=dict]
    For further information visit https://errors.pydantic.dev/2.11/v/missing
2025-06-17 17:00:38,975 - ultibot_backend.services.trading_report_service - ERROR - [MainThread] - trading_report_service.py:182 - Error al calcular métricas de rendimiento para usuario 123e4567-e89b-12d3-a456-426614174000: Error al obtener historial de trades: 9 validation errors for Trade
id
  Input should be a valid UUID, invalid character: expected an optional prefix of `urn:uuid:` followed by [0-9a-fA-F-], found `t` at 1 [type=uuid_parsing, input_value='trade-win-1', input_type=str]
    For further information visit https://errors.pydantic.dev/2.11/v/uuid_parsing
user_id
  Input should be a valid UUID, invalid character: expected an optional prefix of `urn:uuid:` followed by [0-9a-fA-F-], found `u` at 1 [type=uuid_parsing, input_value='user-123', input_type=str]
    For further information visit https://errors.pydantic.dev/2.11/v/uuid_parsing
mode
  Field required [type=missing, input_value={'id': 'trade-win-1', 'us...xecutedPrice': 50000.0}}, input_type=dict]
    For further information visit https://errors.pydantic.dev/2.11/v/missing
side
  Field required [type=missing, input_value={'id': 'trade-win-1', 'us...xecutedPrice': 50000.0}}, input_type=dict]
    For further information visit https://errors.pydantic.dev/2.11/v/missing
entryOrder.orderCategory
  Field required [type=missing, input_value={'executedQuantity': 0.00...executedPrice': 50000.0}, input_type=dict]
    For further information visit https://errors.pydantic.dev/2.11/v/missing
entryOrder.type
  Field required [type=missing, input_value={'executedQuantity': 0.00...executedPrice': 50000.0}, input_type=dict]
    For further information visit https://errors.pydantic.dev/2.11/v/missing
entryOrder.status
  Field required [type=missing, input_value={'executedQuantity': 0.00...executedPrice': 50000.0}, input_type=dict]
    For further information visit https://errors.pydantic.dev/2.11/v/missing
entryOrder.requestedQuantity
  Field required [type=missing, input_value={'executedQuantity': 0.00...executedPrice': 50000.0}, input_type=dict]
    For further information visit https://errors.pydantic.dev/2.11/v/missing
positionStatus
  Field required [type=missing, input_value={'id': 'trade-win-1', 'us...xecutedPrice': 50000.0}}, input_type=dict]
    For further information visit https://errors.pydantic.dev/2.11/v/missing
Traceback (most recent call last):
  File "C:\Users\zamor\UltiBotInversiones\src\ultibot_backend\services\trading_report_service.py", line 65, in get_closed_trades
    trades = [Trade(**record) for record in trade_records]
             ^^^^^^^^^^^^^^^^^^^^^^^^^^^^^^^^^^^^^^^^^^^^^
  File "C:\Users\zamor\UltiBotInversiones\src\ultibot_backend\services\trading_report_service.py", line 65, in <listcomp>
    trades = [Trade(**record) for record in trade_records]
              ^^^^^^^^^^^^^^^
  File "C:\Users\zamor\UltiBotInversiones\.venv\Lib\site-packages\pydantic\main.py", line 253, in __init__
    validated_self = self.__pydantic_validator__.validate_python(data, self_instance=self)
                     ^^^^^^^^^^^^^^^^^^^^^^^^^^^^^^^^^^^^^^^^^^^^^^^^^^^^^^^^^^^^^^^^^^^^^
pydantic_core._pydantic_core.ValidationError: 9 validation errors for Trade
id
  Input should be a valid UUID, invalid character: expected an optional prefix of `urn:uuid:` followed by [0-9a-fA-F-], found `t` at 1 [type=uuid_parsing, input_value='trade-win-1', input_type=str]
    For further information visit https://errors.pydantic.dev/2.11/v/uuid_parsing
user_id
  Input should be a valid UUID, invalid character: expected an optional prefix of `urn:uuid:` followed by [0-9a-fA-F-], found `u` at 1 [type=uuid_parsing, input_value='user-123', input_type=str]
    For further information visit https://errors.pydantic.dev/2.11/v/uuid_parsing
mode
  Field required [type=missing, input_value={'id': 'trade-win-1', 'us...xecutedPrice': 50000.0}}, input_type=dict]
    For further information visit https://errors.pydantic.dev/2.11/v/missing
side
  Field required [type=missing, input_value={'id': 'trade-win-1', 'us...xecutedPrice': 50000.0}}, input_type=dict]
    For further information visit https://errors.pydantic.dev/2.11/v/missing
entryOrder.orderCategory
  Field required [type=missing, input_value={'executedQuantity': 0.00...executedPrice': 50000.0}, input_type=dict]
    For further information visit https://errors.pydantic.dev/2.11/v/missing
entryOrder.type
  Field required [type=missing, input_value={'executedQuantity': 0.00...executedPrice': 50000.0}, input_type=dict]
    For further information visit https://errors.pydantic.dev/2.11/v/missing
entryOrder.status
  Field required [type=missing, input_value={'executedQuantity': 0.00...executedPrice': 50000.0}, input_type=dict]
    For further information visit https://errors.pydantic.dev/2.11/v/missing
entryOrder.requestedQuantity
  Field required [type=missing, input_value={'executedQuantity': 0.00...executedPrice': 50000.0}, input_type=dict]
    For further information visit https://errors.pydantic.dev/2.11/v/missing
positionStatus
  Field required [type=missing, input_value={'id': 'trade-win-1', 'us...xecutedPrice': 50000.0}}, input_type=dict]
    For further information visit https://errors.pydantic.dev/2.11/v/missing

During handling of the above exception, another exception occurred:

Traceback (most recent call last):
  File "C:\Users\zamor\UltiBotInversiones\src\ultibot_backend\services\trading_report_service.py", line 97, in calculate_performance_metrics
    trades = await self.get_closed_trades(
             ^^^^^^^^^^^^^^^^^^^^^^^^^^^^^
  File "C:\Users\zamor\UltiBotInversiones\src\ultibot_backend\services\trading_report_service.py", line 72, in get_closed_trades
    raise ReportError(f"Error al obtener historial de trades: {str(e)}")
ultibot_backend.core.exceptions.ReportError: Error al obtener historial de trades: 9 validation errors for Trade
id
  Input should be a valid UUID, invalid character: expected an optional prefix of `urn:uuid:` followed by [0-9a-fA-F-], found `t` at 1 [type=uuid_parsing, input_value='trade-win-1', input_type=str]
    For further information visit https://errors.pydantic.dev/2.11/v/uuid_parsing
user_id
  Input should be a valid UUID, invalid character: expected an optional prefix of `urn:uuid:` followed by [0-9a-fA-F-], found `u` at 1 [type=uuid_parsing, input_value='user-123', input_type=str]
    For further information visit https://errors.pydantic.dev/2.11/v/uuid_parsing
mode
  Field required [type=missing, input_value={'id': 'trade-win-1', 'us...xecutedPrice': 50000.0}}, input_type=dict]
    For further information visit https://errors.pydantic.dev/2.11/v/missing
side
  Field required [type=missing, input_value={'id': 'trade-win-1', 'us...xecutedPrice': 50000.0}}, input_type=dict]
    For further information visit https://errors.pydantic.dev/2.11/v/missing
entryOrder.orderCategory
  Field required [type=missing, input_value={'executedQuantity': 0.00...executedPrice': 50000.0}, input_type=dict]
    For further information visit https://errors.pydantic.dev/2.11/v/missing
entryOrder.type
  Field required [type=missing, input_value={'executedQuantity': 0.00...executedPrice': 50000.0}, input_type=dict]
    For further information visit https://errors.pydantic.dev/2.11/v/missing
entryOrder.status
  Field required [type=missing, input_value={'executedQuantity': 0.00...executedPrice': 50000.0}, input_type=dict]
    For further information visit https://errors.pydantic.dev/2.11/v/missing
entryOrder.requestedQuantity
  Field required [type=missing, input_value={'executedQuantity': 0.00...executedPrice': 50000.0}, input_type=dict]
    For further information visit https://errors.pydantic.dev/2.11/v/missing
positionStatus
  Field required [type=missing, input_value={'id': 'trade-win-1', 'us...xecutedPrice': 50000.0}}, input_type=dict]
    For further information visit https://errors.pydantic.dev/2.11/v/missing
2025-06-17 17:00:39,064 - ultibot_backend.services.trading_report_service - ERROR - [MainThread] - trading_report_service.py:71 - Error al obtener trades cerrados para usuario 123e4567-e89b-12d3-a456-426614174000: 9 validation errors for Trade
id
  Input should be a valid UUID, invalid character: expected an optional prefix of `urn:uuid:` followed by [0-9a-fA-F-], found `t` at 1 [type=uuid_parsing, input_value='trade-1', input_type=str]
    For further information visit https://errors.pydantic.dev/2.11/v/uuid_parsing
user_id
  Input should be a valid UUID, invalid character: expected an optional prefix of `urn:uuid:` followed by [0-9a-fA-F-], found `u` at 1 [type=uuid_parsing, input_value='user-123', input_type=str]
    For further information visit https://errors.pydantic.dev/2.11/v/uuid_parsing
mode
  Field required [type=missing, input_value={'id': 'trade-1', 'user_i...xecutedPrice': 50000.0}}, input_type=dict]
    For further information visit https://errors.pydantic.dev/2.11/v/missing
side
  Field required [type=missing, input_value={'id': 'trade-1', 'user_i...xecutedPrice': 50000.0}}, input_type=dict]
    For further information visit https://errors.pydantic.dev/2.11/v/missing
entryOrder.orderCategory
  Field required [type=missing, input_value={'executedQuantity': 0.00...executedPrice': 50000.0}, input_type=dict]
    For further information visit https://errors.pydantic.dev/2.11/v/missing
entryOrder.type
  Field required [type=missing, input_value={'executedQuantity': 0.00...executedPrice': 50000.0}, input_type=dict]
    For further information visit https://errors.pydantic.dev/2.11/v/missing
entryOrder.status
  Field required [type=missing, input_value={'executedQuantity': 0.00...executedPrice': 50000.0}, input_type=dict]
    For further information visit https://errors.pydantic.dev/2.11/v/missing
entryOrder.requestedQuantity
  Field required [type=missing, input_value={'executedQuantity': 0.00...executedPrice': 50000.0}, input_type=dict]
    For further information visit https://errors.pydantic.dev/2.11/v/missing
positionStatus
  Field required [type=missing, input_value={'id': 'trade-1', 'user_i...xecutedPrice': 50000.0}}, input_type=dict]
    For further information visit https://errors.pydantic.dev/2.11/v/missing
Traceback (most recent call last):
  File "C:\Users\zamor\UltiBotInversiones\src\ultibot_backend\services\trading_report_service.py", line 65, in get_closed_trades
    trades = [Trade(**record) for record in trade_records]
             ^^^^^^^^^^^^^^^^^^^^^^^^^^^^^^^^^^^^^^^^^^^^^
  File "C:\Users\zamor\UltiBotInversiones\src\ultibot_backend\services\trading_report_service.py", line 65, in <listcomp>
    trades = [Trade(**record) for record in trade_records]
              ^^^^^^^^^^^^^^^
  File "C:\Users\zamor\UltiBotInversiones\.venv\Lib\site-packages\pydantic\main.py", line 253, in __init__
    validated_self = self.__pydantic_validator__.validate_python(data, self_instance=self)
                     ^^^^^^^^^^^^^^^^^^^^^^^^^^^^^^^^^^^^^^^^^^^^^^^^^^^^^^^^^^^^^^^^^^^^^
pydantic_core._pydantic_core.ValidationError: 9 validation errors for Trade
id
  Input should be a valid UUID, invalid character: expected an optional prefix of `urn:uuid:` followed by [0-9a-fA-F-], found `t` at 1 [type=uuid_parsing, input_value='trade-1', input_type=str]
    For further information visit https://errors.pydantic.dev/2.11/v/uuid_parsing
user_id
  Input should be a valid UUID, invalid character: expected an optional prefix of `urn:uuid:` followed by [0-9a-fA-F-], found `u` at 1 [type=uuid_parsing, input_value='user-123', input_type=str]
    For further information visit https://errors.pydantic.dev/2.11/v/uuid_parsing
mode
  Field required [type=missing, input_value={'id': 'trade-1', 'user_i...xecutedPrice': 50000.0}}, input_type=dict]
    For further information visit https://errors.pydantic.dev/2.11/v/missing
side
  Field required [type=missing, input_value={'id': 'trade-1', 'user_i...xecutedPrice': 50000.0}}, input_type=dict]
    For further information visit https://errors.pydantic.dev/2.11/v/missing
entryOrder.orderCategory
  Field required [type=missing, input_value={'executedQuantity': 0.00...executedPrice': 50000.0}, input_type=dict]
    For further information visit https://errors.pydantic.dev/2.11/v/missing
entryOrder.type
  Field required [type=missing, input_value={'executedQuantity': 0.00...executedPrice': 50000.0}, input_type=dict]
    For further information visit https://errors.pydantic.dev/2.11/v/missing
entryOrder.status
  Field required [type=missing, input_value={'executedQuantity': 0.00...executedPrice': 50000.0}, input_type=dict]
    For further information visit https://errors.pydantic.dev/2.11/v/missing
entryOrder.requestedQuantity
  Field required [type=missing, input_value={'executedQuantity': 0.00...executedPrice': 50000.0}, input_type=dict]
    For further information visit https://errors.pydantic.dev/2.11/v/missing
positionStatus
  Field required [type=missing, input_value={'id': 'trade-1', 'user_i...xecutedPrice': 50000.0}}, input_type=dict]
    For further information visit https://errors.pydantic.dev/2.11/v/missing
2025-06-17 17:00:39,064 - ultibot_backend.services.trading_report_service - ERROR - [MainThread] - trading_report_service.py:182 - Error al calcular métricas de rendimiento para usuario 123e4567-e89b-12d3-a456-426614174000: Error al obtener historial de trades: 9 validation errors for Trade
id
  Input should be a valid UUID, invalid character: expected an optional prefix of `urn:uuid:` followed by [0-9a-fA-F-], found `t` at 1 [type=uuid_parsing, input_value='trade-1', input_type=str]
    For further information visit https://errors.pydantic.dev/2.11/v/uuid_parsing
user_id
  Input should be a valid UUID, invalid character: expected an optional prefix of `urn:uuid:` followed by [0-9a-fA-F-], found `u` at 1 [type=uuid_parsing, input_value='user-123', input_type=str]
    For further information visit https://errors.pydantic.dev/2.11/v/uuid_parsing
mode
  Field required [type=missing, input_value={'id': 'trade-1', 'user_i...xecutedPrice': 50000.0}}, input_type=dict]
    For further information visit https://errors.pydantic.dev/2.11/v/missing
side
  Field required [type=missing, input_value={'id': 'trade-1', 'user_i...xecutedPrice': 50000.0}}, input_type=dict]
    For further information visit https://errors.pydantic.dev/2.11/v/missing
entryOrder.orderCategory
  Field required [type=missing, input_value={'executedQuantity': 0.00...executedPrice': 50000.0}, input_type=dict]
    For further information visit https://errors.pydantic.dev/2.11/v/missing
entryOrder.type
  Field required [type=missing, input_value={'executedQuantity': 0.00...executedPrice': 50000.0}, input_type=dict]
    For further information visit https://errors.pydantic.dev/2.11/v/missing
entryOrder.status
  Field required [type=missing, input_value={'executedQuantity': 0.00...executedPrice': 50000.0}, input_type=dict]
    For further information visit https://errors.pydantic.dev/2.11/v/missing
entryOrder.requestedQuantity
  Field required [type=missing, input_value={'executedQuantity': 0.00...executedPrice': 50000.0}, input_type=dict]
    For further information visit https://errors.pydantic.dev/2.11/v/missing
positionStatus
  Field required [type=missing, input_value={'id': 'trade-1', 'user_i...xecutedPrice': 50000.0}}, input_type=dict]
    For further information visit https://errors.pydantic.dev/2.11/v/missing
Traceback (most recent call last):
  File "C:\Users\zamor\UltiBotInversiones\src\ultibot_backend\services\trading_report_service.py", line 65, in get_closed_trades
    trades = [Trade(**record) for record in trade_records]
             ^^^^^^^^^^^^^^^^^^^^^^^^^^^^^^^^^^^^^^^^^^^^^
  File "C:\Users\zamor\UltiBotInversiones\src\ultibot_backend\services\trading_report_service.py", line 65, in <listcomp>
    trades = [Trade(**record) for record in trade_records]
              ^^^^^^^^^^^^^^^
  File "C:\Users\zamor\UltiBotInversiones\.venv\Lib\site-packages\pydantic\main.py", line 253, in __init__
    validated_self = self.__pydantic_validator__.validate_python(data, self_instance=self)
                     ^^^^^^^^^^^^^^^^^^^^^^^^^^^^^^^^^^^^^^^^^^^^^^^^^^^^^^^^^^^^^^^^^^^^^
pydantic_core._pydantic_core.ValidationError: 9 validation errors for Trade
id
  Input should be a valid UUID, invalid character: expected an optional prefix of `urn:uuid:` followed by [0-9a-fA-F-], found `t` at 1 [type=uuid_parsing, input_value='trade-1', input_type=str]
    For further information visit https://errors.pydantic.dev/2.11/v/uuid_parsing
user_id
  Input should be a valid UUID, invalid character: expected an optional prefix of `urn:uuid:` followed by [0-9a-fA-F-], found `u` at 1 [type=uuid_parsing, input_value='user-123', input_type=str]
    For further information visit https://errors.pydantic.dev/2.11/v/uuid_parsing
mode
  Field required [type=missing, input_value={'id': 'trade-1', 'user_i...xecutedPrice': 50000.0}}, input_type=dict]
    For further information visit https://errors.pydantic.dev/2.11/v/missing
side
  Field required [type=missing, input_value={'id': 'trade-1', 'user_i...xecutedPrice': 50000.0}}, input_type=dict]
    For further information visit https://errors.pydantic.dev/2.11/v/missing
entryOrder.orderCategory
  Field required [type=missing, input_value={'executedQuantity': 0.00...executedPrice': 50000.0}, input_type=dict]
    For further information visit https://errors.pydantic.dev/2.11/v/missing
entryOrder.type
  Field required [type=missing, input_value={'executedQuantity': 0.00...executedPrice': 50000.0}, input_type=dict]
    For further information visit https://errors.pydantic.dev/2.11/v/missing
entryOrder.status
  Field required [type=missing, input_value={'executedQuantity': 0.00...executedPrice': 50000.0}, input_type=dict]
    For further information visit https://errors.pydantic.dev/2.11/v/missing
entryOrder.requestedQuantity
  Field required [type=missing, input_value={'executedQuantity': 0.00...executedPrice': 50000.0}, input_type=dict]
    For further information visit https://errors.pydantic.dev/2.11/v/missing
positionStatus
  Field required [type=missing, input_value={'id': 'trade-1', 'user_i...xecutedPrice': 50000.0}}, input_type=dict]
    For further information visit https://errors.pydantic.dev/2.11/v/missing

During handling of the above exception, another exception occurred:

Traceback (most recent call last):
  File "C:\Users\zamor\UltiBotInversiones\src\ultibot_backend\services\trading_report_service.py", line 97, in calculate_performance_metrics
    trades = await self.get_closed_trades(
             ^^^^^^^^^^^^^^^^^^^^^^^^^^^^^
  File "C:\Users\zamor\UltiBotInversiones\src\ultibot_backend\services\trading_report_service.py", line 72, in get_closed_trades
    raise ReportError(f"Error al obtener historial de trades: {str(e)}")
ultibot_backend.core.exceptions.ReportError: Error al obtener historial de trades: 9 validation errors for Trade
id
  Input should be a valid UUID, invalid character: expected an optional prefix of `urn:uuid:` followed by [0-9a-fA-F-], found `t` at 1 [type=uuid_parsing, input_value='trade-1', input_type=str]
    For further information visit https://errors.pydantic.dev/2.11/v/uuid_parsing
user_id
  Input should be a valid UUID, invalid character: expected an optional prefix of `urn:uuid:` followed by [0-9a-fA-F-], found `u` at 1 [type=uuid_parsing, input_value='user-123', input_type=str]
    For further information visit https://errors.pydantic.dev/2.11/v/uuid_parsing
mode
  Field required [type=missing, input_value={'id': 'trade-1', 'user_i...xecutedPrice': 50000.0}}, input_type=dict]
    For further information visit https://errors.pydantic.dev/2.11/v/missing
side
  Field required [type=missing, input_value={'id': 'trade-1', 'user_i...xecutedPrice': 50000.0}}, input_type=dict]
    For further information visit https://errors.pydantic.dev/2.11/v/missing
entryOrder.orderCategory
  Field required [type=missing, input_value={'executedQuantity': 0.00...executedPrice': 50000.0}, input_type=dict]
    For further information visit https://errors.pydantic.dev/2.11/v/missing
entryOrder.type
  Field required [type=missing, input_value={'executedQuantity': 0.00...executedPrice': 50000.0}, input_type=dict]
    For further information visit https://errors.pydantic.dev/2.11/v/missing
entryOrder.status
  Field required [type=missing, input_value={'executedQuantity': 0.00...executedPrice': 50000.0}, input_type=dict]
    For further information visit https://errors.pydantic.dev/2.11/v/missing
entryOrder.requestedQuantity
  Field required [type=missing, input_value={'executedQuantity': 0.00...executedPrice': 50000.0}, input_type=dict]
    For further information visit https://errors.pydantic.dev/2.11/v/missing
positionStatus
  Field required [type=missing, input_value={'id': 'trade-1', 'user_i...xecutedPrice': 50000.0}}, input_type=dict]
    For further information visit https://errors.pydantic.dev/2.11/v/missing
2025-06-17 17:10:47,663 - ultibot_backend - INFO - [MainThread] - main.py:65 - Logging configurado exitosamente usando dictConfig.
2025-06-17 17:10:47,667 - ultibot_backend - INFO - [MainThread] - main.py:136 - Registrando routers de la API...
2025-06-17 17:10:47,684 - ultibot_backend - INFO - [MainThread] - main.py:148 - Todos los routers han sido registrados.
2025-06-17 17:11:09,153 - ultibot_backend - INFO - [MainThread] - main.py:65 - Logging configurado exitosamente usando dictConfig.
2025-06-17 17:11:09,153 - ultibot_backend - INFO - [MainThread] - main.py:136 - Registrando routers de la API...
2025-06-17 17:11:09,178 - ultibot_backend - INFO - [MainThread] - main.py:148 - Todos los routers han sido registrados.
2025-06-17 17:11:09,255 - asyncio - DEBUG - [MainThread] - selector_events.py:54 - Using selector: SelectSelector
2025-06-17 17:11:09,255 - asyncio - DEBUG - [MainThread] - selector_events.py:54 - Using selector: SelectSelector
2025-06-17 17:15:34,993 - ultibot_backend - INFO - [MainThread] - main.py:65 - Logging configurado exitosamente usando dictConfig.
2025-06-17 17:15:34,993 - ultibot_backend - INFO - [MainThread] - main.py:136 - Registrando routers de la API...
2025-06-17 17:15:35,018 - ultibot_backend - INFO - [MainThread] - main.py:148 - Todos los routers han sido registrados.
2025-06-17 17:15:35,083 - asyncio - DEBUG - [MainThread] - selector_events.py:54 - Using selector: SelectSelector
2025-06-17 17:15:35,089 - asyncio - DEBUG - [MainThread] - selector_events.py:54 - Using selector: SelectSelector
2025-06-17 17:15:35,095 - ultibot_backend - INFO - [MainThread] - main.py:105 - Middleware: Solicitud entrante: GET /api/v1/performance/strategies
2025-06-17 17:15:35,097 - ultibot_backend.services.performance_service - INFO - [MainThread] - performance_service.py:109 - Fetching performance data for user 00000000-0000-0000-0000-000000000001, mode_filter: OperatingMode.PAPER
2025-06-17 17:15:35,097 - ultibot_backend.services.performance_service - INFO - [MainThread] - performance_service.py:160 - Generated 1 performance entries for user 00000000-0000-0000-0000-000000000001
2025-06-17 17:15:35,099 - ultibot_backend - INFO - [MainThread] - main.py:107 - Middleware: Solicitud procesada: GET /api/v1/performance/strategies - Status: 200
2025-06-17 17:15:35,099 - httpx - INFO - [MainThread] - _client.py:1786 - HTTP Request: GET http://test/api/v1/performance/strategies?mode=paper "HTTP/1.1 200 OK"
2025-06-17 17:21:22,866 - ultibot_backend - INFO - [MainThread] - main.py:65 - Logging configurado exitosamente usando dictConfig.
2025-06-17 17:21:22,866 - ultibot_backend - INFO - [MainThread] - main.py:136 - Registrando routers de la API...
2025-06-17 17:21:22,888 - ultibot_backend - INFO - [MainThread] - main.py:148 - Todos los routers han sido registrados.
2025-06-17 17:21:22,934 - asyncio - DEBUG - [MainThread] - selector_events.py:54 - Using selector: SelectSelector
2025-06-17 17:21:22,936 - asyncio - DEBUG - [MainThread] - selector_events.py:54 - Using selector: SelectSelector
2025-06-17 17:21:22,944 - ultibot_backend - INFO - [MainThread] - main.py:105 - Middleware: Solicitud entrante: GET /api/v1/performance/strategies
2025-06-17 17:21:22,945 - ultibot_backend.services.performance_service - INFO - [MainThread] - performance_service.py:109 - Fetching performance data for user 00000000-0000-0000-0000-000000000001, mode_filter: OperatingMode.PAPER
2025-06-17 17:21:22,946 - ultibot_backend.services.performance_service - INFO - [MainThread] - performance_service.py:160 - Generated 1 performance entries for user 00000000-0000-0000-0000-000000000001
2025-06-17 17:21:22,946 - ultibot_backend - INFO - [MainThread] - main.py:107 - Middleware: Solicitud procesada: GET /api/v1/performance/strategies - Status: 200
2025-06-17 17:21:22,946 - httpx - INFO - [MainThread] - _client.py:1786 - HTTP Request: GET http://test/api/v1/performance/strategies?mode=paper "HTTP/1.1 200 OK"
2025-06-17 17:22:26,639 - ultibot_backend - INFO - [MainThread] - main.py:65 - Logging configurado exitosamente usando dictConfig.
2025-06-17 17:22:26,639 - ultibot_backend - INFO - [MainThread] - main.py:136 - Registrando routers de la API...
2025-06-17 17:22:26,659 - ultibot_backend - INFO - [MainThread] - main.py:148 - Todos los routers han sido registrados.
2025-06-17 17:22:26,709 - asyncio - DEBUG - [MainThread] - selector_events.py:54 - Using selector: SelectSelector
2025-06-17 17:22:26,711 - asyncio - DEBUG - [MainThread] - selector_events.py:54 - Using selector: SelectSelector
2025-06-17 17:22:26,716 - ultibot_backend - INFO - [MainThread] - main.py:105 - Middleware: Solicitud entrante: GET /api/v1/performance/strategies
2025-06-17 17:22:26,719 - ultibot_backend.services.performance_service - INFO - [MainThread] - performance_service.py:109 - Fetching performance data for user 00000000-0000-0000-0000-000000000001, mode_filter: OperatingMode.PAPER
2025-06-17 17:22:26,720 - ultibot_backend.services.performance_service - INFO - [MainThread] - performance_service.py:160 - Generated 1 performance entries for user 00000000-0000-0000-0000-000000000001
2025-06-17 17:22:26,720 - ultibot_backend - INFO - [MainThread] - main.py:107 - Middleware: Solicitud procesada: GET /api/v1/performance/strategies - Status: 200
2025-06-17 17:22:26,721 - httpx - INFO - [MainThread] - _client.py:1786 - HTTP Request: GET http://test/api/v1/performance/strategies?mode=paper "HTTP/1.1 200 OK"
2025-06-17 17:23:37,655 - ultibot_backend - INFO - [MainThread] - main.py:65 - Logging configurado exitosamente usando dictConfig.
2025-06-17 17:23:37,655 - ultibot_backend - INFO - [MainThread] - main.py:136 - Registrando routers de la API...
2025-06-17 17:23:37,683 - ultibot_backend - INFO - [MainThread] - main.py:148 - Todos los routers han sido registrados.
2025-06-17 17:23:37,757 - asyncio - DEBUG - [MainThread] - selector_events.py:54 - Using selector: SelectSelector
2025-06-17 17:23:37,758 - asyncio - DEBUG - [MainThread] - selector_events.py:54 - Using selector: SelectSelector
2025-06-17 17:23:37,766 - ultibot_backend - INFO - [MainThread] - main.py:105 - Middleware: Solicitud entrante: GET /api/v1/performance/strategies
2025-06-17 17:23:37,768 - ultibot_backend.services.performance_service - INFO - [MainThread] - performance_service.py:109 - Fetching performance data for user 00000000-0000-0000-0000-000000000001, mode_filter: OperatingMode.PAPER
2025-06-17 17:23:37,768 - ultibot_backend.services.performance_service - INFO - [MainThread] - performance_service.py:160 - Generated 1 performance entries for user 00000000-0000-0000-0000-000000000001
2025-06-17 17:23:37,769 - ultibot_backend - INFO - [MainThread] - main.py:107 - Middleware: Solicitud procesada: GET /api/v1/performance/strategies - Status: 200
2025-06-17 17:23:37,769 - httpx - INFO - [MainThread] - _client.py:1786 - HTTP Request: GET http://test/api/v1/performance/strategies?mode=paper "HTTP/1.1 200 OK"
2025-06-17 18:00:33,729 - ultibot_backend - INFO - [MainThread] - main.py:65 - Logging configurado exitosamente usando dictConfig.
2025-06-17 18:00:33,729 - ultibot_backend - INFO - [MainThread] - main.py:136 - Registrando routers de la API...
2025-06-17 18:00:33,744 - ultibot_backend - INFO - [MainThread] - main.py:148 - Todos los routers han sido registrados.
2025-06-17 18:00:34,134 - qasync - INFO - [MainThread] - __init__.py:57 - Forcing use of PySide6 as Qt Implementation
2025-06-17 18:00:34,924 - matplotlib - DEBUG - [MainThread] - __init__.py:342 - matplotlib data path: C:\Users\zamor\UltiBotInversiones\.venv\Lib\site-packages\matplotlib\mpl-data
2025-06-17 18:00:34,949 - matplotlib - DEBUG - [MainThread] - __init__.py:342 - CONFIGDIR=C:\Users\zamor\.matplotlib
2025-06-17 18:00:34,952 - matplotlib - DEBUG - [MainThread] - __init__.py:1557 - interactive is False
2025-06-17 18:00:34,952 - matplotlib - DEBUG - [MainThread] - __init__.py:1558 - platform is win32
2025-06-17 18:00:35,016 - matplotlib - DEBUG - [MainThread] - __init__.py:342 - CACHEDIR=C:\Users\zamor\.matplotlib
2025-06-17 18:00:35,069 - matplotlib.font_manager - DEBUG - [MainThread] - font_manager.py:1635 - Using fontManager instance from C:\Users\zamor\.matplotlib\fontlist-v390.json
2025-06-17 18:09:25,124 - ultibot_backend - INFO - [MainThread] - main.py:65 - Logging configurado exitosamente usando dictConfig.
2025-06-17 18:09:25,124 - ultibot_backend - INFO - [MainThread] - main.py:136 - Registrando routers de la API...
2025-06-17 18:09:25,139 - ultibot_backend - INFO - [MainThread] - main.py:148 - Todos los routers han sido registrados.
2025-06-17 18:09:25,295 - qasync - INFO - [MainThread] - __init__.py:57 - Forcing use of PySide6 as Qt Implementation
2025-06-17 18:09:25,428 - matplotlib - DEBUG - [MainThread] - __init__.py:342 - matplotlib data path: C:\Users\zamor\UltiBotInversiones\.venv\Lib\site-packages\matplotlib\mpl-data
2025-06-17 18:09:25,434 - matplotlib - DEBUG - [MainThread] - __init__.py:342 - CONFIGDIR=C:\Users\zamor\.matplotlib
2025-06-17 18:09:25,434 - matplotlib - DEBUG - [MainThread] - __init__.py:1557 - interactive is False
2025-06-17 18:09:25,434 - matplotlib - DEBUG - [MainThread] - __init__.py:1558 - platform is win32
2025-06-17 18:09:25,499 - matplotlib - DEBUG - [MainThread] - __init__.py:342 - CACHEDIR=C:\Users\zamor\.matplotlib
2025-06-17 18:09:25,564 - matplotlib.font_manager - DEBUG - [MainThread] - font_manager.py:1635 - Using fontManager instance from C:\Users\zamor\.matplotlib\fontlist-v390.json
